[2025-02-12T06:36:37.280+0000] {local_task_job_runner.py:123} INFO - ::group::Pre task execution logs
[2025-02-12T06:36:37.723+0000] {taskinstance.py:2613} INFO - Dependencies all met for dep_context=non-requeueable deps ti=<TaskInstance: Covid19.create_dim_location scheduled__2025-02-12T06:30:00+00:00 [queued]>
[2025-02-12T06:36:37.767+0000] {taskinstance.py:2613} INFO - Dependencies all met for dep_context=requeueable deps ti=<TaskInstance: Covid19.create_dim_location scheduled__2025-02-12T06:30:00+00:00 [queued]>
[2025-02-12T06:36:37.768+0000] {taskinstance.py:2866} INFO - Starting attempt 1 of 1
[2025-02-12T06:36:45.305+0000] {taskinstance.py:2889} INFO - Executing <Task(PostgresOperator): create_dim_location> on 2025-02-12 06:30:00+00:00
[2025-02-12T06:36:45.355+0000] {warnings.py:112} WARNING - /home/***/.local/lib/python3.12/site-packages/***/task/task_runner/standard_task_runner.py:70: DeprecationWarning: This process (pid=86) is multi-threaded, use of fork() may lead to deadlocks in the child.
  pid = os.fork()

[2025-02-12T06:36:45.370+0000] {standard_task_runner.py:72} INFO - Started process 104 to run task
[2025-02-12T06:36:45.368+0000] {standard_task_runner.py:104} INFO - Running: ['***', 'tasks', 'run', 'Covid19', 'create_dim_location', 'scheduled__2025-02-12T06:30:00+00:00', '--job-id', '19', '--raw', '--subdir', 'DAGS_FOLDER/covid_19.py', '--cfg-path', '/tmp/tmpznivt8o8']
[2025-02-12T06:36:45.380+0000] {standard_task_runner.py:105} INFO - Job 19: Subtask create_dim_location
[2025-02-12T06:36:57.785+0000] {cli_action_loggers.py:177} WARNING - Failed to log action (psycopg2.OperationalError) could not translate host name "postgres" to address: Temporary failure in name resolution

(Background on this error at: https://sqlalche.me/e/14/e3q8)
[2025-02-12T06:37:01.049+0000] {job.py:229} INFO - Heartbeat recovered after 25.00 seconds
[2025-02-12T06:37:01.167+0000] {task_command.py:467} INFO - Running <TaskInstance: Covid19.create_dim_location scheduled__2025-02-12T06:30:00+00:00 [running]> on host e0d8147cd68a
[2025-02-12T06:37:01.347+0000] {abstractoperator.py:783} ERROR - Exception rendering Jinja template for task 'create_dim_location', field 'sql'. Template: './queries/create_dim_location.sql'
Traceback (most recent call last):
  File "/home/airflow/.local/lib/python3.12/site-packages/airflow/models/abstractoperator.py", line 775, in _do_render_template_fields
    rendered_content = self.render_template(
                       ^^^^^^^^^^^^^^^^^^^^^
  File "/home/airflow/.local/lib/python3.12/site-packages/airflow/template/templater.py", line 168, in render_template
    template = jinja_env.get_template(value)
               ^^^^^^^^^^^^^^^^^^^^^^^^^^^^^
  File "/home/airflow/.local/lib/python3.12/site-packages/jinja2/environment.py", line 1013, in get_template
    return self._load_template(name, globals)
           ^^^^^^^^^^^^^^^^^^^^^^^^^^^^^^^^^^
  File "/home/airflow/.local/lib/python3.12/site-packages/jinja2/environment.py", line 972, in _load_template
    template = self.loader.load(self, name, self.make_globals(globals))
               ^^^^^^^^^^^^^^^^^^^^^^^^^^^^^^^^^^^^^^^^^^^^^^^^^^^^^^^^
  File "/home/airflow/.local/lib/python3.12/site-packages/jinja2/loaders.py", line 126, in load
    source, filename, uptodate = self.get_source(environment, name)
                                 ^^^^^^^^^^^^^^^^^^^^^^^^^^^^^^^^^^
  File "/home/airflow/.local/lib/python3.12/site-packages/jinja2/loaders.py", line 207, in get_source
    raise TemplateNotFound(template)
jinja2.exceptions.TemplateNotFound: ./queries/create_dim_location.sql
[2025-02-12T06:37:01.370+0000] {taskinstance.py:3311} ERROR - Task failed with exception
Traceback (most recent call last):
  File "/home/airflow/.local/lib/python3.12/site-packages/airflow/models/taskinstance.py", line 273, in _run_raw_task
    TaskInstance._execute_task_with_callbacks(
  File "/home/airflow/.local/lib/python3.12/site-packages/airflow/models/taskinstance.py", line 3115, in _execute_task_with_callbacks
    task_orig = self.render_templates(context=context, jinja_env=jinja_env)
                ^^^^^^^^^^^^^^^^^^^^^^^^^^^^^^^^^^^^^^^^^^^^^^^^^^^^^^^^^^^
  File "/home/airflow/.local/lib/python3.12/site-packages/airflow/models/taskinstance.py", line 3534, in render_templates
    original_task.render_template_fields(context, jinja_env)
  File "/home/airflow/.local/lib/python3.12/site-packages/airflow/models/baseoperator.py", line 1438, in render_template_fields
    self._do_render_template_fields(self, self.template_fields, context, jinja_env, set())
  File "/home/airflow/.local/lib/python3.12/site-packages/airflow/models/abstractoperator.py", line 775, in _do_render_template_fields
    rendered_content = self.render_template(
                       ^^^^^^^^^^^^^^^^^^^^^
  File "/home/airflow/.local/lib/python3.12/site-packages/airflow/template/templater.py", line 168, in render_template
    template = jinja_env.get_template(value)
               ^^^^^^^^^^^^^^^^^^^^^^^^^^^^^
  File "/home/airflow/.local/lib/python3.12/site-packages/jinja2/environment.py", line 1013, in get_template
    return self._load_template(name, globals)
           ^^^^^^^^^^^^^^^^^^^^^^^^^^^^^^^^^^
  File "/home/airflow/.local/lib/python3.12/site-packages/jinja2/environment.py", line 972, in _load_template
    template = self.loader.load(self, name, self.make_globals(globals))
               ^^^^^^^^^^^^^^^^^^^^^^^^^^^^^^^^^^^^^^^^^^^^^^^^^^^^^^^^
  File "/home/airflow/.local/lib/python3.12/site-packages/jinja2/loaders.py", line 126, in load
    source, filename, uptodate = self.get_source(environment, name)
                                 ^^^^^^^^^^^^^^^^^^^^^^^^^^^^^^^^^^
  File "/home/airflow/.local/lib/python3.12/site-packages/jinja2/loaders.py", line 207, in get_source
    raise TemplateNotFound(template)
jinja2.exceptions.TemplateNotFound: ./queries/create_dim_location.sql
[2025-02-12T06:37:01.398+0000] {taskinstance.py:1225} INFO - Marking task as FAILED. dag_id=Covid19, task_id=create_dim_location, run_id=scheduled__2025-02-12T06:30:00+00:00, execution_date=20250212T063000, start_date=20250212T063637, end_date=20250212T063701
[2025-02-12T06:37:01.450+0000] {taskinstance.py:340} INFO - ::group::Post task execution logs
[2025-02-12T06:37:01.452+0000] {standard_task_runner.py:124} ERROR - Failed to execute job 19 for task create_dim_location (./queries/create_dim_location.sql; 104)
Traceback (most recent call last):
  File "/home/airflow/.local/lib/python3.12/site-packages/airflow/task/task_runner/standard_task_runner.py", line 117, in _start_by_fork
    ret = args.func(args, dag=self.dag)
          ^^^^^^^^^^^^^^^^^^^^^^^^^^^^^
  File "/home/airflow/.local/lib/python3.12/site-packages/airflow/cli/cli_config.py", line 49, in command
    return func(*args, **kwargs)
           ^^^^^^^^^^^^^^^^^^^^^
  File "/home/airflow/.local/lib/python3.12/site-packages/airflow/utils/cli.py", line 116, in wrapper
    return f(*args, **kwargs)
           ^^^^^^^^^^^^^^^^^^
  File "/home/airflow/.local/lib/python3.12/site-packages/airflow/cli/commands/task_command.py", line 483, in task_run
    task_return_code = _run_task_by_selected_method(args, _dag, ti)
                       ^^^^^^^^^^^^^^^^^^^^^^^^^^^^^^^^^^^^^^^^^^^^
  File "/home/airflow/.local/lib/python3.12/site-packages/airflow/cli/commands/task_command.py", line 256, in _run_task_by_selected_method
    return _run_raw_task(args, ti)
           ^^^^^^^^^^^^^^^^^^^^^^^
  File "/home/airflow/.local/lib/python3.12/site-packages/airflow/cli/commands/task_command.py", line 341, in _run_raw_task
    return ti._run_raw_task(
           ^^^^^^^^^^^^^^^^^
  File "/home/airflow/.local/lib/python3.12/site-packages/airflow/utils/session.py", line 97, in wrapper
    return func(*args, session=session, **kwargs)
           ^^^^^^^^^^^^^^^^^^^^^^^^^^^^^^^^^^^^^^
  File "/home/airflow/.local/lib/python3.12/site-packages/airflow/models/taskinstance.py", line 3005, in _run_raw_task
    return _run_raw_task(
           ^^^^^^^^^^^^^^
  File "/home/airflow/.local/lib/python3.12/site-packages/airflow/models/taskinstance.py", line 273, in _run_raw_task
    TaskInstance._execute_task_with_callbacks(
  File "/home/airflow/.local/lib/python3.12/site-packages/airflow/models/taskinstance.py", line 3115, in _execute_task_with_callbacks
    task_orig = self.render_templates(context=context, jinja_env=jinja_env)
                ^^^^^^^^^^^^^^^^^^^^^^^^^^^^^^^^^^^^^^^^^^^^^^^^^^^^^^^^^^^
  File "/home/airflow/.local/lib/python3.12/site-packages/airflow/models/taskinstance.py", line 3534, in render_templates
    original_task.render_template_fields(context, jinja_env)
  File "/home/airflow/.local/lib/python3.12/site-packages/airflow/models/baseoperator.py", line 1438, in render_template_fields
    self._do_render_template_fields(self, self.template_fields, context, jinja_env, set())
  File "/home/airflow/.local/lib/python3.12/site-packages/airflow/models/abstractoperator.py", line 775, in _do_render_template_fields
    rendered_content = self.render_template(
                       ^^^^^^^^^^^^^^^^^^^^^
  File "/home/airflow/.local/lib/python3.12/site-packages/airflow/template/templater.py", line 168, in render_template
    template = jinja_env.get_template(value)
               ^^^^^^^^^^^^^^^^^^^^^^^^^^^^^
  File "/home/airflow/.local/lib/python3.12/site-packages/jinja2/environment.py", line 1013, in get_template
    return self._load_template(name, globals)
           ^^^^^^^^^^^^^^^^^^^^^^^^^^^^^^^^^^
  File "/home/airflow/.local/lib/python3.12/site-packages/jinja2/environment.py", line 972, in _load_template
    template = self.loader.load(self, name, self.make_globals(globals))
               ^^^^^^^^^^^^^^^^^^^^^^^^^^^^^^^^^^^^^^^^^^^^^^^^^^^^^^^^
  File "/home/airflow/.local/lib/python3.12/site-packages/jinja2/loaders.py", line 126, in load
    source, filename, uptodate = self.get_source(environment, name)
                                 ^^^^^^^^^^^^^^^^^^^^^^^^^^^^^^^^^^
  File "/home/airflow/.local/lib/python3.12/site-packages/jinja2/loaders.py", line 207, in get_source
    raise TemplateNotFound(template)
jinja2.exceptions.TemplateNotFound: ./queries/create_dim_location.sql
[2025-02-12T06:37:01.539+0000] {local_task_job_runner.py:266} INFO - Task exited with return code 1
[2025-02-12T06:37:01.569+0000] {local_task_job_runner.py:245} INFO - ::endgroup::
