[2025-02-13T08:47:05.558+0000] {local_task_job_runner.py:123} INFO - ::group::Pre task execution logs
[2025-02-13T08:47:05.585+0000] {taskinstance.py:2613} INFO - Dependencies all met for dep_context=non-requeueable deps ti=<TaskInstance: Covid19_ETL_Snowflake.create_tables manual__2025-02-13T08:46:44.858735+00:00 [queued]>
[2025-02-13T08:47:05.603+0000] {taskinstance.py:2613} INFO - Dependencies all met for dep_context=requeueable deps ti=<TaskInstance: Covid19_ETL_Snowflake.create_tables manual__2025-02-13T08:46:44.858735+00:00 [queued]>
[2025-02-13T08:47:05.604+0000] {taskinstance.py:2866} INFO - Starting attempt 1 of 1
[2025-02-13T08:47:05.651+0000] {taskinstance.py:2889} INFO - Executing <Task(SnowflakeOperator): create_tables> on 2025-02-13 08:46:44.858735+00:00
[2025-02-13T08:47:05.713+0000] {warnings.py:112} WARNING - /home/***/.local/lib/python3.12/site-packages/***/task/task_runner/standard_task_runner.py:70: DeprecationWarning: This process (pid=1086) is multi-threaded, use of fork() may lead to deadlocks in the child.
  pid = os.fork()

[2025-02-13T08:47:05.716+0000] {standard_task_runner.py:72} INFO - Started process 1088 to run task
[2025-02-13T08:47:05.716+0000] {standard_task_runner.py:104} INFO - Running: ['***', 'tasks', 'run', 'Covid19_ETL_Snowflake', 'create_tables', 'manual__2025-02-13T08:46:44.858735+00:00', '--job-id', '24', '--raw', '--subdir', 'DAGS_FOLDER/Covid19_Snowflake.py', '--cfg-path', '/tmp/tmpaksug7l1']
[2025-02-13T08:47:05.719+0000] {standard_task_runner.py:105} INFO - Job 24: Subtask create_tables
[2025-02-13T08:47:05.826+0000] {task_command.py:467} INFO - Running <TaskInstance: Covid19_ETL_Snowflake.create_tables manual__2025-02-13T08:46:44.858735+00:00 [running]> on host 3b43358e3e84
[2025-02-13T08:47:05.971+0000] {taskinstance.py:3132} INFO - Exporting env vars: AIRFLOW_CTX_DAG_OWNER='***' AIRFLOW_CTX_DAG_ID='Covid19_ETL_Snowflake' AIRFLOW_CTX_TASK_ID='create_tables' AIRFLOW_CTX_EXECUTION_DATE='2025-02-13T08:46:44.858735+00:00' AIRFLOW_CTX_TRY_NUMBER='1' AIRFLOW_CTX_DAG_RUN_ID='manual__2025-02-13T08:46:44.858735+00:00'
[2025-02-13T08:47:05.974+0000] {taskinstance.py:731} INFO - ::endgroup::
[2025-02-13T08:47:06.099+0000] {sql.py:278} INFO - Executing: 
        CREATE TABLE IF NOT EXISTS dim_date_details (
            date_id SERIAL PRIMARY KEY,
            date DATE UNIQUE NOT NULL,
            year INTEGER,
            month INTEGER,
            day INTEGER,
            weekday VARCHAR(9),
            is_weekend BOOLEAN
        );

        CREATE TABLE IF NOT EXISTS dim_location_details (
            location_id SERIAL PRIMARY KEY,
            fips VARCHAR(10),
            admin2 VARCHAR(255),
            province_state VARCHAR(255),
            country_region VARCHAR(255),
            lat FLOAT,
            long_ FLOAT,
            combined_key VARCHAR(500) UNIQUE
        );

        CREATE TABLE IF NOT EXISTS fact_cases (
            case_id SERIAL PRIMARY KEY,
            date_id INTEGER REFERENCES dim_date_details(date_id),
            location_id INTEGER REFERENCES dim_location_details(location_id),
            confirmed INTEGER,
            deaths INTEGER,
            recovered INTEGER,
            active INTEGER,
            incident_rate FLOAT,
            case_fatality_ratio FLOAT
        );
        
[2025-02-13T08:47:06.159+0000] {base.py:84} INFO - Retrieving connection 'snowflake_conn'
[2025-02-13T08:47:06.184+0000] {base.py:84} INFO - Retrieving connection 'snowflake_conn'
[2025-02-13T08:47:06.190+0000] {connection.py:414} INFO - Snowflake Connector for Python Version: 3.12.4, Python Version: 3.12.8, Platform: Linux-5.10.102.1-microsoft-standard-WSL2-x86_64-with-glibc2.36
[2025-02-13T08:47:06.193+0000] {connection.py:1197} INFO - Connecting to GLOBAL Snowflake domain
[2025-02-13T08:47:06.296+0000] {taskinstance.py:3311} ERROR - Task failed with exception
Traceback (most recent call last):
  File "/home/airflow/.local/lib/python3.12/site-packages/airflow/models/taskinstance.py", line 767, in _execute_task
    result = _execute_callable(context=context, **execute_callable_kwargs)
             ^^^^^^^^^^^^^^^^^^^^^^^^^^^^^^^^^^^^^^^^^^^^^^^^^^^^^^^^^^^^^
  File "/home/airflow/.local/lib/python3.12/site-packages/airflow/models/taskinstance.py", line 733, in _execute_callable
    return ExecutionCallableRunner(
           ^^^^^^^^^^^^^^^^^^^^^^^^
  File "/home/airflow/.local/lib/python3.12/site-packages/airflow/utils/operator_helpers.py", line 252, in run
    return self.func(*args, **kwargs)
           ^^^^^^^^^^^^^^^^^^^^^^^^^^
  File "/home/airflow/.local/lib/python3.12/site-packages/airflow/models/baseoperator.py", line 422, in wrapper
    return func(self, *args, **kwargs)
           ^^^^^^^^^^^^^^^^^^^^^^^^^^^
  File "/home/airflow/.local/lib/python3.12/site-packages/airflow/providers/common/sql/operators/sql.py", line 284, in execute
    output = hook.run(
             ^^^^^^^^^
  File "/home/airflow/.local/lib/python3.12/site-packages/airflow/providers/snowflake/hooks/snowflake.py", line 429, in run
    with closing(self.get_conn()) as conn:
                 ^^^^^^^^^^^^^^^
  File "/home/airflow/.local/lib/python3.12/site-packages/airflow/providers/snowflake/hooks/snowflake.py", line 303, in get_conn
    conn = connector.connect(**conn_config)
           ^^^^^^^^^^^^^^^^^^^^^^^^^^^^^^^^
  File "/home/airflow/.local/lib/python3.12/site-packages/snowflake/connector/__init__.py", line 55, in Connect
    return SnowflakeConnection(**kwargs)
           ^^^^^^^^^^^^^^^^^^^^^^^^^^^^^
  File "/home/airflow/.local/lib/python3.12/site-packages/snowflake/connector/connection.py", line 457, in __init__
    self.connect(**kwargs)
  File "/home/airflow/.local/lib/python3.12/site-packages/snowflake/connector/connection.py", line 733, in connect
    self.__config(**kwargs)
  File "/home/airflow/.local/lib/python3.12/site-packages/snowflake/connector/connection.py", line 1255, in __config
    Error.errorhandler_wrapper(
  File "/home/airflow/.local/lib/python3.12/site-packages/snowflake/connector/errors.py", line 284, in errorhandler_wrapper
    handed_over = Error.hand_to_other_handler(
                  ^^^^^^^^^^^^^^^^^^^^^^^^^^^^
  File "/home/airflow/.local/lib/python3.12/site-packages/snowflake/connector/errors.py", line 342, in hand_to_other_handler
    connection.errorhandler(connection, cursor, error_class, error_value)
  File "/home/airflow/.local/lib/python3.12/site-packages/snowflake/connector/errors.py", line 215, in default_errorhandler
    raise error_class(
snowflake.connector.errors.ProgrammingError: 251001: 251001: Account must be specified
[2025-02-13T08:47:06.314+0000] {taskinstance.py:1225} INFO - Marking task as FAILED. dag_id=Covid19_ETL_Snowflake, task_id=create_tables, run_id=manual__2025-02-13T08:46:44.858735+00:00, execution_date=20250213T084644, start_date=20250213T084705, end_date=20250213T084706
[2025-02-13T08:47:06.362+0000] {taskinstance.py:340} INFO - ::group::Post task execution logs
[2025-02-13T08:47:06.368+0000] {standard_task_runner.py:124} ERROR - Failed to execute job 24 for task create_tables (251001: 251001: Account must be specified; 1088)
Traceback (most recent call last):
  File "/home/airflow/.local/lib/python3.12/site-packages/airflow/task/task_runner/standard_task_runner.py", line 117, in _start_by_fork
    ret = args.func(args, dag=self.dag)
          ^^^^^^^^^^^^^^^^^^^^^^^^^^^^^
  File "/home/airflow/.local/lib/python3.12/site-packages/airflow/cli/cli_config.py", line 49, in command
    return func(*args, **kwargs)
           ^^^^^^^^^^^^^^^^^^^^^
  File "/home/airflow/.local/lib/python3.12/site-packages/airflow/utils/cli.py", line 116, in wrapper
    return f(*args, **kwargs)
           ^^^^^^^^^^^^^^^^^^
  File "/home/airflow/.local/lib/python3.12/site-packages/airflow/cli/commands/task_command.py", line 483, in task_run
    task_return_code = _run_task_by_selected_method(args, _dag, ti)
                       ^^^^^^^^^^^^^^^^^^^^^^^^^^^^^^^^^^^^^^^^^^^^
  File "/home/airflow/.local/lib/python3.12/site-packages/airflow/cli/commands/task_command.py", line 256, in _run_task_by_selected_method
    return _run_raw_task(args, ti)
           ^^^^^^^^^^^^^^^^^^^^^^^
  File "/home/airflow/.local/lib/python3.12/site-packages/airflow/cli/commands/task_command.py", line 341, in _run_raw_task
    return ti._run_raw_task(
           ^^^^^^^^^^^^^^^^^
  File "/home/airflow/.local/lib/python3.12/site-packages/airflow/utils/session.py", line 97, in wrapper
    return func(*args, session=session, **kwargs)
           ^^^^^^^^^^^^^^^^^^^^^^^^^^^^^^^^^^^^^^
  File "/home/airflow/.local/lib/python3.12/site-packages/airflow/models/taskinstance.py", line 3005, in _run_raw_task
    return _run_raw_task(
           ^^^^^^^^^^^^^^
  File "/home/airflow/.local/lib/python3.12/site-packages/airflow/models/taskinstance.py", line 273, in _run_raw_task
    TaskInstance._execute_task_with_callbacks(
  File "/home/airflow/.local/lib/python3.12/site-packages/airflow/models/taskinstance.py", line 3159, in _execute_task_with_callbacks
    result = self._execute_task(context, task_orig)
             ^^^^^^^^^^^^^^^^^^^^^^^^^^^^^^^^^^^^^^
  File "/home/airflow/.local/lib/python3.12/site-packages/airflow/models/taskinstance.py", line 3183, in _execute_task
    return _execute_task(self, context, task_orig)
           ^^^^^^^^^^^^^^^^^^^^^^^^^^^^^^^^^^^^^^^
  File "/home/airflow/.local/lib/python3.12/site-packages/airflow/models/taskinstance.py", line 767, in _execute_task
    result = _execute_callable(context=context, **execute_callable_kwargs)
             ^^^^^^^^^^^^^^^^^^^^^^^^^^^^^^^^^^^^^^^^^^^^^^^^^^^^^^^^^^^^^
  File "/home/airflow/.local/lib/python3.12/site-packages/airflow/models/taskinstance.py", line 733, in _execute_callable
    return ExecutionCallableRunner(
           ^^^^^^^^^^^^^^^^^^^^^^^^
  File "/home/airflow/.local/lib/python3.12/site-packages/airflow/utils/operator_helpers.py", line 252, in run
    return self.func(*args, **kwargs)
           ^^^^^^^^^^^^^^^^^^^^^^^^^^
  File "/home/airflow/.local/lib/python3.12/site-packages/airflow/models/baseoperator.py", line 422, in wrapper
    return func(self, *args, **kwargs)
           ^^^^^^^^^^^^^^^^^^^^^^^^^^^
  File "/home/airflow/.local/lib/python3.12/site-packages/airflow/providers/common/sql/operators/sql.py", line 284, in execute
    output = hook.run(
             ^^^^^^^^^
  File "/home/airflow/.local/lib/python3.12/site-packages/airflow/providers/snowflake/hooks/snowflake.py", line 429, in run
    with closing(self.get_conn()) as conn:
                 ^^^^^^^^^^^^^^^
  File "/home/airflow/.local/lib/python3.12/site-packages/airflow/providers/snowflake/hooks/snowflake.py", line 303, in get_conn
    conn = connector.connect(**conn_config)
           ^^^^^^^^^^^^^^^^^^^^^^^^^^^^^^^^
  File "/home/airflow/.local/lib/python3.12/site-packages/snowflake/connector/__init__.py", line 55, in Connect
    return SnowflakeConnection(**kwargs)
           ^^^^^^^^^^^^^^^^^^^^^^^^^^^^^
  File "/home/airflow/.local/lib/python3.12/site-packages/snowflake/connector/connection.py", line 457, in __init__
    self.connect(**kwargs)
  File "/home/airflow/.local/lib/python3.12/site-packages/snowflake/connector/connection.py", line 733, in connect
    self.__config(**kwargs)
  File "/home/airflow/.local/lib/python3.12/site-packages/snowflake/connector/connection.py", line 1255, in __config
    Error.errorhandler_wrapper(
  File "/home/airflow/.local/lib/python3.12/site-packages/snowflake/connector/errors.py", line 284, in errorhandler_wrapper
    handed_over = Error.hand_to_other_handler(
                  ^^^^^^^^^^^^^^^^^^^^^^^^^^^^
  File "/home/airflow/.local/lib/python3.12/site-packages/snowflake/connector/errors.py", line 342, in hand_to_other_handler
    connection.errorhandler(connection, cursor, error_class, error_value)
  File "/home/airflow/.local/lib/python3.12/site-packages/snowflake/connector/errors.py", line 215, in default_errorhandler
    raise error_class(
snowflake.connector.errors.ProgrammingError: 251001: 251001: Account must be specified
[2025-02-13T08:47:06.427+0000] {local_task_job_runner.py:266} INFO - Task exited with return code 1
[2025-02-13T08:47:06.467+0000] {taskinstance.py:3895} INFO - 0 downstream tasks scheduled from follow-on schedule check
[2025-02-13T08:47:06.483+0000] {local_task_job_runner.py:245} INFO - ::endgroup::
