[2025-02-12T18:28:35.002+0000] {local_task_job_runner.py:123} INFO - ::group::Pre task execution logs
[2025-02-12T18:28:35.076+0000] {taskinstance.py:2613} INFO - Dependencies all met for dep_context=non-requeueable deps ti=<TaskInstance: Covid19_ETL_v2.1.extract_data manual__2025-02-12T18:28:07.884104+00:00 [queued]>
[2025-02-12T18:28:35.107+0000] {taskinstance.py:2613} INFO - Dependencies all met for dep_context=requeueable deps ti=<TaskInstance: Covid19_ETL_v2.1.extract_data manual__2025-02-12T18:28:07.884104+00:00 [queued]>
[2025-02-12T18:28:35.108+0000] {taskinstance.py:2866} INFO - Starting attempt 1 of 1
[2025-02-12T18:28:35.152+0000] {taskinstance.py:2889} INFO - Executing <Task(PythonOperator): extract_data> on 2025-02-12 18:28:07.884104+00:00
[2025-02-12T18:28:35.180+0000] {standard_task_runner.py:104} INFO - Running: ['***', 'tasks', 'run', 'Covid19_ETL_v2.1', 'extract_data', 'manual__2025-02-12T18:28:07.884104+00:00', '--job-id', '162', '--raw', '--subdir', 'DAGS_FOLDER/covid_test.py', '--cfg-path', '/tmp/tmpa4hoexxe']
[2025-02-12T18:28:35.194+0000] {warnings.py:112} WARNING - /home/***/.local/lib/python3.12/site-packages/***/task/task_runner/standard_task_runner.py:70: DeprecationWarning: This process (pid=1940) is multi-threaded, use of fork() may lead to deadlocks in the child.
  pid = os.fork()

[2025-02-12T18:28:35.201+0000] {standard_task_runner.py:72} INFO - Started process 1942 to run task
[2025-02-12T18:28:35.195+0000] {standard_task_runner.py:105} INFO - Job 162: Subtask extract_data
[2025-02-12T18:28:36.481+0000] {task_command.py:467} INFO - Running <TaskInstance: Covid19_ETL_v2.1.extract_data manual__2025-02-12T18:28:07.884104+00:00 [running]> on host f99369d27a52
[2025-02-12T18:28:38.823+0000] {taskinstance.py:3132} INFO - Exporting env vars: AIRFLOW_CTX_DAG_OWNER='***' AIRFLOW_CTX_DAG_ID='Covid19_ETL_v2.1' AIRFLOW_CTX_TASK_ID='extract_data' AIRFLOW_CTX_EXECUTION_DATE='2025-02-12T18:28:07.884104+00:00' AIRFLOW_CTX_TRY_NUMBER='1' AIRFLOW_CTX_DAG_RUN_ID='manual__2025-02-12T18:28:07.884104+00:00'
[2025-02-12T18:28:38.827+0000] {taskinstance.py:731} INFO - ::endgroup::
[2025-02-12T18:28:38.887+0000] {base.py:84} INFO - Retrieving connection 'postgres_conn'
[2025-02-12T18:28:38.905+0000] {covid_test.py:32} INFO - Trying https://raw.githubusercontent.com/CSSEGISandData/COVID-19/master/csse_covid_19_data/csse_covid_19_daily_reports/01-30-2020.csv
[2025-02-12T18:28:39.847+0000] {covid_test.py:54} INFO - Successfully fetched data for 2020-01-30
[2025-02-12T18:28:39.849+0000] {python.py:240} INFO - Done. Returned value was: None
[2025-02-12T18:28:39.868+0000] {taskinstance.py:340} INFO - ::group::Post task execution logs
[2025-02-12T18:28:39.868+0000] {taskinstance.py:352} INFO - Marking task as SUCCESS. dag_id=Covid19_ETL_v2.1, task_id=extract_data, run_id=manual__2025-02-12T18:28:07.884104+00:00, execution_date=20250212T182807, start_date=20250212T182835, end_date=20250212T182839
[2025-02-12T18:28:39.925+0000] {local_task_job_runner.py:266} INFO - Task exited with return code 0
[2025-02-12T18:28:40.014+0000] {taskinstance.py:3895} INFO - 1 downstream tasks scheduled from follow-on schedule check
[2025-02-12T18:28:40.021+0000] {local_task_job_runner.py:245} INFO - ::endgroup::
[2025-02-12T18:28:40.430+0000] {standard_task_runner.py:217} INFO - Process not found (most likely exited), stop collecting metrics
