[2025-02-11T10:14:01.346+0000] {processor.py:186} INFO - Started process (PID=40) to work on /opt/airflow/dags/covid_19.py
[2025-02-11T10:14:01.468+0000] {processor.py:914} INFO - Processing file /opt/airflow/dags/covid_19.py for tasks to queue
[2025-02-11T10:14:01.895+0000] {logging_mixin.py:190} INFO - [2025-02-11T10:14:01.520+0000] {dagbag.py:588} INFO - Filling up the DagBag from /opt/airflow/dags/covid_19.py
[2025-02-11T10:15:21.012+0000] {processor.py:186} INFO - Started process (PID=60) to work on /opt/airflow/dags/covid_19.py
[2025-02-11T10:15:21.015+0000] {processor.py:914} INFO - Processing file /opt/airflow/dags/covid_19.py for tasks to queue
[2025-02-11T10:15:21.030+0000] {logging_mixin.py:190} INFO - [2025-02-11T10:15:21.028+0000] {dagbag.py:588} INFO - Filling up the DagBag from /opt/airflow/dags/covid_19.py
[2025-02-11T10:15:24.576+0000] {logging_mixin.py:190} INFO - [2025-02-11T10:15:24.573+0000] {templater.py:94} ERROR - Failed to resolve template field 'sql'
Traceback (most recent call last):
  File "/home/airflow/.local/lib/python3.12/site-packages/airflow/template/templater.py", line 92, in resolve_template_files
    setattr(self, field, env.loader.get_source(env, content)[0])  # type: ignore
                         ^^^^^^^^^^^^^^^^^^^^^^^^^^^^^^^^^^^
  File "/home/airflow/.local/lib/python3.12/site-packages/jinja2/loaders.py", line 207, in get_source
    raise TemplateNotFound(template)
jinja2.exceptions.TemplateNotFound: ./queries/create_dim_date.sql
[2025-02-11T10:15:24.578+0000] {logging_mixin.py:190} INFO - [2025-02-11T10:15:24.578+0000] {templater.py:94} ERROR - Failed to resolve template field 'sql'
Traceback (most recent call last):
  File "/home/airflow/.local/lib/python3.12/site-packages/airflow/template/templater.py", line 92, in resolve_template_files
    setattr(self, field, env.loader.get_source(env, content)[0])  # type: ignore
                         ^^^^^^^^^^^^^^^^^^^^^^^^^^^^^^^^^^^
  File "/home/airflow/.local/lib/python3.12/site-packages/jinja2/loaders.py", line 207, in get_source
    raise TemplateNotFound(template)
jinja2.exceptions.TemplateNotFound: ./queries/create_dim_location.sql
[2025-02-11T10:15:24.579+0000] {logging_mixin.py:190} INFO - [2025-02-11T10:15:24.579+0000] {templater.py:94} ERROR - Failed to resolve template field 'sql'
Traceback (most recent call last):
  File "/home/airflow/.local/lib/python3.12/site-packages/airflow/template/templater.py", line 92, in resolve_template_files
    setattr(self, field, env.loader.get_source(env, content)[0])  # type: ignore
                         ^^^^^^^^^^^^^^^^^^^^^^^^^^^^^^^^^^^
  File "/home/airflow/.local/lib/python3.12/site-packages/jinja2/loaders.py", line 207, in get_source
    raise TemplateNotFound(template)
jinja2.exceptions.TemplateNotFound: queries/create_fact_table.sql
[2025-02-11T10:15:24.595+0000] {processor.py:925} INFO - DAG(s) 'Covid19' retrieved from /opt/airflow/dags/covid_19.py
[2025-02-11T10:15:24.850+0000] {logging_mixin.py:190} INFO - [2025-02-11T10:15:24.849+0000] {override.py:1911} INFO - Created Permission View: can delete on DAG:Covid19
[2025-02-11T10:15:24.864+0000] {logging_mixin.py:190} INFO - [2025-02-11T10:15:24.863+0000] {override.py:1911} INFO - Created Permission View: can read on DAG:Covid19
[2025-02-11T10:15:24.875+0000] {logging_mixin.py:190} INFO - [2025-02-11T10:15:24.875+0000] {override.py:1911} INFO - Created Permission View: can edit on DAG:Covid19
[2025-02-11T10:15:24.892+0000] {logging_mixin.py:190} INFO - [2025-02-11T10:15:24.891+0000] {override.py:1911} INFO - Created Permission View: can create on DAG Run:Covid19
[2025-02-11T10:15:24.903+0000] {logging_mixin.py:190} INFO - [2025-02-11T10:15:24.903+0000] {override.py:1911} INFO - Created Permission View: menu access on DAG Run:Covid19
[2025-02-11T10:15:24.915+0000] {logging_mixin.py:190} INFO - [2025-02-11T10:15:24.915+0000] {override.py:1911} INFO - Created Permission View: can read on DAG Run:Covid19
[2025-02-11T10:15:24.934+0000] {logging_mixin.py:190} INFO - [2025-02-11T10:15:24.933+0000] {override.py:1911} INFO - Created Permission View: can delete on DAG Run:Covid19
[2025-02-11T10:15:24.936+0000] {logging_mixin.py:190} INFO - [2025-02-11T10:15:24.936+0000] {dag.py:3239} INFO - Sync 1 DAGs
[2025-02-11T10:15:24.955+0000] {logging_mixin.py:190} INFO - [2025-02-11T10:15:24.955+0000] {dag.py:3262} INFO - Creating ORM DAG for Covid19
[2025-02-11T10:15:24.974+0000] {logging_mixin.py:190} INFO - [2025-02-11T10:15:24.973+0000] {dag.py:4180} INFO - Setting next_dagrun for Covid19 to 2025-02-11 10:10:00+00:00, run_after=2025-02-11 10:15:00+00:00
[2025-02-11T10:15:25.004+0000] {processor.py:208} INFO - Processing /opt/airflow/dags/covid_19.py took 4.049 seconds
[2025-02-11T10:15:55.159+0000] {processor.py:186} INFO - Started process (PID=68) to work on /opt/airflow/dags/covid_19.py
[2025-02-11T10:15:55.163+0000] {processor.py:914} INFO - Processing file /opt/airflow/dags/covid_19.py for tasks to queue
[2025-02-11T10:15:55.185+0000] {logging_mixin.py:190} INFO - [2025-02-11T10:15:55.180+0000] {dagbag.py:588} INFO - Filling up the DagBag from /opt/airflow/dags/covid_19.py
[2025-02-11T10:16:01.775+0000] {logging_mixin.py:190} INFO - [2025-02-11T10:16:01.772+0000] {templater.py:94} ERROR - Failed to resolve template field 'sql'
Traceback (most recent call last):
  File "/home/airflow/.local/lib/python3.12/site-packages/airflow/template/templater.py", line 92, in resolve_template_files
    setattr(self, field, env.loader.get_source(env, content)[0])  # type: ignore
                         ^^^^^^^^^^^^^^^^^^^^^^^^^^^^^^^^^^^
  File "/home/airflow/.local/lib/python3.12/site-packages/jinja2/loaders.py", line 207, in get_source
    raise TemplateNotFound(template)
jinja2.exceptions.TemplateNotFound: ./queries/create_dim_date.sql
[2025-02-11T10:16:01.777+0000] {logging_mixin.py:190} INFO - [2025-02-11T10:16:01.777+0000] {templater.py:94} ERROR - Failed to resolve template field 'sql'
Traceback (most recent call last):
  File "/home/airflow/.local/lib/python3.12/site-packages/airflow/template/templater.py", line 92, in resolve_template_files
    setattr(self, field, env.loader.get_source(env, content)[0])  # type: ignore
                         ^^^^^^^^^^^^^^^^^^^^^^^^^^^^^^^^^^^
  File "/home/airflow/.local/lib/python3.12/site-packages/jinja2/loaders.py", line 207, in get_source
    raise TemplateNotFound(template)
jinja2.exceptions.TemplateNotFound: ./queries/create_dim_location.sql
[2025-02-11T10:16:01.779+0000] {logging_mixin.py:190} INFO - [2025-02-11T10:16:01.778+0000] {templater.py:94} ERROR - Failed to resolve template field 'sql'
Traceback (most recent call last):
  File "/home/airflow/.local/lib/python3.12/site-packages/airflow/template/templater.py", line 92, in resolve_template_files
    setattr(self, field, env.loader.get_source(env, content)[0])  # type: ignore
                         ^^^^^^^^^^^^^^^^^^^^^^^^^^^^^^^^^^^
  File "/home/airflow/.local/lib/python3.12/site-packages/jinja2/loaders.py", line 207, in get_source
    raise TemplateNotFound(template)
jinja2.exceptions.TemplateNotFound: queries/create_fact_table.sql
[2025-02-11T10:16:01.782+0000] {processor.py:925} INFO - DAG(s) 'Covid19' retrieved from /opt/airflow/dags/covid_19.py
[2025-02-11T10:16:01.818+0000] {logging_mixin.py:190} INFO - [2025-02-11T10:16:01.818+0000] {dag.py:3239} INFO - Sync 1 DAGs
[2025-02-11T10:16:01.846+0000] {logging_mixin.py:190} INFO - [2025-02-11T10:16:01.845+0000] {dag.py:4180} INFO - Setting next_dagrun for Covid19 to 2025-02-11 10:10:00+00:00, run_after=2025-02-11 10:15:00+00:00
[2025-02-11T10:16:01.878+0000] {processor.py:208} INFO - Processing /opt/airflow/dags/covid_19.py took 6.725 seconds
[2025-02-11T10:16:33.410+0000] {processor.py:186} INFO - Started process (PID=76) to work on /opt/airflow/dags/covid_19.py
[2025-02-11T10:16:33.520+0000] {processor.py:914} INFO - Processing file /opt/airflow/dags/covid_19.py for tasks to queue
[2025-02-11T10:16:33.608+0000] {logging_mixin.py:190} INFO - [2025-02-11T10:16:33.522+0000] {dagbag.py:588} INFO - Filling up the DagBag from /opt/airflow/dags/covid_19.py
[2025-02-11T10:16:35.417+0000] {logging_mixin.py:190} INFO - [2025-02-11T10:16:35.416+0000] {templater.py:94} ERROR - Failed to resolve template field 'sql'
Traceback (most recent call last):
  File "/home/airflow/.local/lib/python3.12/site-packages/airflow/template/templater.py", line 92, in resolve_template_files
    setattr(self, field, env.loader.get_source(env, content)[0])  # type: ignore
                         ^^^^^^^^^^^^^^^^^^^^^^^^^^^^^^^^^^^
  File "/home/airflow/.local/lib/python3.12/site-packages/jinja2/loaders.py", line 207, in get_source
    raise TemplateNotFound(template)
jinja2.exceptions.TemplateNotFound: ./queries/create_dim_date.sql
[2025-02-11T10:16:35.420+0000] {logging_mixin.py:190} INFO - [2025-02-11T10:16:35.419+0000] {templater.py:94} ERROR - Failed to resolve template field 'sql'
Traceback (most recent call last):
  File "/home/airflow/.local/lib/python3.12/site-packages/airflow/template/templater.py", line 92, in resolve_template_files
    setattr(self, field, env.loader.get_source(env, content)[0])  # type: ignore
                         ^^^^^^^^^^^^^^^^^^^^^^^^^^^^^^^^^^^
  File "/home/airflow/.local/lib/python3.12/site-packages/jinja2/loaders.py", line 207, in get_source
    raise TemplateNotFound(template)
jinja2.exceptions.TemplateNotFound: ./queries/create_dim_location.sql
[2025-02-11T10:16:35.422+0000] {logging_mixin.py:190} INFO - [2025-02-11T10:16:35.422+0000] {templater.py:94} ERROR - Failed to resolve template field 'sql'
Traceback (most recent call last):
  File "/home/airflow/.local/lib/python3.12/site-packages/airflow/template/templater.py", line 92, in resolve_template_files
    setattr(self, field, env.loader.get_source(env, content)[0])  # type: ignore
                         ^^^^^^^^^^^^^^^^^^^^^^^^^^^^^^^^^^^
  File "/home/airflow/.local/lib/python3.12/site-packages/jinja2/loaders.py", line 207, in get_source
    raise TemplateNotFound(template)
jinja2.exceptions.TemplateNotFound: queries/create_fact_table.sql
[2025-02-11T10:16:35.426+0000] {processor.py:925} INFO - DAG(s) 'Covid19' retrieved from /opt/airflow/dags/covid_19.py
[2025-02-11T10:16:35.455+0000] {logging_mixin.py:190} INFO - [2025-02-11T10:16:35.455+0000] {dag.py:3239} INFO - Sync 1 DAGs
[2025-02-11T10:16:35.482+0000] {logging_mixin.py:190} INFO - [2025-02-11T10:16:35.481+0000] {dag.py:4180} INFO - Setting next_dagrun for Covid19 to 2025-02-11 10:10:00+00:00, run_after=2025-02-11 10:15:00+00:00
[2025-02-11T10:16:35.507+0000] {processor.py:208} INFO - Processing /opt/airflow/dags/covid_19.py took 2.310 seconds
[2025-02-11T10:17:06.430+0000] {processor.py:186} INFO - Started process (PID=84) to work on /opt/airflow/dags/covid_19.py
[2025-02-11T10:17:06.432+0000] {processor.py:914} INFO - Processing file /opt/airflow/dags/covid_19.py for tasks to queue
[2025-02-11T10:17:06.438+0000] {logging_mixin.py:190} INFO - [2025-02-11T10:17:06.437+0000] {dagbag.py:588} INFO - Filling up the DagBag from /opt/airflow/dags/covid_19.py
[2025-02-11T10:17:11.659+0000] {logging_mixin.py:190} INFO - [2025-02-11T10:17:11.654+0000] {templater.py:94} ERROR - Failed to resolve template field 'sql'
Traceback (most recent call last):
  File "/home/airflow/.local/lib/python3.12/site-packages/airflow/template/templater.py", line 92, in resolve_template_files
    setattr(self, field, env.loader.get_source(env, content)[0])  # type: ignore
                         ^^^^^^^^^^^^^^^^^^^^^^^^^^^^^^^^^^^
  File "/home/airflow/.local/lib/python3.12/site-packages/jinja2/loaders.py", line 207, in get_source
    raise TemplateNotFound(template)
jinja2.exceptions.TemplateNotFound: ./queries/create_dim_date.sql
[2025-02-11T10:17:11.660+0000] {logging_mixin.py:190} INFO - [2025-02-11T10:17:11.660+0000] {templater.py:94} ERROR - Failed to resolve template field 'sql'
Traceback (most recent call last):
  File "/home/airflow/.local/lib/python3.12/site-packages/airflow/template/templater.py", line 92, in resolve_template_files
    setattr(self, field, env.loader.get_source(env, content)[0])  # type: ignore
                         ^^^^^^^^^^^^^^^^^^^^^^^^^^^^^^^^^^^
  File "/home/airflow/.local/lib/python3.12/site-packages/jinja2/loaders.py", line 207, in get_source
    raise TemplateNotFound(template)
jinja2.exceptions.TemplateNotFound: ./queries/create_dim_location.sql
[2025-02-11T10:17:11.662+0000] {logging_mixin.py:190} INFO - [2025-02-11T10:17:11.661+0000] {templater.py:94} ERROR - Failed to resolve template field 'sql'
Traceback (most recent call last):
  File "/home/airflow/.local/lib/python3.12/site-packages/airflow/template/templater.py", line 92, in resolve_template_files
    setattr(self, field, env.loader.get_source(env, content)[0])  # type: ignore
                         ^^^^^^^^^^^^^^^^^^^^^^^^^^^^^^^^^^^
  File "/home/airflow/.local/lib/python3.12/site-packages/jinja2/loaders.py", line 207, in get_source
    raise TemplateNotFound(template)
jinja2.exceptions.TemplateNotFound: queries/create_fact_table.sql
[2025-02-11T10:17:11.682+0000] {processor.py:925} INFO - DAG(s) 'Covid19' retrieved from /opt/airflow/dags/covid_19.py
[2025-02-11T10:17:11.810+0000] {logging_mixin.py:190} INFO - [2025-02-11T10:17:11.809+0000] {dag.py:3239} INFO - Sync 1 DAGs
[2025-02-11T10:17:11.858+0000] {logging_mixin.py:190} INFO - [2025-02-11T10:17:11.858+0000] {dag.py:4180} INFO - Setting next_dagrun for Covid19 to 2025-02-11 10:10:00+00:00, run_after=2025-02-11 10:15:00+00:00
[2025-02-11T10:17:11.902+0000] {processor.py:208} INFO - Processing /opt/airflow/dags/covid_19.py took 5.479 seconds
[2025-02-11T10:17:42.359+0000] {processor.py:186} INFO - Started process (PID=92) to work on /opt/airflow/dags/covid_19.py
[2025-02-11T10:17:42.364+0000] {processor.py:914} INFO - Processing file /opt/airflow/dags/covid_19.py for tasks to queue
[2025-02-11T10:17:42.369+0000] {logging_mixin.py:190} INFO - [2025-02-11T10:17:42.368+0000] {dagbag.py:588} INFO - Filling up the DagBag from /opt/airflow/dags/covid_19.py
[2025-02-11T10:17:43.830+0000] {logging_mixin.py:190} INFO - [2025-02-11T10:17:43.823+0000] {templater.py:94} ERROR - Failed to resolve template field 'sql'
Traceback (most recent call last):
  File "/home/airflow/.local/lib/python3.12/site-packages/airflow/template/templater.py", line 92, in resolve_template_files
    setattr(self, field, env.loader.get_source(env, content)[0])  # type: ignore
                         ^^^^^^^^^^^^^^^^^^^^^^^^^^^^^^^^^^^
  File "/home/airflow/.local/lib/python3.12/site-packages/jinja2/loaders.py", line 207, in get_source
    raise TemplateNotFound(template)
jinja2.exceptions.TemplateNotFound: ./queries/create_dim_date.sql
[2025-02-11T10:17:43.833+0000] {logging_mixin.py:190} INFO - [2025-02-11T10:17:43.832+0000] {templater.py:94} ERROR - Failed to resolve template field 'sql'
Traceback (most recent call last):
  File "/home/airflow/.local/lib/python3.12/site-packages/airflow/template/templater.py", line 92, in resolve_template_files
    setattr(self, field, env.loader.get_source(env, content)[0])  # type: ignore
                         ^^^^^^^^^^^^^^^^^^^^^^^^^^^^^^^^^^^
  File "/home/airflow/.local/lib/python3.12/site-packages/jinja2/loaders.py", line 207, in get_source
    raise TemplateNotFound(template)
jinja2.exceptions.TemplateNotFound: ./queries/create_dim_location.sql
[2025-02-11T10:17:43.835+0000] {logging_mixin.py:190} INFO - [2025-02-11T10:17:43.834+0000] {templater.py:94} ERROR - Failed to resolve template field 'sql'
Traceback (most recent call last):
  File "/home/airflow/.local/lib/python3.12/site-packages/airflow/template/templater.py", line 92, in resolve_template_files
    setattr(self, field, env.loader.get_source(env, content)[0])  # type: ignore
                         ^^^^^^^^^^^^^^^^^^^^^^^^^^^^^^^^^^^
  File "/home/airflow/.local/lib/python3.12/site-packages/jinja2/loaders.py", line 207, in get_source
    raise TemplateNotFound(template)
jinja2.exceptions.TemplateNotFound: queries/create_fact_table.sql
[2025-02-11T10:17:43.844+0000] {processor.py:925} INFO - DAG(s) 'Covid19' retrieved from /opt/airflow/dags/covid_19.py
[2025-02-11T10:17:43.901+0000] {logging_mixin.py:190} INFO - [2025-02-11T10:17:43.900+0000] {dag.py:3239} INFO - Sync 1 DAGs
[2025-02-11T10:17:43.949+0000] {logging_mixin.py:190} INFO - [2025-02-11T10:17:43.949+0000] {dag.py:4180} INFO - Setting next_dagrun for Covid19 to 2025-02-11 10:10:00+00:00, run_after=2025-02-11 10:15:00+00:00
[2025-02-11T10:17:43.971+0000] {processor.py:208} INFO - Processing /opt/airflow/dags/covid_19.py took 1.621 seconds
[2025-02-11T10:18:14.644+0000] {processor.py:186} INFO - Started process (PID=100) to work on /opt/airflow/dags/covid_19.py
[2025-02-11T10:18:14.646+0000] {processor.py:914} INFO - Processing file /opt/airflow/dags/covid_19.py for tasks to queue
[2025-02-11T10:18:14.648+0000] {logging_mixin.py:190} INFO - [2025-02-11T10:18:14.648+0000] {dagbag.py:588} INFO - Filling up the DagBag from /opt/airflow/dags/covid_19.py
[2025-02-11T10:18:15.083+0000] {logging_mixin.py:190} INFO - [2025-02-11T10:18:15.082+0000] {templater.py:94} ERROR - Failed to resolve template field 'sql'
Traceback (most recent call last):
  File "/home/airflow/.local/lib/python3.12/site-packages/airflow/template/templater.py", line 92, in resolve_template_files
    setattr(self, field, env.loader.get_source(env, content)[0])  # type: ignore
                         ^^^^^^^^^^^^^^^^^^^^^^^^^^^^^^^^^^^
  File "/home/airflow/.local/lib/python3.12/site-packages/jinja2/loaders.py", line 207, in get_source
    raise TemplateNotFound(template)
jinja2.exceptions.TemplateNotFound: ./queries/create_dim_date.sql
[2025-02-11T10:18:15.085+0000] {logging_mixin.py:190} INFO - [2025-02-11T10:18:15.085+0000] {templater.py:94} ERROR - Failed to resolve template field 'sql'
Traceback (most recent call last):
  File "/home/airflow/.local/lib/python3.12/site-packages/airflow/template/templater.py", line 92, in resolve_template_files
    setattr(self, field, env.loader.get_source(env, content)[0])  # type: ignore
                         ^^^^^^^^^^^^^^^^^^^^^^^^^^^^^^^^^^^
  File "/home/airflow/.local/lib/python3.12/site-packages/jinja2/loaders.py", line 207, in get_source
    raise TemplateNotFound(template)
jinja2.exceptions.TemplateNotFound: ./queries/create_dim_location.sql
[2025-02-11T10:18:15.086+0000] {logging_mixin.py:190} INFO - [2025-02-11T10:18:15.086+0000] {templater.py:94} ERROR - Failed to resolve template field 'sql'
Traceback (most recent call last):
  File "/home/airflow/.local/lib/python3.12/site-packages/airflow/template/templater.py", line 92, in resolve_template_files
    setattr(self, field, env.loader.get_source(env, content)[0])  # type: ignore
                         ^^^^^^^^^^^^^^^^^^^^^^^^^^^^^^^^^^^
  File "/home/airflow/.local/lib/python3.12/site-packages/jinja2/loaders.py", line 207, in get_source
    raise TemplateNotFound(template)
jinja2.exceptions.TemplateNotFound: queries/create_fact_table.sql
[2025-02-11T10:18:15.090+0000] {processor.py:925} INFO - DAG(s) 'Covid19' retrieved from /opt/airflow/dags/covid_19.py
[2025-02-11T10:18:15.112+0000] {logging_mixin.py:190} INFO - [2025-02-11T10:18:15.112+0000] {dag.py:3239} INFO - Sync 1 DAGs
[2025-02-11T10:18:15.133+0000] {logging_mixin.py:190} INFO - [2025-02-11T10:18:15.133+0000] {dag.py:4180} INFO - Setting next_dagrun for Covid19 to 2025-02-11 10:10:00+00:00, run_after=2025-02-11 10:15:00+00:00
[2025-02-11T10:18:15.156+0000] {processor.py:208} INFO - Processing /opt/airflow/dags/covid_19.py took 0.517 seconds
[2025-02-11T10:18:45.413+0000] {processor.py:186} INFO - Started process (PID=108) to work on /opt/airflow/dags/covid_19.py
[2025-02-11T10:18:45.414+0000] {processor.py:914} INFO - Processing file /opt/airflow/dags/covid_19.py for tasks to queue
[2025-02-11T10:18:45.416+0000] {logging_mixin.py:190} INFO - [2025-02-11T10:18:45.416+0000] {dagbag.py:588} INFO - Filling up the DagBag from /opt/airflow/dags/covid_19.py
[2025-02-11T10:18:46.091+0000] {logging_mixin.py:190} INFO - [2025-02-11T10:18:46.090+0000] {templater.py:94} ERROR - Failed to resolve template field 'sql'
Traceback (most recent call last):
  File "/home/airflow/.local/lib/python3.12/site-packages/airflow/template/templater.py", line 92, in resolve_template_files
    setattr(self, field, env.loader.get_source(env, content)[0])  # type: ignore
                         ^^^^^^^^^^^^^^^^^^^^^^^^^^^^^^^^^^^
  File "/home/airflow/.local/lib/python3.12/site-packages/jinja2/loaders.py", line 207, in get_source
    raise TemplateNotFound(template)
jinja2.exceptions.TemplateNotFound: ./queries/create_dim_date.sql
[2025-02-11T10:18:46.092+0000] {logging_mixin.py:190} INFO - [2025-02-11T10:18:46.092+0000] {templater.py:94} ERROR - Failed to resolve template field 'sql'
Traceback (most recent call last):
  File "/home/airflow/.local/lib/python3.12/site-packages/airflow/template/templater.py", line 92, in resolve_template_files
    setattr(self, field, env.loader.get_source(env, content)[0])  # type: ignore
                         ^^^^^^^^^^^^^^^^^^^^^^^^^^^^^^^^^^^
  File "/home/airflow/.local/lib/python3.12/site-packages/jinja2/loaders.py", line 207, in get_source
    raise TemplateNotFound(template)
jinja2.exceptions.TemplateNotFound: ./queries/create_dim_location.sql
[2025-02-11T10:18:46.093+0000] {logging_mixin.py:190} INFO - [2025-02-11T10:18:46.093+0000] {templater.py:94} ERROR - Failed to resolve template field 'sql'
Traceback (most recent call last):
  File "/home/airflow/.local/lib/python3.12/site-packages/airflow/template/templater.py", line 92, in resolve_template_files
    setattr(self, field, env.loader.get_source(env, content)[0])  # type: ignore
                         ^^^^^^^^^^^^^^^^^^^^^^^^^^^^^^^^^^^
  File "/home/airflow/.local/lib/python3.12/site-packages/jinja2/loaders.py", line 207, in get_source
    raise TemplateNotFound(template)
jinja2.exceptions.TemplateNotFound: queries/create_fact_table.sql
[2025-02-11T10:18:46.096+0000] {processor.py:925} INFO - DAG(s) 'Covid19' retrieved from /opt/airflow/dags/covid_19.py
[2025-02-11T10:18:46.119+0000] {logging_mixin.py:190} INFO - [2025-02-11T10:18:46.119+0000] {dag.py:3239} INFO - Sync 1 DAGs
[2025-02-11T10:18:46.139+0000] {logging_mixin.py:190} INFO - [2025-02-11T10:18:46.138+0000] {dag.py:4180} INFO - Setting next_dagrun for Covid19 to 2025-02-11 10:10:00+00:00, run_after=2025-02-11 10:15:00+00:00
[2025-02-11T10:18:46.162+0000] {processor.py:208} INFO - Processing /opt/airflow/dags/covid_19.py took 0.755 seconds
[2025-02-11T10:19:17.902+0000] {processor.py:186} INFO - Started process (PID=117) to work on /opt/airflow/dags/covid_19.py
[2025-02-11T10:19:17.904+0000] {processor.py:914} INFO - Processing file /opt/airflow/dags/covid_19.py for tasks to queue
[2025-02-11T10:19:17.907+0000] {logging_mixin.py:190} INFO - [2025-02-11T10:19:17.907+0000] {dagbag.py:588} INFO - Filling up the DagBag from /opt/airflow/dags/covid_19.py
[2025-02-11T10:19:18.550+0000] {logging_mixin.py:190} INFO - [2025-02-11T10:19:18.549+0000] {templater.py:94} ERROR - Failed to resolve template field 'sql'
Traceback (most recent call last):
  File "/home/airflow/.local/lib/python3.12/site-packages/airflow/template/templater.py", line 92, in resolve_template_files
    setattr(self, field, env.loader.get_source(env, content)[0])  # type: ignore
                         ^^^^^^^^^^^^^^^^^^^^^^^^^^^^^^^^^^^
  File "/home/airflow/.local/lib/python3.12/site-packages/jinja2/loaders.py", line 207, in get_source
    raise TemplateNotFound(template)
jinja2.exceptions.TemplateNotFound: ./queries/create_dim_date.sql
[2025-02-11T10:19:18.552+0000] {logging_mixin.py:190} INFO - [2025-02-11T10:19:18.552+0000] {templater.py:94} ERROR - Failed to resolve template field 'sql'
Traceback (most recent call last):
  File "/home/airflow/.local/lib/python3.12/site-packages/airflow/template/templater.py", line 92, in resolve_template_files
    setattr(self, field, env.loader.get_source(env, content)[0])  # type: ignore
                         ^^^^^^^^^^^^^^^^^^^^^^^^^^^^^^^^^^^
  File "/home/airflow/.local/lib/python3.12/site-packages/jinja2/loaders.py", line 207, in get_source
    raise TemplateNotFound(template)
jinja2.exceptions.TemplateNotFound: ./queries/create_dim_location.sql
[2025-02-11T10:19:18.553+0000] {logging_mixin.py:190} INFO - [2025-02-11T10:19:18.553+0000] {templater.py:94} ERROR - Failed to resolve template field 'sql'
Traceback (most recent call last):
  File "/home/airflow/.local/lib/python3.12/site-packages/airflow/template/templater.py", line 92, in resolve_template_files
    setattr(self, field, env.loader.get_source(env, content)[0])  # type: ignore
                         ^^^^^^^^^^^^^^^^^^^^^^^^^^^^^^^^^^^
  File "/home/airflow/.local/lib/python3.12/site-packages/jinja2/loaders.py", line 207, in get_source
    raise TemplateNotFound(template)
jinja2.exceptions.TemplateNotFound: queries/create_fact_table.sql
[2025-02-11T10:19:18.556+0000] {processor.py:925} INFO - DAG(s) 'Covid19' retrieved from /opt/airflow/dags/covid_19.py
[2025-02-11T10:19:18.582+0000] {logging_mixin.py:190} INFO - [2025-02-11T10:19:18.582+0000] {dag.py:3239} INFO - Sync 1 DAGs
[2025-02-11T10:19:18.598+0000] {logging_mixin.py:190} INFO - [2025-02-11T10:19:18.598+0000] {dag.py:4180} INFO - Setting next_dagrun for Covid19 to 2025-02-11 10:10:00+00:00, run_after=2025-02-11 10:15:00+00:00
[2025-02-11T10:19:18.620+0000] {processor.py:208} INFO - Processing /opt/airflow/dags/covid_19.py took 0.736 seconds
[2025-02-11T10:19:48.912+0000] {processor.py:186} INFO - Started process (PID=125) to work on /opt/airflow/dags/covid_19.py
[2025-02-11T10:19:48.914+0000] {processor.py:914} INFO - Processing file /opt/airflow/dags/covid_19.py for tasks to queue
[2025-02-11T10:19:48.916+0000] {logging_mixin.py:190} INFO - [2025-02-11T10:19:48.916+0000] {dagbag.py:588} INFO - Filling up the DagBag from /opt/airflow/dags/covid_19.py
[2025-02-11T10:19:49.560+0000] {logging_mixin.py:190} INFO - [2025-02-11T10:19:49.558+0000] {templater.py:94} ERROR - Failed to resolve template field 'sql'
Traceback (most recent call last):
  File "/home/airflow/.local/lib/python3.12/site-packages/airflow/template/templater.py", line 92, in resolve_template_files
    setattr(self, field, env.loader.get_source(env, content)[0])  # type: ignore
                         ^^^^^^^^^^^^^^^^^^^^^^^^^^^^^^^^^^^
  File "/home/airflow/.local/lib/python3.12/site-packages/jinja2/loaders.py", line 207, in get_source
    raise TemplateNotFound(template)
jinja2.exceptions.TemplateNotFound: ./queries/create_dim_date.sql
[2025-02-11T10:19:49.562+0000] {logging_mixin.py:190} INFO - [2025-02-11T10:19:49.561+0000] {templater.py:94} ERROR - Failed to resolve template field 'sql'
Traceback (most recent call last):
  File "/home/airflow/.local/lib/python3.12/site-packages/airflow/template/templater.py", line 92, in resolve_template_files
    setattr(self, field, env.loader.get_source(env, content)[0])  # type: ignore
                         ^^^^^^^^^^^^^^^^^^^^^^^^^^^^^^^^^^^
  File "/home/airflow/.local/lib/python3.12/site-packages/jinja2/loaders.py", line 207, in get_source
    raise TemplateNotFound(template)
jinja2.exceptions.TemplateNotFound: ./queries/create_dim_location.sql
[2025-02-11T10:19:49.563+0000] {logging_mixin.py:190} INFO - [2025-02-11T10:19:49.563+0000] {templater.py:94} ERROR - Failed to resolve template field 'sql'
Traceback (most recent call last):
  File "/home/airflow/.local/lib/python3.12/site-packages/airflow/template/templater.py", line 92, in resolve_template_files
    setattr(self, field, env.loader.get_source(env, content)[0])  # type: ignore
                         ^^^^^^^^^^^^^^^^^^^^^^^^^^^^^^^^^^^
  File "/home/airflow/.local/lib/python3.12/site-packages/jinja2/loaders.py", line 207, in get_source
    raise TemplateNotFound(template)
jinja2.exceptions.TemplateNotFound: queries/create_fact_table.sql
[2025-02-11T10:19:49.566+0000] {processor.py:925} INFO - DAG(s) 'Covid19' retrieved from /opt/airflow/dags/covid_19.py
[2025-02-11T10:19:49.591+0000] {logging_mixin.py:190} INFO - [2025-02-11T10:19:49.590+0000] {dag.py:3239} INFO - Sync 1 DAGs
[2025-02-11T10:19:49.619+0000] {logging_mixin.py:190} INFO - [2025-02-11T10:19:49.619+0000] {dag.py:4180} INFO - Setting next_dagrun for Covid19 to 2025-02-11 10:10:00+00:00, run_after=2025-02-11 10:15:00+00:00
[2025-02-11T10:19:49.654+0000] {processor.py:208} INFO - Processing /opt/airflow/dags/covid_19.py took 0.752 seconds
[2025-02-11T10:20:20.074+0000] {processor.py:186} INFO - Started process (PID=133) to work on /opt/airflow/dags/covid_19.py
[2025-02-11T10:20:20.079+0000] {processor.py:914} INFO - Processing file /opt/airflow/dags/covid_19.py for tasks to queue
[2025-02-11T10:20:20.095+0000] {logging_mixin.py:190} INFO - [2025-02-11T10:20:20.091+0000] {dagbag.py:588} INFO - Filling up the DagBag from /opt/airflow/dags/covid_19.py
[2025-02-11T10:20:21.440+0000] {logging_mixin.py:190} INFO - [2025-02-11T10:20:21.437+0000] {templater.py:94} ERROR - Failed to resolve template field 'sql'
Traceback (most recent call last):
  File "/home/airflow/.local/lib/python3.12/site-packages/airflow/template/templater.py", line 92, in resolve_template_files
    setattr(self, field, env.loader.get_source(env, content)[0])  # type: ignore
                         ^^^^^^^^^^^^^^^^^^^^^^^^^^^^^^^^^^^
  File "/home/airflow/.local/lib/python3.12/site-packages/jinja2/loaders.py", line 207, in get_source
    raise TemplateNotFound(template)
jinja2.exceptions.TemplateNotFound: ./queries/create_dim_date.sql
[2025-02-11T10:20:21.442+0000] {logging_mixin.py:190} INFO - [2025-02-11T10:20:21.442+0000] {templater.py:94} ERROR - Failed to resolve template field 'sql'
Traceback (most recent call last):
  File "/home/airflow/.local/lib/python3.12/site-packages/airflow/template/templater.py", line 92, in resolve_template_files
    setattr(self, field, env.loader.get_source(env, content)[0])  # type: ignore
                         ^^^^^^^^^^^^^^^^^^^^^^^^^^^^^^^^^^^
  File "/home/airflow/.local/lib/python3.12/site-packages/jinja2/loaders.py", line 207, in get_source
    raise TemplateNotFound(template)
jinja2.exceptions.TemplateNotFound: ./queries/create_dim_location.sql
[2025-02-11T10:20:21.443+0000] {logging_mixin.py:190} INFO - [2025-02-11T10:20:21.443+0000] {templater.py:94} ERROR - Failed to resolve template field 'sql'
Traceback (most recent call last):
  File "/home/airflow/.local/lib/python3.12/site-packages/airflow/template/templater.py", line 92, in resolve_template_files
    setattr(self, field, env.loader.get_source(env, content)[0])  # type: ignore
                         ^^^^^^^^^^^^^^^^^^^^^^^^^^^^^^^^^^^
  File "/home/airflow/.local/lib/python3.12/site-packages/jinja2/loaders.py", line 207, in get_source
    raise TemplateNotFound(template)
jinja2.exceptions.TemplateNotFound: queries/create_fact_table.sql
[2025-02-11T10:20:21.458+0000] {processor.py:925} INFO - DAG(s) 'Covid19' retrieved from /opt/airflow/dags/covid_19.py
[2025-02-11T10:20:21.515+0000] {logging_mixin.py:190} INFO - [2025-02-11T10:20:21.515+0000] {dag.py:3239} INFO - Sync 1 DAGs
[2025-02-11T10:20:21.556+0000] {logging_mixin.py:190} INFO - [2025-02-11T10:20:21.556+0000] {dag.py:4180} INFO - Setting next_dagrun for Covid19 to 2025-02-11 10:15:00+00:00, run_after=2025-02-11 10:20:00+00:00
[2025-02-11T10:20:21.588+0000] {processor.py:208} INFO - Processing /opt/airflow/dags/covid_19.py took 1.573 seconds
[2025-02-11T10:20:51.907+0000] {processor.py:186} INFO - Started process (PID=141) to work on /opt/airflow/dags/covid_19.py
[2025-02-11T10:20:51.912+0000] {processor.py:914} INFO - Processing file /opt/airflow/dags/covid_19.py for tasks to queue
[2025-02-11T10:20:51.916+0000] {logging_mixin.py:190} INFO - [2025-02-11T10:20:51.916+0000] {dagbag.py:588} INFO - Filling up the DagBag from /opt/airflow/dags/covid_19.py
[2025-02-11T10:20:52.510+0000] {logging_mixin.py:190} INFO - [2025-02-11T10:20:52.509+0000] {templater.py:94} ERROR - Failed to resolve template field 'sql'
Traceback (most recent call last):
  File "/home/airflow/.local/lib/python3.12/site-packages/airflow/template/templater.py", line 92, in resolve_template_files
    setattr(self, field, env.loader.get_source(env, content)[0])  # type: ignore
                         ^^^^^^^^^^^^^^^^^^^^^^^^^^^^^^^^^^^
  File "/home/airflow/.local/lib/python3.12/site-packages/jinja2/loaders.py", line 207, in get_source
    raise TemplateNotFound(template)
jinja2.exceptions.TemplateNotFound: ./queries/create_dim_date.sql
[2025-02-11T10:20:52.512+0000] {logging_mixin.py:190} INFO - [2025-02-11T10:20:52.511+0000] {templater.py:94} ERROR - Failed to resolve template field 'sql'
Traceback (most recent call last):
  File "/home/airflow/.local/lib/python3.12/site-packages/airflow/template/templater.py", line 92, in resolve_template_files
    setattr(self, field, env.loader.get_source(env, content)[0])  # type: ignore
                         ^^^^^^^^^^^^^^^^^^^^^^^^^^^^^^^^^^^
  File "/home/airflow/.local/lib/python3.12/site-packages/jinja2/loaders.py", line 207, in get_source
    raise TemplateNotFound(template)
jinja2.exceptions.TemplateNotFound: ./queries/create_dim_location.sql
[2025-02-11T10:20:52.513+0000] {logging_mixin.py:190} INFO - [2025-02-11T10:20:52.513+0000] {templater.py:94} ERROR - Failed to resolve template field 'sql'
Traceback (most recent call last):
  File "/home/airflow/.local/lib/python3.12/site-packages/airflow/template/templater.py", line 92, in resolve_template_files
    setattr(self, field, env.loader.get_source(env, content)[0])  # type: ignore
                         ^^^^^^^^^^^^^^^^^^^^^^^^^^^^^^^^^^^
  File "/home/airflow/.local/lib/python3.12/site-packages/jinja2/loaders.py", line 207, in get_source
    raise TemplateNotFound(template)
jinja2.exceptions.TemplateNotFound: queries/create_fact_table.sql
[2025-02-11T10:20:52.518+0000] {processor.py:925} INFO - DAG(s) 'Covid19' retrieved from /opt/airflow/dags/covid_19.py
[2025-02-11T10:20:52.549+0000] {logging_mixin.py:190} INFO - [2025-02-11T10:20:52.548+0000] {dag.py:3239} INFO - Sync 1 DAGs
[2025-02-11T10:20:52.583+0000] {logging_mixin.py:190} INFO - [2025-02-11T10:20:52.583+0000] {dag.py:4180} INFO - Setting next_dagrun for Covid19 to 2025-02-11 10:15:00+00:00, run_after=2025-02-11 10:20:00+00:00
[2025-02-11T10:20:52.609+0000] {processor.py:208} INFO - Processing /opt/airflow/dags/covid_19.py took 0.715 seconds
[2025-02-11T10:21:22.952+0000] {processor.py:186} INFO - Started process (PID=149) to work on /opt/airflow/dags/covid_19.py
[2025-02-11T10:21:22.955+0000] {processor.py:914} INFO - Processing file /opt/airflow/dags/covid_19.py for tasks to queue
[2025-02-11T10:21:22.960+0000] {logging_mixin.py:190} INFO - [2025-02-11T10:21:22.959+0000] {dagbag.py:588} INFO - Filling up the DagBag from /opt/airflow/dags/covid_19.py
[2025-02-11T10:21:23.424+0000] {logging_mixin.py:190} INFO - [2025-02-11T10:21:23.422+0000] {templater.py:94} ERROR - Failed to resolve template field 'sql'
Traceback (most recent call last):
  File "/home/airflow/.local/lib/python3.12/site-packages/airflow/template/templater.py", line 92, in resolve_template_files
    setattr(self, field, env.loader.get_source(env, content)[0])  # type: ignore
                         ^^^^^^^^^^^^^^^^^^^^^^^^^^^^^^^^^^^
  File "/home/airflow/.local/lib/python3.12/site-packages/jinja2/loaders.py", line 207, in get_source
    raise TemplateNotFound(template)
jinja2.exceptions.TemplateNotFound: ./queries/create_dim_date.sql
[2025-02-11T10:21:23.426+0000] {logging_mixin.py:190} INFO - [2025-02-11T10:21:23.425+0000] {templater.py:94} ERROR - Failed to resolve template field 'sql'
Traceback (most recent call last):
  File "/home/airflow/.local/lib/python3.12/site-packages/airflow/template/templater.py", line 92, in resolve_template_files
    setattr(self, field, env.loader.get_source(env, content)[0])  # type: ignore
                         ^^^^^^^^^^^^^^^^^^^^^^^^^^^^^^^^^^^
  File "/home/airflow/.local/lib/python3.12/site-packages/jinja2/loaders.py", line 207, in get_source
    raise TemplateNotFound(template)
jinja2.exceptions.TemplateNotFound: ./queries/create_dim_location.sql
[2025-02-11T10:21:23.427+0000] {logging_mixin.py:190} INFO - [2025-02-11T10:21:23.427+0000] {templater.py:94} ERROR - Failed to resolve template field 'sql'
Traceback (most recent call last):
  File "/home/airflow/.local/lib/python3.12/site-packages/airflow/template/templater.py", line 92, in resolve_template_files
    setattr(self, field, env.loader.get_source(env, content)[0])  # type: ignore
                         ^^^^^^^^^^^^^^^^^^^^^^^^^^^^^^^^^^^
  File "/home/airflow/.local/lib/python3.12/site-packages/jinja2/loaders.py", line 207, in get_source
    raise TemplateNotFound(template)
jinja2.exceptions.TemplateNotFound: queries/create_fact_table.sql
[2025-02-11T10:21:23.434+0000] {processor.py:925} INFO - DAG(s) 'Covid19' retrieved from /opt/airflow/dags/covid_19.py
[2025-02-11T10:21:23.477+0000] {logging_mixin.py:190} INFO - [2025-02-11T10:21:23.476+0000] {dag.py:3239} INFO - Sync 1 DAGs
[2025-02-11T10:21:23.510+0000] {logging_mixin.py:190} INFO - [2025-02-11T10:21:23.510+0000] {dag.py:4180} INFO - Setting next_dagrun for Covid19 to 2025-02-11 10:15:00+00:00, run_after=2025-02-11 10:20:00+00:00
[2025-02-11T10:21:23.557+0000] {processor.py:208} INFO - Processing /opt/airflow/dags/covid_19.py took 0.616 seconds
[2025-02-11T10:21:49.138+0000] {processor.py:186} INFO - Started process (PID=157) to work on /opt/airflow/dags/covid_19.py
[2025-02-11T10:21:49.140+0000] {processor.py:914} INFO - Processing file /opt/airflow/dags/covid_19.py for tasks to queue
[2025-02-11T10:21:49.149+0000] {logging_mixin.py:190} INFO - [2025-02-11T10:21:49.148+0000] {dagbag.py:588} INFO - Filling up the DagBag from /opt/airflow/dags/covid_19.py
[2025-02-11T10:21:50.034+0000] {logging_mixin.py:190} INFO - [2025-02-11T10:21:50.033+0000] {templater.py:94} ERROR - Failed to resolve template field 'sql'
Traceback (most recent call last):
  File "/home/airflow/.local/lib/python3.12/site-packages/airflow/template/templater.py", line 92, in resolve_template_files
    setattr(self, field, env.loader.get_source(env, content)[0])  # type: ignore
                         ^^^^^^^^^^^^^^^^^^^^^^^^^^^^^^^^^^^
  File "/home/airflow/.local/lib/python3.12/site-packages/jinja2/loaders.py", line 207, in get_source
    raise TemplateNotFound(template)
jinja2.exceptions.TemplateNotFound: ./queries/create_dim_date.sql
[2025-02-11T10:21:50.036+0000] {logging_mixin.py:190} INFO - [2025-02-11T10:21:50.035+0000] {templater.py:94} ERROR - Failed to resolve template field 'sql'
Traceback (most recent call last):
  File "/home/airflow/.local/lib/python3.12/site-packages/airflow/template/templater.py", line 92, in resolve_template_files
    setattr(self, field, env.loader.get_source(env, content)[0])  # type: ignore
                         ^^^^^^^^^^^^^^^^^^^^^^^^^^^^^^^^^^^
  File "/home/airflow/.local/lib/python3.12/site-packages/jinja2/loaders.py", line 207, in get_source
    raise TemplateNotFound(template)
jinja2.exceptions.TemplateNotFound: ./queries/create_dim_location.sql
[2025-02-11T10:21:50.036+0000] {logging_mixin.py:190} INFO - [2025-02-11T10:21:50.036+0000] {templater.py:94} ERROR - Failed to resolve template field 'sql'
Traceback (most recent call last):
  File "/home/airflow/.local/lib/python3.12/site-packages/airflow/template/templater.py", line 92, in resolve_template_files
    setattr(self, field, env.loader.get_source(env, content)[0])  # type: ignore
                         ^^^^^^^^^^^^^^^^^^^^^^^^^^^^^^^^^^^
  File "/home/airflow/.local/lib/python3.12/site-packages/jinja2/loaders.py", line 207, in get_source
    raise TemplateNotFound(template)
jinja2.exceptions.TemplateNotFound: queries/create_fact_table.sql
[2025-02-11T10:21:50.040+0000] {processor.py:925} INFO - DAG(s) 'Covid19' retrieved from /opt/airflow/dags/covid_19.py
[2025-02-11T10:21:50.070+0000] {logging_mixin.py:190} INFO - [2025-02-11T10:21:50.070+0000] {dag.py:3239} INFO - Sync 1 DAGs
[2025-02-11T10:21:50.168+0000] {logging_mixin.py:190} INFO - [2025-02-11T10:21:50.168+0000] {dag.py:4180} INFO - Setting next_dagrun for Covid19 to 2025-02-11 10:15:00+00:00, run_after=2025-02-11 10:20:00+00:00
[2025-02-11T10:21:50.704+0000] {processor.py:208} INFO - Processing /opt/airflow/dags/covid_19.py took 1.589 seconds
[2025-02-11T10:22:21.993+0000] {processor.py:186} INFO - Started process (PID=169) to work on /opt/airflow/dags/covid_19.py
[2025-02-11T10:22:22.000+0000] {processor.py:914} INFO - Processing file /opt/airflow/dags/covid_19.py for tasks to queue
[2025-02-11T10:22:22.081+0000] {logging_mixin.py:190} INFO - [2025-02-11T10:22:22.074+0000] {dagbag.py:588} INFO - Filling up the DagBag from /opt/airflow/dags/covid_19.py
[2025-02-11T10:22:23.682+0000] {logging_mixin.py:190} INFO - [2025-02-11T10:22:23.677+0000] {templater.py:94} ERROR - Failed to resolve template field 'sql'
Traceback (most recent call last):
  File "/home/airflow/.local/lib/python3.12/site-packages/airflow/template/templater.py", line 92, in resolve_template_files
    setattr(self, field, env.loader.get_source(env, content)[0])  # type: ignore
                         ^^^^^^^^^^^^^^^^^^^^^^^^^^^^^^^^^^^
  File "/home/airflow/.local/lib/python3.12/site-packages/jinja2/loaders.py", line 207, in get_source
    raise TemplateNotFound(template)
jinja2.exceptions.TemplateNotFound: ./queries/create_dim_date.sql
[2025-02-11T10:22:23.684+0000] {logging_mixin.py:190} INFO - [2025-02-11T10:22:23.684+0000] {templater.py:94} ERROR - Failed to resolve template field 'sql'
Traceback (most recent call last):
  File "/home/airflow/.local/lib/python3.12/site-packages/airflow/template/templater.py", line 92, in resolve_template_files
    setattr(self, field, env.loader.get_source(env, content)[0])  # type: ignore
                         ^^^^^^^^^^^^^^^^^^^^^^^^^^^^^^^^^^^
  File "/home/airflow/.local/lib/python3.12/site-packages/jinja2/loaders.py", line 207, in get_source
    raise TemplateNotFound(template)
jinja2.exceptions.TemplateNotFound: ./queries/create_dim_location.sql
[2025-02-11T10:22:23.687+0000] {logging_mixin.py:190} INFO - [2025-02-11T10:22:23.686+0000] {templater.py:94} ERROR - Failed to resolve template field 'sql'
Traceback (most recent call last):
  File "/home/airflow/.local/lib/python3.12/site-packages/airflow/template/templater.py", line 92, in resolve_template_files
    setattr(self, field, env.loader.get_source(env, content)[0])  # type: ignore
                         ^^^^^^^^^^^^^^^^^^^^^^^^^^^^^^^^^^^
  File "/home/airflow/.local/lib/python3.12/site-packages/jinja2/loaders.py", line 207, in get_source
    raise TemplateNotFound(template)
jinja2.exceptions.TemplateNotFound: queries/create_fact_table.sql
[2025-02-11T10:22:23.712+0000] {processor.py:925} INFO - DAG(s) 'Covid19' retrieved from /opt/airflow/dags/covid_19.py
[2025-02-11T10:22:23.896+0000] {logging_mixin.py:190} INFO - [2025-02-11T10:22:23.895+0000] {dag.py:3239} INFO - Sync 1 DAGs
[2025-02-11T10:22:23.977+0000] {logging_mixin.py:190} INFO - [2025-02-11T10:22:23.977+0000] {dag.py:4180} INFO - Setting next_dagrun for Covid19 to 2025-02-11 10:20:00+00:00, run_after=2025-02-11 10:25:00+00:00
[2025-02-11T10:22:24.026+0000] {processor.py:208} INFO - Processing /opt/airflow/dags/covid_19.py took 2.120 seconds
[2025-02-11T10:22:55.213+0000] {processor.py:186} INFO - Started process (PID=182) to work on /opt/airflow/dags/covid_19.py
[2025-02-11T10:22:55.269+0000] {processor.py:914} INFO - Processing file /opt/airflow/dags/covid_19.py for tasks to queue
[2025-02-11T10:22:55.271+0000] {logging_mixin.py:190} INFO - [2025-02-11T10:22:55.271+0000] {dagbag.py:588} INFO - Filling up the DagBag from /opt/airflow/dags/covid_19.py
[2025-02-11T10:22:57.782+0000] {logging_mixin.py:190} INFO - [2025-02-11T10:22:57.776+0000] {templater.py:94} ERROR - Failed to resolve template field 'sql'
Traceback (most recent call last):
  File "/home/airflow/.local/lib/python3.12/site-packages/airflow/template/templater.py", line 92, in resolve_template_files
    setattr(self, field, env.loader.get_source(env, content)[0])  # type: ignore
                         ^^^^^^^^^^^^^^^^^^^^^^^^^^^^^^^^^^^
  File "/home/airflow/.local/lib/python3.12/site-packages/jinja2/loaders.py", line 207, in get_source
    raise TemplateNotFound(template)
jinja2.exceptions.TemplateNotFound: ./queries/create_dim_date.sql
[2025-02-11T10:22:57.785+0000] {logging_mixin.py:190} INFO - [2025-02-11T10:22:57.784+0000] {templater.py:94} ERROR - Failed to resolve template field 'sql'
Traceback (most recent call last):
  File "/home/airflow/.local/lib/python3.12/site-packages/airflow/template/templater.py", line 92, in resolve_template_files
    setattr(self, field, env.loader.get_source(env, content)[0])  # type: ignore
                         ^^^^^^^^^^^^^^^^^^^^^^^^^^^^^^^^^^^
  File "/home/airflow/.local/lib/python3.12/site-packages/jinja2/loaders.py", line 207, in get_source
    raise TemplateNotFound(template)
jinja2.exceptions.TemplateNotFound: ./queries/create_dim_location.sql
[2025-02-11T10:22:57.788+0000] {logging_mixin.py:190} INFO - [2025-02-11T10:22:57.787+0000] {templater.py:94} ERROR - Failed to resolve template field 'sql'
Traceback (most recent call last):
  File "/home/airflow/.local/lib/python3.12/site-packages/airflow/template/templater.py", line 92, in resolve_template_files
    setattr(self, field, env.loader.get_source(env, content)[0])  # type: ignore
                         ^^^^^^^^^^^^^^^^^^^^^^^^^^^^^^^^^^^
  File "/home/airflow/.local/lib/python3.12/site-packages/jinja2/loaders.py", line 207, in get_source
    raise TemplateNotFound(template)
jinja2.exceptions.TemplateNotFound: queries/create_fact_table.sql
[2025-02-11T10:22:57.814+0000] {processor.py:925} INFO - DAG(s) 'Covid19' retrieved from /opt/airflow/dags/covid_19.py
[2025-02-11T10:22:57.892+0000] {logging_mixin.py:190} INFO - [2025-02-11T10:22:57.892+0000] {dag.py:3239} INFO - Sync 1 DAGs
[2025-02-11T10:22:57.923+0000] {logging_mixin.py:190} INFO - [2025-02-11T10:22:57.923+0000] {dag.py:4180} INFO - Setting next_dagrun for Covid19 to 2025-02-11 10:20:00+00:00, run_after=2025-02-11 10:25:00+00:00
[2025-02-11T10:22:57.954+0000] {processor.py:208} INFO - Processing /opt/airflow/dags/covid_19.py took 3.125 seconds
[2025-02-11T10:23:28.142+0000] {processor.py:186} INFO - Started process (PID=196) to work on /opt/airflow/dags/covid_19.py
[2025-02-11T10:23:28.145+0000] {processor.py:914} INFO - Processing file /opt/airflow/dags/covid_19.py for tasks to queue
[2025-02-11T10:23:28.151+0000] {logging_mixin.py:190} INFO - [2025-02-11T10:23:28.148+0000] {dagbag.py:588} INFO - Filling up the DagBag from /opt/airflow/dags/covid_19.py
[2025-02-11T10:23:29.241+0000] {logging_mixin.py:190} INFO - [2025-02-11T10:23:29.236+0000] {templater.py:94} ERROR - Failed to resolve template field 'sql'
Traceback (most recent call last):
  File "/home/airflow/.local/lib/python3.12/site-packages/airflow/template/templater.py", line 92, in resolve_template_files
    setattr(self, field, env.loader.get_source(env, content)[0])  # type: ignore
                         ^^^^^^^^^^^^^^^^^^^^^^^^^^^^^^^^^^^
  File "/home/airflow/.local/lib/python3.12/site-packages/jinja2/loaders.py", line 207, in get_source
    raise TemplateNotFound(template)
jinja2.exceptions.TemplateNotFound: ./queries/create_dim_date.sql
[2025-02-11T10:23:29.243+0000] {logging_mixin.py:190} INFO - [2025-02-11T10:23:29.242+0000] {templater.py:94} ERROR - Failed to resolve template field 'sql'
Traceback (most recent call last):
  File "/home/airflow/.local/lib/python3.12/site-packages/airflow/template/templater.py", line 92, in resolve_template_files
    setattr(self, field, env.loader.get_source(env, content)[0])  # type: ignore
                         ^^^^^^^^^^^^^^^^^^^^^^^^^^^^^^^^^^^
  File "/home/airflow/.local/lib/python3.12/site-packages/jinja2/loaders.py", line 207, in get_source
    raise TemplateNotFound(template)
jinja2.exceptions.TemplateNotFound: ./queries/create_dim_location.sql
[2025-02-11T10:23:29.245+0000] {logging_mixin.py:190} INFO - [2025-02-11T10:23:29.244+0000] {templater.py:94} ERROR - Failed to resolve template field 'sql'
Traceback (most recent call last):
  File "/home/airflow/.local/lib/python3.12/site-packages/airflow/template/templater.py", line 92, in resolve_template_files
    setattr(self, field, env.loader.get_source(env, content)[0])  # type: ignore
                         ^^^^^^^^^^^^^^^^^^^^^^^^^^^^^^^^^^^
  File "/home/airflow/.local/lib/python3.12/site-packages/jinja2/loaders.py", line 207, in get_source
    raise TemplateNotFound(template)
jinja2.exceptions.TemplateNotFound: queries/create_fact_table.sql
[2025-02-11T10:23:29.261+0000] {processor.py:925} INFO - DAG(s) 'Covid19' retrieved from /opt/airflow/dags/covid_19.py
[2025-02-11T10:23:29.362+0000] {logging_mixin.py:190} INFO - [2025-02-11T10:23:29.362+0000] {dag.py:3239} INFO - Sync 1 DAGs
[2025-02-11T10:23:29.391+0000] {logging_mixin.py:190} INFO - [2025-02-11T10:23:29.391+0000] {dag.py:4180} INFO - Setting next_dagrun for Covid19 to 2025-02-11 10:20:00+00:00, run_after=2025-02-11 10:25:00+00:00
[2025-02-11T10:23:29.420+0000] {processor.py:208} INFO - Processing /opt/airflow/dags/covid_19.py took 1.295 seconds
[2025-02-11T10:23:59.777+0000] {processor.py:186} INFO - Started process (PID=205) to work on /opt/airflow/dags/covid_19.py
[2025-02-11T10:23:59.780+0000] {processor.py:914} INFO - Processing file /opt/airflow/dags/covid_19.py for tasks to queue
[2025-02-11T10:23:59.785+0000] {logging_mixin.py:190} INFO - [2025-02-11T10:23:59.785+0000] {dagbag.py:588} INFO - Filling up the DagBag from /opt/airflow/dags/covid_19.py
[2025-02-11T10:24:00.893+0000] {logging_mixin.py:190} INFO - [2025-02-11T10:24:00.885+0000] {templater.py:94} ERROR - Failed to resolve template field 'sql'
Traceback (most recent call last):
  File "/home/airflow/.local/lib/python3.12/site-packages/airflow/template/templater.py", line 92, in resolve_template_files
    setattr(self, field, env.loader.get_source(env, content)[0])  # type: ignore
                         ^^^^^^^^^^^^^^^^^^^^^^^^^^^^^^^^^^^
  File "/home/airflow/.local/lib/python3.12/site-packages/jinja2/loaders.py", line 207, in get_source
    raise TemplateNotFound(template)
jinja2.exceptions.TemplateNotFound: ./queries/create_dim_date.sql
[2025-02-11T10:24:00.896+0000] {logging_mixin.py:190} INFO - [2025-02-11T10:24:00.895+0000] {templater.py:94} ERROR - Failed to resolve template field 'sql'
Traceback (most recent call last):
  File "/home/airflow/.local/lib/python3.12/site-packages/airflow/template/templater.py", line 92, in resolve_template_files
    setattr(self, field, env.loader.get_source(env, content)[0])  # type: ignore
                         ^^^^^^^^^^^^^^^^^^^^^^^^^^^^^^^^^^^
  File "/home/airflow/.local/lib/python3.12/site-packages/jinja2/loaders.py", line 207, in get_source
    raise TemplateNotFound(template)
jinja2.exceptions.TemplateNotFound: ./queries/create_dim_location.sql
[2025-02-11T10:24:00.898+0000] {logging_mixin.py:190} INFO - [2025-02-11T10:24:00.897+0000] {templater.py:94} ERROR - Failed to resolve template field 'sql'
Traceback (most recent call last):
  File "/home/airflow/.local/lib/python3.12/site-packages/airflow/template/templater.py", line 92, in resolve_template_files
    setattr(self, field, env.loader.get_source(env, content)[0])  # type: ignore
                         ^^^^^^^^^^^^^^^^^^^^^^^^^^^^^^^^^^^
  File "/home/airflow/.local/lib/python3.12/site-packages/jinja2/loaders.py", line 207, in get_source
    raise TemplateNotFound(template)
jinja2.exceptions.TemplateNotFound: queries/create_fact_table.sql
[2025-02-11T10:24:00.919+0000] {processor.py:925} INFO - DAG(s) 'Covid19' retrieved from /opt/airflow/dags/covid_19.py
[2025-02-11T10:24:01.075+0000] {logging_mixin.py:190} INFO - [2025-02-11T10:24:01.074+0000] {dag.py:3239} INFO - Sync 1 DAGs
[2025-02-11T10:24:01.176+0000] {logging_mixin.py:190} INFO - [2025-02-11T10:24:01.175+0000] {dag.py:4180} INFO - Setting next_dagrun for Covid19 to 2025-02-11 10:20:00+00:00, run_after=2025-02-11 10:25:00+00:00
[2025-02-11T10:24:01.267+0000] {processor.py:208} INFO - Processing /opt/airflow/dags/covid_19.py took 1.505 seconds
[2025-02-11T10:24:31.765+0000] {processor.py:186} INFO - Started process (PID=213) to work on /opt/airflow/dags/covid_19.py
[2025-02-11T10:24:31.767+0000] {processor.py:914} INFO - Processing file /opt/airflow/dags/covid_19.py for tasks to queue
[2025-02-11T10:24:31.770+0000] {logging_mixin.py:190} INFO - [2025-02-11T10:24:31.769+0000] {dagbag.py:588} INFO - Filling up the DagBag from /opt/airflow/dags/covid_19.py
[2025-02-11T10:24:32.599+0000] {logging_mixin.py:190} INFO - [2025-02-11T10:24:32.594+0000] {templater.py:94} ERROR - Failed to resolve template field 'sql'
Traceback (most recent call last):
  File "/home/airflow/.local/lib/python3.12/site-packages/airflow/template/templater.py", line 92, in resolve_template_files
    setattr(self, field, env.loader.get_source(env, content)[0])  # type: ignore
                         ^^^^^^^^^^^^^^^^^^^^^^^^^^^^^^^^^^^
  File "/home/airflow/.local/lib/python3.12/site-packages/jinja2/loaders.py", line 207, in get_source
    raise TemplateNotFound(template)
jinja2.exceptions.TemplateNotFound: ./queries/create_dim_date.sql
[2025-02-11T10:24:32.601+0000] {logging_mixin.py:190} INFO - [2025-02-11T10:24:32.601+0000] {templater.py:94} ERROR - Failed to resolve template field 'sql'
Traceback (most recent call last):
  File "/home/airflow/.local/lib/python3.12/site-packages/airflow/template/templater.py", line 92, in resolve_template_files
    setattr(self, field, env.loader.get_source(env, content)[0])  # type: ignore
                         ^^^^^^^^^^^^^^^^^^^^^^^^^^^^^^^^^^^
  File "/home/airflow/.local/lib/python3.12/site-packages/jinja2/loaders.py", line 207, in get_source
    raise TemplateNotFound(template)
jinja2.exceptions.TemplateNotFound: ./queries/create_dim_location.sql
[2025-02-11T10:24:32.602+0000] {logging_mixin.py:190} INFO - [2025-02-11T10:24:32.602+0000] {templater.py:94} ERROR - Failed to resolve template field 'sql'
Traceback (most recent call last):
  File "/home/airflow/.local/lib/python3.12/site-packages/airflow/template/templater.py", line 92, in resolve_template_files
    setattr(self, field, env.loader.get_source(env, content)[0])  # type: ignore
                         ^^^^^^^^^^^^^^^^^^^^^^^^^^^^^^^^^^^
  File "/home/airflow/.local/lib/python3.12/site-packages/jinja2/loaders.py", line 207, in get_source
    raise TemplateNotFound(template)
jinja2.exceptions.TemplateNotFound: queries/create_fact_table.sql
[2025-02-11T10:24:32.626+0000] {processor.py:925} INFO - DAG(s) 'Covid19' retrieved from /opt/airflow/dags/covid_19.py
[2025-02-11T10:24:32.728+0000] {logging_mixin.py:190} INFO - [2025-02-11T10:24:32.728+0000] {dag.py:3239} INFO - Sync 1 DAGs
[2025-02-11T10:24:32.762+0000] {logging_mixin.py:190} INFO - [2025-02-11T10:24:32.762+0000] {dag.py:4180} INFO - Setting next_dagrun for Covid19 to 2025-02-11 10:20:00+00:00, run_after=2025-02-11 10:25:00+00:00
[2025-02-11T10:24:32.792+0000] {processor.py:208} INFO - Processing /opt/airflow/dags/covid_19.py took 1.034 seconds
[2025-02-11T10:25:03.348+0000] {processor.py:186} INFO - Started process (PID=222) to work on /opt/airflow/dags/covid_19.py
[2025-02-11T10:25:03.350+0000] {processor.py:914} INFO - Processing file /opt/airflow/dags/covid_19.py for tasks to queue
[2025-02-11T10:25:03.355+0000] {logging_mixin.py:190} INFO - [2025-02-11T10:25:03.354+0000] {dagbag.py:588} INFO - Filling up the DagBag from /opt/airflow/dags/covid_19.py
[2025-02-11T10:25:04.527+0000] {logging_mixin.py:190} INFO - [2025-02-11T10:25:04.520+0000] {templater.py:94} ERROR - Failed to resolve template field 'sql'
Traceback (most recent call last):
  File "/home/airflow/.local/lib/python3.12/site-packages/airflow/template/templater.py", line 92, in resolve_template_files
    setattr(self, field, env.loader.get_source(env, content)[0])  # type: ignore
                         ^^^^^^^^^^^^^^^^^^^^^^^^^^^^^^^^^^^
  File "/home/airflow/.local/lib/python3.12/site-packages/jinja2/loaders.py", line 207, in get_source
    raise TemplateNotFound(template)
jinja2.exceptions.TemplateNotFound: ./queries/create_dim_date.sql
[2025-02-11T10:25:04.530+0000] {logging_mixin.py:190} INFO - [2025-02-11T10:25:04.530+0000] {templater.py:94} ERROR - Failed to resolve template field 'sql'
Traceback (most recent call last):
  File "/home/airflow/.local/lib/python3.12/site-packages/airflow/template/templater.py", line 92, in resolve_template_files
    setattr(self, field, env.loader.get_source(env, content)[0])  # type: ignore
                         ^^^^^^^^^^^^^^^^^^^^^^^^^^^^^^^^^^^
  File "/home/airflow/.local/lib/python3.12/site-packages/jinja2/loaders.py", line 207, in get_source
    raise TemplateNotFound(template)
jinja2.exceptions.TemplateNotFound: ./queries/create_dim_location.sql
[2025-02-11T10:25:04.531+0000] {logging_mixin.py:190} INFO - [2025-02-11T10:25:04.531+0000] {templater.py:94} ERROR - Failed to resolve template field 'sql'
Traceback (most recent call last):
  File "/home/airflow/.local/lib/python3.12/site-packages/airflow/template/templater.py", line 92, in resolve_template_files
    setattr(self, field, env.loader.get_source(env, content)[0])  # type: ignore
                         ^^^^^^^^^^^^^^^^^^^^^^^^^^^^^^^^^^^
  File "/home/airflow/.local/lib/python3.12/site-packages/jinja2/loaders.py", line 207, in get_source
    raise TemplateNotFound(template)
jinja2.exceptions.TemplateNotFound: queries/create_fact_table.sql
[2025-02-11T10:25:04.554+0000] {processor.py:925} INFO - DAG(s) 'Covid19' retrieved from /opt/airflow/dags/covid_19.py
[2025-02-11T10:25:04.642+0000] {logging_mixin.py:190} INFO - [2025-02-11T10:25:04.642+0000] {dag.py:3239} INFO - Sync 1 DAGs
[2025-02-11T10:25:04.680+0000] {logging_mixin.py:190} INFO - [2025-02-11T10:25:04.680+0000] {dag.py:4180} INFO - Setting next_dagrun for Covid19 to 2025-02-11 10:20:00+00:00, run_after=2025-02-11 10:25:00+00:00
[2025-02-11T10:25:04.715+0000] {processor.py:208} INFO - Processing /opt/airflow/dags/covid_19.py took 1.375 seconds
[2025-02-11T10:28:42.350+0000] {processor.py:186} INFO - Started process (PID=40) to work on /opt/airflow/dags/covid_19.py
[2025-02-11T10:28:42.386+0000] {processor.py:914} INFO - Processing file /opt/airflow/dags/covid_19.py for tasks to queue
[2025-02-11T10:28:42.388+0000] {logging_mixin.py:190} INFO - [2025-02-11T10:28:42.388+0000] {dagbag.py:588} INFO - Filling up the DagBag from /opt/airflow/dags/covid_19.py
[2025-02-11T10:29:17.990+0000] {logging_mixin.py:190} INFO - [2025-02-11T10:29:17.947+0000] {timeout.py:68} ERROR - Process timed out, PID: 40
[2025-02-11T10:29:18.040+0000] {logging_mixin.py:190} INFO - [2025-02-11T10:29:17.993+0000] {dagbag.py:387} ERROR - Failed to import: /opt/airflow/dags/covid_19.py
Traceback (most recent call last):
  File "/home/airflow/.local/lib/python3.12/site-packages/airflow/models/dagbag.py", line 383, in parse
    loader.exec_module(new_module)
  File "<frozen importlib._bootstrap_external>", line 999, in exec_module
  File "<frozen importlib._bootstrap>", line 488, in _call_with_frames_removed
  File "/opt/airflow/dags/covid_19.py", line 5, in <module>
    import pandas as pd
  File "/home/airflow/.local/lib/python3.12/site-packages/pandas/__init__.py", line 46, in <module>
    from pandas.core.api import (
  File "/home/airflow/.local/lib/python3.12/site-packages/pandas/core/api.py", line 28, in <module>
    from pandas.core.arrays import Categorical
  File "/home/airflow/.local/lib/python3.12/site-packages/pandas/core/arrays/__init__.py", line 1, in <module>
    from pandas.core.arrays.arrow import ArrowExtensionArray
  File "/home/airflow/.local/lib/python3.12/site-packages/pandas/core/arrays/arrow/__init__.py", line 1, in <module>
    from pandas.core.arrays.arrow.array import ArrowExtensionArray
  File "/home/airflow/.local/lib/python3.12/site-packages/pandas/core/arrays/arrow/array.py", line 58, in <module>
    from pandas.core.arrays.string_ import StringDtype
  File "/home/airflow/.local/lib/python3.12/site-packages/pandas/core/arrays/string_.py", line 39, in <module>
    from pandas.core.arrays.floating import (
  File "<frozen importlib._bootstrap>", line 1360, in _find_and_load
  File "<frozen importlib._bootstrap>", line 1331, in _find_and_load_unlocked
  File "<frozen importlib._bootstrap>", line 935, in _load_unlocked
  File "<frozen importlib._bootstrap_external>", line 995, in exec_module
  File "<frozen importlib._bootstrap_external>", line 1134, in get_code
  File "<frozen importlib._bootstrap>", line 491, in _verbose_message
  File "/home/airflow/.local/lib/python3.12/site-packages/airflow/utils/timeout.py", line 69, in handle_timeout
    raise AirflowTaskTimeout(self.error_message)
airflow.exceptions.AirflowTaskTimeout: DagBag import timeout for /opt/airflow/dags/covid_19.py after 30.0s.
Please take a look at these docs to improve your DAG import time:
* https://airflow.apache.org/docs/apache-airflow/2.10.4/best-practices.html#top-level-python-code
* https://airflow.apache.org/docs/apache-airflow/2.10.4/best-practices.html#reducing-dag-complexity, PID: 40
[2025-02-11T10:29:18.047+0000] {processor.py:927} WARNING - No viable dags retrieved from /opt/airflow/dags/covid_19.py
[2025-02-11T10:29:18.174+0000] {processor.py:208} INFO - Processing /opt/airflow/dags/covid_19.py took 35.825 seconds
[2025-02-11T10:29:48.691+0000] {processor.py:186} INFO - Started process (PID=48) to work on /opt/airflow/dags/covid_19.py
[2025-02-11T10:29:48.694+0000] {processor.py:914} INFO - Processing file /opt/airflow/dags/covid_19.py for tasks to queue
[2025-02-11T10:29:48.704+0000] {logging_mixin.py:190} INFO - [2025-02-11T10:29:48.700+0000] {dagbag.py:588} INFO - Filling up the DagBag from /opt/airflow/dags/covid_19.py
[2025-02-11T10:29:51.617+0000] {logging_mixin.py:190} INFO - [2025-02-11T10:29:51.612+0000] {templater.py:94} ERROR - Failed to resolve template field 'sql'
Traceback (most recent call last):
  File "/home/airflow/.local/lib/python3.12/site-packages/airflow/template/templater.py", line 92, in resolve_template_files
    setattr(self, field, env.loader.get_source(env, content)[0])  # type: ignore
                         ^^^^^^^^^^^^^^^^^^^^^^^^^^^^^^^^^^^
  File "/home/airflow/.local/lib/python3.12/site-packages/jinja2/loaders.py", line 207, in get_source
    raise TemplateNotFound(template)
jinja2.exceptions.TemplateNotFound: ./queries/create_dim_date.sql
[2025-02-11T10:29:51.619+0000] {logging_mixin.py:190} INFO - [2025-02-11T10:29:51.619+0000] {templater.py:94} ERROR - Failed to resolve template field 'sql'
Traceback (most recent call last):
  File "/home/airflow/.local/lib/python3.12/site-packages/airflow/template/templater.py", line 92, in resolve_template_files
    setattr(self, field, env.loader.get_source(env, content)[0])  # type: ignore
                         ^^^^^^^^^^^^^^^^^^^^^^^^^^^^^^^^^^^
  File "/home/airflow/.local/lib/python3.12/site-packages/jinja2/loaders.py", line 207, in get_source
    raise TemplateNotFound(template)
jinja2.exceptions.TemplateNotFound: ./queries/create_dim_location.sql
[2025-02-11T10:29:51.621+0000] {logging_mixin.py:190} INFO - [2025-02-11T10:29:51.620+0000] {templater.py:94} ERROR - Failed to resolve template field 'sql'
Traceback (most recent call last):
  File "/home/airflow/.local/lib/python3.12/site-packages/airflow/template/templater.py", line 92, in resolve_template_files
    setattr(self, field, env.loader.get_source(env, content)[0])  # type: ignore
                         ^^^^^^^^^^^^^^^^^^^^^^^^^^^^^^^^^^^
  File "/home/airflow/.local/lib/python3.12/site-packages/jinja2/loaders.py", line 207, in get_source
    raise TemplateNotFound(template)
jinja2.exceptions.TemplateNotFound: queries/create_fact_table.sql
[2025-02-11T10:29:51.649+0000] {processor.py:925} INFO - DAG(s) 'Covid19' retrieved from /opt/airflow/dags/covid_19.py
[2025-02-11T10:29:52.438+0000] {logging_mixin.py:190} INFO - [2025-02-11T10:29:52.437+0000] {dag.py:3239} INFO - Sync 1 DAGs
[2025-02-11T10:29:52.482+0000] {logging_mixin.py:190} INFO - [2025-02-11T10:29:52.482+0000] {dag.py:4180} INFO - Setting next_dagrun for Covid19 to 2025-02-11 10:20:00+00:00, run_after=2025-02-11 10:25:00+00:00
[2025-02-11T10:29:52.824+0000] {processor.py:208} INFO - Processing /opt/airflow/dags/covid_19.py took 4.288 seconds
[2025-02-11T10:30:23.621+0000] {processor.py:186} INFO - Started process (PID=62) to work on /opt/airflow/dags/covid_19.py
[2025-02-11T10:30:23.623+0000] {processor.py:914} INFO - Processing file /opt/airflow/dags/covid_19.py for tasks to queue
[2025-02-11T10:30:23.625+0000] {logging_mixin.py:190} INFO - [2025-02-11T10:30:23.625+0000] {dagbag.py:588} INFO - Filling up the DagBag from /opt/airflow/dags/covid_19.py
[2025-02-11T10:30:24.420+0000] {logging_mixin.py:190} INFO - [2025-02-11T10:30:24.419+0000] {templater.py:94} ERROR - Failed to resolve template field 'sql'
Traceback (most recent call last):
  File "/home/airflow/.local/lib/python3.12/site-packages/airflow/template/templater.py", line 92, in resolve_template_files
    setattr(self, field, env.loader.get_source(env, content)[0])  # type: ignore
                         ^^^^^^^^^^^^^^^^^^^^^^^^^^^^^^^^^^^
  File "/home/airflow/.local/lib/python3.12/site-packages/jinja2/loaders.py", line 207, in get_source
    raise TemplateNotFound(template)
jinja2.exceptions.TemplateNotFound: ./queries/create_dim_date.sql
[2025-02-11T10:30:24.421+0000] {logging_mixin.py:190} INFO - [2025-02-11T10:30:24.421+0000] {templater.py:94} ERROR - Failed to resolve template field 'sql'
Traceback (most recent call last):
  File "/home/airflow/.local/lib/python3.12/site-packages/airflow/template/templater.py", line 92, in resolve_template_files
    setattr(self, field, env.loader.get_source(env, content)[0])  # type: ignore
                         ^^^^^^^^^^^^^^^^^^^^^^^^^^^^^^^^^^^
  File "/home/airflow/.local/lib/python3.12/site-packages/jinja2/loaders.py", line 207, in get_source
    raise TemplateNotFound(template)
jinja2.exceptions.TemplateNotFound: ./queries/create_dim_location.sql
[2025-02-11T10:30:24.423+0000] {logging_mixin.py:190} INFO - [2025-02-11T10:30:24.422+0000] {templater.py:94} ERROR - Failed to resolve template field 'sql'
Traceback (most recent call last):
  File "/home/airflow/.local/lib/python3.12/site-packages/airflow/template/templater.py", line 92, in resolve_template_files
    setattr(self, field, env.loader.get_source(env, content)[0])  # type: ignore
                         ^^^^^^^^^^^^^^^^^^^^^^^^^^^^^^^^^^^
  File "/home/airflow/.local/lib/python3.12/site-packages/jinja2/loaders.py", line 207, in get_source
    raise TemplateNotFound(template)
jinja2.exceptions.TemplateNotFound: queries/create_fact_table.sql
[2025-02-11T10:30:24.426+0000] {processor.py:925} INFO - DAG(s) 'Covid19' retrieved from /opt/airflow/dags/covid_19.py
[2025-02-11T10:30:24.446+0000] {logging_mixin.py:190} INFO - [2025-02-11T10:30:24.446+0000] {dag.py:3239} INFO - Sync 1 DAGs
[2025-02-11T10:30:24.466+0000] {logging_mixin.py:190} INFO - [2025-02-11T10:30:24.466+0000] {dag.py:4180} INFO - Setting next_dagrun for Covid19 to 2025-02-11 10:25:00+00:00, run_after=2025-02-11 10:30:00+00:00
[2025-02-11T10:30:24.487+0000] {processor.py:208} INFO - Processing /opt/airflow/dags/covid_19.py took 0.872 seconds
[2025-02-11T10:30:54.752+0000] {processor.py:186} INFO - Started process (PID=70) to work on /opt/airflow/dags/covid_19.py
[2025-02-11T10:30:54.753+0000] {processor.py:914} INFO - Processing file /opt/airflow/dags/covid_19.py for tasks to queue
[2025-02-11T10:30:54.754+0000] {logging_mixin.py:190} INFO - [2025-02-11T10:30:54.754+0000] {dagbag.py:588} INFO - Filling up the DagBag from /opt/airflow/dags/covid_19.py
[2025-02-11T10:30:55.187+0000] {logging_mixin.py:190} INFO - [2025-02-11T10:30:55.186+0000] {templater.py:94} ERROR - Failed to resolve template field 'sql'
Traceback (most recent call last):
  File "/home/airflow/.local/lib/python3.12/site-packages/airflow/template/templater.py", line 92, in resolve_template_files
    setattr(self, field, env.loader.get_source(env, content)[0])  # type: ignore
                         ^^^^^^^^^^^^^^^^^^^^^^^^^^^^^^^^^^^
  File "/home/airflow/.local/lib/python3.12/site-packages/jinja2/loaders.py", line 207, in get_source
    raise TemplateNotFound(template)
jinja2.exceptions.TemplateNotFound: ./queries/create_dim_date.sql
[2025-02-11T10:30:55.189+0000] {logging_mixin.py:190} INFO - [2025-02-11T10:30:55.188+0000] {templater.py:94} ERROR - Failed to resolve template field 'sql'
Traceback (most recent call last):
  File "/home/airflow/.local/lib/python3.12/site-packages/airflow/template/templater.py", line 92, in resolve_template_files
    setattr(self, field, env.loader.get_source(env, content)[0])  # type: ignore
                         ^^^^^^^^^^^^^^^^^^^^^^^^^^^^^^^^^^^
  File "/home/airflow/.local/lib/python3.12/site-packages/jinja2/loaders.py", line 207, in get_source
    raise TemplateNotFound(template)
jinja2.exceptions.TemplateNotFound: ./queries/create_dim_location.sql
[2025-02-11T10:30:55.191+0000] {logging_mixin.py:190} INFO - [2025-02-11T10:30:55.190+0000] {templater.py:94} ERROR - Failed to resolve template field 'sql'
Traceback (most recent call last):
  File "/home/airflow/.local/lib/python3.12/site-packages/airflow/template/templater.py", line 92, in resolve_template_files
    setattr(self, field, env.loader.get_source(env, content)[0])  # type: ignore
                         ^^^^^^^^^^^^^^^^^^^^^^^^^^^^^^^^^^^
  File "/home/airflow/.local/lib/python3.12/site-packages/jinja2/loaders.py", line 207, in get_source
    raise TemplateNotFound(template)
jinja2.exceptions.TemplateNotFound: queries/create_fact_table.sql
[2025-02-11T10:30:55.196+0000] {processor.py:925} INFO - DAG(s) 'Covid19' retrieved from /opt/airflow/dags/covid_19.py
[2025-02-11T10:30:55.219+0000] {logging_mixin.py:190} INFO - [2025-02-11T10:30:55.219+0000] {dag.py:3239} INFO - Sync 1 DAGs
[2025-02-11T10:30:55.242+0000] {logging_mixin.py:190} INFO - [2025-02-11T10:30:55.242+0000] {dag.py:4180} INFO - Setting next_dagrun for Covid19 to 2025-02-11 10:25:00+00:00, run_after=2025-02-11 10:30:00+00:00
[2025-02-11T10:30:55.262+0000] {processor.py:208} INFO - Processing /opt/airflow/dags/covid_19.py took 0.516 seconds
[2025-02-11T10:31:30.698+0000] {processor.py:186} INFO - Started process (PID=96) to work on /opt/airflow/dags/covid_19.py
[2025-02-11T10:31:30.703+0000] {processor.py:914} INFO - Processing file /opt/airflow/dags/covid_19.py for tasks to queue
[2025-02-11T10:31:30.711+0000] {logging_mixin.py:190} INFO - [2025-02-11T10:31:30.710+0000] {dagbag.py:588} INFO - Filling up the DagBag from /opt/airflow/dags/covid_19.py
[2025-02-11T10:31:36.142+0000] {logging_mixin.py:190} INFO - [2025-02-11T10:31:36.137+0000] {templater.py:94} ERROR - Failed to resolve template field 'sql'
Traceback (most recent call last):
  File "/home/airflow/.local/lib/python3.12/site-packages/airflow/template/templater.py", line 92, in resolve_template_files
    setattr(self, field, env.loader.get_source(env, content)[0])  # type: ignore
                         ^^^^^^^^^^^^^^^^^^^^^^^^^^^^^^^^^^^
  File "/home/airflow/.local/lib/python3.12/site-packages/jinja2/loaders.py", line 207, in get_source
    raise TemplateNotFound(template)
jinja2.exceptions.TemplateNotFound: ./queries/create_dim_date.sql
[2025-02-11T10:31:36.144+0000] {logging_mixin.py:190} INFO - [2025-02-11T10:31:36.144+0000] {templater.py:94} ERROR - Failed to resolve template field 'sql'
Traceback (most recent call last):
  File "/home/airflow/.local/lib/python3.12/site-packages/airflow/template/templater.py", line 92, in resolve_template_files
    setattr(self, field, env.loader.get_source(env, content)[0])  # type: ignore
                         ^^^^^^^^^^^^^^^^^^^^^^^^^^^^^^^^^^^
  File "/home/airflow/.local/lib/python3.12/site-packages/jinja2/loaders.py", line 207, in get_source
    raise TemplateNotFound(template)
jinja2.exceptions.TemplateNotFound: ./queries/create_dim_location.sql
[2025-02-11T10:31:36.146+0000] {logging_mixin.py:190} INFO - [2025-02-11T10:31:36.145+0000] {templater.py:94} ERROR - Failed to resolve template field 'sql'
Traceback (most recent call last):
  File "/home/airflow/.local/lib/python3.12/site-packages/airflow/template/templater.py", line 92, in resolve_template_files
    setattr(self, field, env.loader.get_source(env, content)[0])  # type: ignore
                         ^^^^^^^^^^^^^^^^^^^^^^^^^^^^^^^^^^^
  File "/home/airflow/.local/lib/python3.12/site-packages/jinja2/loaders.py", line 207, in get_source
    raise TemplateNotFound(template)
jinja2.exceptions.TemplateNotFound: queries/create_fact_table.sql
[2025-02-11T10:31:36.156+0000] {processor.py:925} INFO - DAG(s) 'Covid19' retrieved from /opt/airflow/dags/covid_19.py
[2025-02-11T10:31:36.230+0000] {logging_mixin.py:190} INFO - [2025-02-11T10:31:36.229+0000] {dag.py:3239} INFO - Sync 1 DAGs
[2025-02-11T10:31:36.289+0000] {logging_mixin.py:190} INFO - [2025-02-11T10:31:36.289+0000] {dag.py:4180} INFO - Setting next_dagrun for Covid19 to 2025-02-11 10:30:00+00:00, run_after=2025-02-11 10:35:00+00:00
[2025-02-11T10:31:36.339+0000] {processor.py:208} INFO - Processing /opt/airflow/dags/covid_19.py took 5.662 seconds
[2025-02-11T10:32:07.210+0000] {processor.py:186} INFO - Started process (PID=110) to work on /opt/airflow/dags/covid_19.py
[2025-02-11T10:32:07.212+0000] {processor.py:914} INFO - Processing file /opt/airflow/dags/covid_19.py for tasks to queue
[2025-02-11T10:32:07.214+0000] {logging_mixin.py:190} INFO - [2025-02-11T10:32:07.214+0000] {dagbag.py:588} INFO - Filling up the DagBag from /opt/airflow/dags/covid_19.py
[2025-02-11T10:32:08.128+0000] {logging_mixin.py:190} INFO - [2025-02-11T10:32:08.127+0000] {templater.py:94} ERROR - Failed to resolve template field 'sql'
Traceback (most recent call last):
  File "/home/airflow/.local/lib/python3.12/site-packages/airflow/template/templater.py", line 92, in resolve_template_files
    setattr(self, field, env.loader.get_source(env, content)[0])  # type: ignore
                         ^^^^^^^^^^^^^^^^^^^^^^^^^^^^^^^^^^^
  File "/home/airflow/.local/lib/python3.12/site-packages/jinja2/loaders.py", line 207, in get_source
    raise TemplateNotFound(template)
jinja2.exceptions.TemplateNotFound: ./queries/create_dim_date.sql
[2025-02-11T10:32:08.130+0000] {logging_mixin.py:190} INFO - [2025-02-11T10:32:08.129+0000] {templater.py:94} ERROR - Failed to resolve template field 'sql'
Traceback (most recent call last):
  File "/home/airflow/.local/lib/python3.12/site-packages/airflow/template/templater.py", line 92, in resolve_template_files
    setattr(self, field, env.loader.get_source(env, content)[0])  # type: ignore
                         ^^^^^^^^^^^^^^^^^^^^^^^^^^^^^^^^^^^
  File "/home/airflow/.local/lib/python3.12/site-packages/jinja2/loaders.py", line 207, in get_source
    raise TemplateNotFound(template)
jinja2.exceptions.TemplateNotFound: ./queries/create_dim_location.sql
[2025-02-11T10:32:08.131+0000] {logging_mixin.py:190} INFO - [2025-02-11T10:32:08.131+0000] {templater.py:94} ERROR - Failed to resolve template field 'sql'
Traceback (most recent call last):
  File "/home/airflow/.local/lib/python3.12/site-packages/airflow/template/templater.py", line 92, in resolve_template_files
    setattr(self, field, env.loader.get_source(env, content)[0])  # type: ignore
                         ^^^^^^^^^^^^^^^^^^^^^^^^^^^^^^^^^^^
  File "/home/airflow/.local/lib/python3.12/site-packages/jinja2/loaders.py", line 207, in get_source
    raise TemplateNotFound(template)
jinja2.exceptions.TemplateNotFound: queries/create_fact_table.sql
[2025-02-11T10:32:08.135+0000] {processor.py:925} INFO - DAG(s) 'Covid19' retrieved from /opt/airflow/dags/covid_19.py
[2025-02-11T10:32:08.166+0000] {logging_mixin.py:190} INFO - [2025-02-11T10:32:08.165+0000] {dag.py:3239} INFO - Sync 1 DAGs
[2025-02-11T10:32:08.197+0000] {logging_mixin.py:190} INFO - [2025-02-11T10:32:08.197+0000] {dag.py:4180} INFO - Setting next_dagrun for Covid19 to 2025-02-11 10:30:00+00:00, run_after=2025-02-11 10:35:00+00:00
[2025-02-11T10:32:08.224+0000] {processor.py:208} INFO - Processing /opt/airflow/dags/covid_19.py took 1.023 seconds
[2025-02-11T10:32:38.549+0000] {processor.py:186} INFO - Started process (PID=118) to work on /opt/airflow/dags/covid_19.py
[2025-02-11T10:32:38.551+0000] {processor.py:914} INFO - Processing file /opt/airflow/dags/covid_19.py for tasks to queue
[2025-02-11T10:32:38.552+0000] {logging_mixin.py:190} INFO - [2025-02-11T10:32:38.552+0000] {dagbag.py:588} INFO - Filling up the DagBag from /opt/airflow/dags/covid_19.py
[2025-02-11T10:32:39.357+0000] {logging_mixin.py:190} INFO - [2025-02-11T10:32:39.355+0000] {templater.py:94} ERROR - Failed to resolve template field 'sql'
Traceback (most recent call last):
  File "/home/airflow/.local/lib/python3.12/site-packages/airflow/template/templater.py", line 92, in resolve_template_files
    setattr(self, field, env.loader.get_source(env, content)[0])  # type: ignore
                         ^^^^^^^^^^^^^^^^^^^^^^^^^^^^^^^^^^^
  File "/home/airflow/.local/lib/python3.12/site-packages/jinja2/loaders.py", line 207, in get_source
    raise TemplateNotFound(template)
jinja2.exceptions.TemplateNotFound: ./queries/create_dim_date.sql
[2025-02-11T10:32:39.360+0000] {logging_mixin.py:190} INFO - [2025-02-11T10:32:39.359+0000] {templater.py:94} ERROR - Failed to resolve template field 'sql'
Traceback (most recent call last):
  File "/home/airflow/.local/lib/python3.12/site-packages/airflow/template/templater.py", line 92, in resolve_template_files
    setattr(self, field, env.loader.get_source(env, content)[0])  # type: ignore
                         ^^^^^^^^^^^^^^^^^^^^^^^^^^^^^^^^^^^
  File "/home/airflow/.local/lib/python3.12/site-packages/jinja2/loaders.py", line 207, in get_source
    raise TemplateNotFound(template)
jinja2.exceptions.TemplateNotFound: ./queries/create_dim_location.sql
[2025-02-11T10:32:39.362+0000] {logging_mixin.py:190} INFO - [2025-02-11T10:32:39.362+0000] {templater.py:94} ERROR - Failed to resolve template field 'sql'
Traceback (most recent call last):
  File "/home/airflow/.local/lib/python3.12/site-packages/airflow/template/templater.py", line 92, in resolve_template_files
    setattr(self, field, env.loader.get_source(env, content)[0])  # type: ignore
                         ^^^^^^^^^^^^^^^^^^^^^^^^^^^^^^^^^^^
  File "/home/airflow/.local/lib/python3.12/site-packages/jinja2/loaders.py", line 207, in get_source
    raise TemplateNotFound(template)
jinja2.exceptions.TemplateNotFound: queries/create_fact_table.sql
[2025-02-11T10:32:39.367+0000] {processor.py:925} INFO - DAG(s) 'Covid19' retrieved from /opt/airflow/dags/covid_19.py
[2025-02-11T10:32:39.405+0000] {logging_mixin.py:190} INFO - [2025-02-11T10:32:39.405+0000] {dag.py:3239} INFO - Sync 1 DAGs
[2025-02-11T10:32:39.439+0000] {logging_mixin.py:190} INFO - [2025-02-11T10:32:39.439+0000] {dag.py:4180} INFO - Setting next_dagrun for Covid19 to 2025-02-11 10:30:00+00:00, run_after=2025-02-11 10:35:00+00:00
[2025-02-11T10:32:39.466+0000] {processor.py:208} INFO - Processing /opt/airflow/dags/covid_19.py took 0.922 seconds
[2025-02-11T10:33:09.803+0000] {processor.py:186} INFO - Started process (PID=126) to work on /opt/airflow/dags/covid_19.py
[2025-02-11T10:33:09.804+0000] {processor.py:914} INFO - Processing file /opt/airflow/dags/covid_19.py for tasks to queue
[2025-02-11T10:33:09.806+0000] {logging_mixin.py:190} INFO - [2025-02-11T10:33:09.806+0000] {dagbag.py:588} INFO - Filling up the DagBag from /opt/airflow/dags/covid_19.py
[2025-02-11T10:33:10.389+0000] {logging_mixin.py:190} INFO - [2025-02-11T10:33:10.388+0000] {templater.py:94} ERROR - Failed to resolve template field 'sql'
Traceback (most recent call last):
  File "/home/airflow/.local/lib/python3.12/site-packages/airflow/template/templater.py", line 92, in resolve_template_files
    setattr(self, field, env.loader.get_source(env, content)[0])  # type: ignore
                         ^^^^^^^^^^^^^^^^^^^^^^^^^^^^^^^^^^^
  File "/home/airflow/.local/lib/python3.12/site-packages/jinja2/loaders.py", line 207, in get_source
    raise TemplateNotFound(template)
jinja2.exceptions.TemplateNotFound: ./queries/create_dim_date.sql
[2025-02-11T10:33:10.391+0000] {logging_mixin.py:190} INFO - [2025-02-11T10:33:10.391+0000] {templater.py:94} ERROR - Failed to resolve template field 'sql'
Traceback (most recent call last):
  File "/home/airflow/.local/lib/python3.12/site-packages/airflow/template/templater.py", line 92, in resolve_template_files
    setattr(self, field, env.loader.get_source(env, content)[0])  # type: ignore
                         ^^^^^^^^^^^^^^^^^^^^^^^^^^^^^^^^^^^
  File "/home/airflow/.local/lib/python3.12/site-packages/jinja2/loaders.py", line 207, in get_source
    raise TemplateNotFound(template)
jinja2.exceptions.TemplateNotFound: ./queries/create_dim_location.sql
[2025-02-11T10:33:10.393+0000] {logging_mixin.py:190} INFO - [2025-02-11T10:33:10.393+0000] {templater.py:94} ERROR - Failed to resolve template field 'sql'
Traceback (most recent call last):
  File "/home/airflow/.local/lib/python3.12/site-packages/airflow/template/templater.py", line 92, in resolve_template_files
    setattr(self, field, env.loader.get_source(env, content)[0])  # type: ignore
                         ^^^^^^^^^^^^^^^^^^^^^^^^^^^^^^^^^^^
  File "/home/airflow/.local/lib/python3.12/site-packages/jinja2/loaders.py", line 207, in get_source
    raise TemplateNotFound(template)
jinja2.exceptions.TemplateNotFound: queries/create_fact_table.sql
[2025-02-11T10:33:10.401+0000] {processor.py:925} INFO - DAG(s) 'Covid19' retrieved from /opt/airflow/dags/covid_19.py
[2025-02-11T10:33:10.438+0000] {logging_mixin.py:190} INFO - [2025-02-11T10:33:10.438+0000] {dag.py:3239} INFO - Sync 1 DAGs
[2025-02-11T10:33:10.462+0000] {logging_mixin.py:190} INFO - [2025-02-11T10:33:10.462+0000] {dag.py:4180} INFO - Setting next_dagrun for Covid19 to 2025-02-11 10:30:00+00:00, run_after=2025-02-11 10:35:00+00:00
[2025-02-11T10:33:10.482+0000] {processor.py:208} INFO - Processing /opt/airflow/dags/covid_19.py took 0.686 seconds
[2025-02-11T10:33:40.987+0000] {processor.py:186} INFO - Started process (PID=134) to work on /opt/airflow/dags/covid_19.py
[2025-02-11T10:33:40.988+0000] {processor.py:914} INFO - Processing file /opt/airflow/dags/covid_19.py for tasks to queue
[2025-02-11T10:33:40.990+0000] {logging_mixin.py:190} INFO - [2025-02-11T10:33:40.990+0000] {dagbag.py:588} INFO - Filling up the DagBag from /opt/airflow/dags/covid_19.py
[2025-02-11T10:33:41.315+0000] {logging_mixin.py:190} INFO - [2025-02-11T10:33:41.312+0000] {templater.py:94} ERROR - Failed to resolve template field 'sql'
Traceback (most recent call last):
  File "/home/airflow/.local/lib/python3.12/site-packages/airflow/template/templater.py", line 92, in resolve_template_files
    setattr(self, field, env.loader.get_source(env, content)[0])  # type: ignore
                         ^^^^^^^^^^^^^^^^^^^^^^^^^^^^^^^^^^^
  File "/home/airflow/.local/lib/python3.12/site-packages/jinja2/loaders.py", line 207, in get_source
    raise TemplateNotFound(template)
jinja2.exceptions.TemplateNotFound: ./queries/create_dim_date.sql
[2025-02-11T10:33:41.316+0000] {logging_mixin.py:190} INFO - [2025-02-11T10:33:41.316+0000] {templater.py:94} ERROR - Failed to resolve template field 'sql'
Traceback (most recent call last):
  File "/home/airflow/.local/lib/python3.12/site-packages/airflow/template/templater.py", line 92, in resolve_template_files
    setattr(self, field, env.loader.get_source(env, content)[0])  # type: ignore
                         ^^^^^^^^^^^^^^^^^^^^^^^^^^^^^^^^^^^
  File "/home/airflow/.local/lib/python3.12/site-packages/jinja2/loaders.py", line 207, in get_source
    raise TemplateNotFound(template)
jinja2.exceptions.TemplateNotFound: ./queries/create_dim_location.sql
[2025-02-11T10:33:41.318+0000] {logging_mixin.py:190} INFO - [2025-02-11T10:33:41.317+0000] {templater.py:94} ERROR - Failed to resolve template field 'sql'
Traceback (most recent call last):
  File "/home/airflow/.local/lib/python3.12/site-packages/airflow/template/templater.py", line 92, in resolve_template_files
    setattr(self, field, env.loader.get_source(env, content)[0])  # type: ignore
                         ^^^^^^^^^^^^^^^^^^^^^^^^^^^^^^^^^^^
  File "/home/airflow/.local/lib/python3.12/site-packages/jinja2/loaders.py", line 207, in get_source
    raise TemplateNotFound(template)
jinja2.exceptions.TemplateNotFound: queries/create_fact_table.sql
[2025-02-11T10:33:41.322+0000] {processor.py:925} INFO - DAG(s) 'Covid19' retrieved from /opt/airflow/dags/covid_19.py
[2025-02-11T10:33:41.353+0000] {logging_mixin.py:190} INFO - [2025-02-11T10:33:41.353+0000] {dag.py:3239} INFO - Sync 1 DAGs
[2025-02-11T10:33:41.378+0000] {logging_mixin.py:190} INFO - [2025-02-11T10:33:41.377+0000] {dag.py:4180} INFO - Setting next_dagrun for Covid19 to 2025-02-11 10:30:00+00:00, run_after=2025-02-11 10:35:00+00:00
[2025-02-11T10:33:41.401+0000] {processor.py:208} INFO - Processing /opt/airflow/dags/covid_19.py took 0.421 seconds
[2025-02-11T10:34:11.716+0000] {processor.py:186} INFO - Started process (PID=142) to work on /opt/airflow/dags/covid_19.py
[2025-02-11T10:34:11.718+0000] {processor.py:914} INFO - Processing file /opt/airflow/dags/covid_19.py for tasks to queue
[2025-02-11T10:34:11.721+0000] {logging_mixin.py:190} INFO - [2025-02-11T10:34:11.720+0000] {dagbag.py:588} INFO - Filling up the DagBag from /opt/airflow/dags/covid_19.py
[2025-02-11T10:34:12.219+0000] {logging_mixin.py:190} INFO - [2025-02-11T10:34:12.216+0000] {templater.py:94} ERROR - Failed to resolve template field 'sql'
Traceback (most recent call last):
  File "/home/airflow/.local/lib/python3.12/site-packages/airflow/template/templater.py", line 92, in resolve_template_files
    setattr(self, field, env.loader.get_source(env, content)[0])  # type: ignore
                         ^^^^^^^^^^^^^^^^^^^^^^^^^^^^^^^^^^^
  File "/home/airflow/.local/lib/python3.12/site-packages/jinja2/loaders.py", line 207, in get_source
    raise TemplateNotFound(template)
jinja2.exceptions.TemplateNotFound: ./queries/create_dim_date.sql
[2025-02-11T10:34:12.221+0000] {logging_mixin.py:190} INFO - [2025-02-11T10:34:12.220+0000] {templater.py:94} ERROR - Failed to resolve template field 'sql'
Traceback (most recent call last):
  File "/home/airflow/.local/lib/python3.12/site-packages/airflow/template/templater.py", line 92, in resolve_template_files
    setattr(self, field, env.loader.get_source(env, content)[0])  # type: ignore
                         ^^^^^^^^^^^^^^^^^^^^^^^^^^^^^^^^^^^
  File "/home/airflow/.local/lib/python3.12/site-packages/jinja2/loaders.py", line 207, in get_source
    raise TemplateNotFound(template)
jinja2.exceptions.TemplateNotFound: ./queries/create_dim_location.sql
[2025-02-11T10:34:12.222+0000] {logging_mixin.py:190} INFO - [2025-02-11T10:34:12.222+0000] {templater.py:94} ERROR - Failed to resolve template field 'sql'
Traceback (most recent call last):
  File "/home/airflow/.local/lib/python3.12/site-packages/airflow/template/templater.py", line 92, in resolve_template_files
    setattr(self, field, env.loader.get_source(env, content)[0])  # type: ignore
                         ^^^^^^^^^^^^^^^^^^^^^^^^^^^^^^^^^^^
  File "/home/airflow/.local/lib/python3.12/site-packages/jinja2/loaders.py", line 207, in get_source
    raise TemplateNotFound(template)
jinja2.exceptions.TemplateNotFound: queries/create_fact_table.sql
[2025-02-11T10:34:12.226+0000] {processor.py:925} INFO - DAG(s) 'Covid19' retrieved from /opt/airflow/dags/covid_19.py
[2025-02-11T10:34:12.268+0000] {logging_mixin.py:190} INFO - [2025-02-11T10:34:12.267+0000] {dag.py:3239} INFO - Sync 1 DAGs
[2025-02-11T10:34:12.309+0000] {logging_mixin.py:190} INFO - [2025-02-11T10:34:12.309+0000] {dag.py:4180} INFO - Setting next_dagrun for Covid19 to 2025-02-11 10:30:00+00:00, run_after=2025-02-11 10:35:00+00:00
[2025-02-11T10:34:12.336+0000] {processor.py:208} INFO - Processing /opt/airflow/dags/covid_19.py took 0.633 seconds
[2025-02-11T10:34:42.661+0000] {processor.py:186} INFO - Started process (PID=150) to work on /opt/airflow/dags/covid_19.py
[2025-02-11T10:34:42.663+0000] {processor.py:914} INFO - Processing file /opt/airflow/dags/covid_19.py for tasks to queue
[2025-02-11T10:34:42.664+0000] {logging_mixin.py:190} INFO - [2025-02-11T10:34:42.664+0000] {dagbag.py:588} INFO - Filling up the DagBag from /opt/airflow/dags/covid_19.py
[2025-02-11T10:34:43.055+0000] {logging_mixin.py:190} INFO - [2025-02-11T10:34:43.052+0000] {templater.py:94} ERROR - Failed to resolve template field 'sql'
Traceback (most recent call last):
  File "/home/airflow/.local/lib/python3.12/site-packages/airflow/template/templater.py", line 92, in resolve_template_files
    setattr(self, field, env.loader.get_source(env, content)[0])  # type: ignore
                         ^^^^^^^^^^^^^^^^^^^^^^^^^^^^^^^^^^^
  File "/home/airflow/.local/lib/python3.12/site-packages/jinja2/loaders.py", line 207, in get_source
    raise TemplateNotFound(template)
jinja2.exceptions.TemplateNotFound: ./queries/create_dim_date.sql
[2025-02-11T10:34:43.058+0000] {logging_mixin.py:190} INFO - [2025-02-11T10:34:43.057+0000] {templater.py:94} ERROR - Failed to resolve template field 'sql'
Traceback (most recent call last):
  File "/home/airflow/.local/lib/python3.12/site-packages/airflow/template/templater.py", line 92, in resolve_template_files
    setattr(self, field, env.loader.get_source(env, content)[0])  # type: ignore
                         ^^^^^^^^^^^^^^^^^^^^^^^^^^^^^^^^^^^
  File "/home/airflow/.local/lib/python3.12/site-packages/jinja2/loaders.py", line 207, in get_source
    raise TemplateNotFound(template)
jinja2.exceptions.TemplateNotFound: ./queries/create_dim_location.sql
[2025-02-11T10:34:43.063+0000] {logging_mixin.py:190} INFO - [2025-02-11T10:34:43.061+0000] {templater.py:94} ERROR - Failed to resolve template field 'sql'
Traceback (most recent call last):
  File "/home/airflow/.local/lib/python3.12/site-packages/airflow/template/templater.py", line 92, in resolve_template_files
    setattr(self, field, env.loader.get_source(env, content)[0])  # type: ignore
                         ^^^^^^^^^^^^^^^^^^^^^^^^^^^^^^^^^^^
  File "/home/airflow/.local/lib/python3.12/site-packages/jinja2/loaders.py", line 207, in get_source
    raise TemplateNotFound(template)
jinja2.exceptions.TemplateNotFound: queries/create_fact_table.sql
[2025-02-11T10:34:43.071+0000] {processor.py:925} INFO - DAG(s) 'Covid19' retrieved from /opt/airflow/dags/covid_19.py
[2025-02-11T10:34:43.121+0000] {logging_mixin.py:190} INFO - [2025-02-11T10:34:43.120+0000] {dag.py:3239} INFO - Sync 1 DAGs
[2025-02-11T10:34:43.152+0000] {logging_mixin.py:190} INFO - [2025-02-11T10:34:43.152+0000] {dag.py:4180} INFO - Setting next_dagrun for Covid19 to 2025-02-11 10:30:00+00:00, run_after=2025-02-11 10:35:00+00:00
[2025-02-11T10:34:43.191+0000] {processor.py:208} INFO - Processing /opt/airflow/dags/covid_19.py took 0.536 seconds
[2025-02-11T10:35:14.170+0000] {processor.py:186} INFO - Started process (PID=162) to work on /opt/airflow/dags/covid_19.py
[2025-02-11T10:35:14.174+0000] {processor.py:914} INFO - Processing file /opt/airflow/dags/covid_19.py for tasks to queue
[2025-02-11T10:35:14.202+0000] {logging_mixin.py:190} INFO - [2025-02-11T10:35:14.189+0000] {dagbag.py:588} INFO - Filling up the DagBag from /opt/airflow/dags/covid_19.py
[2025-02-11T10:35:15.534+0000] {logging_mixin.py:190} INFO - [2025-02-11T10:35:15.479+0000] {templater.py:94} ERROR - Failed to resolve template field 'sql'
Traceback (most recent call last):
  File "/home/airflow/.local/lib/python3.12/site-packages/airflow/template/templater.py", line 92, in resolve_template_files
    setattr(self, field, env.loader.get_source(env, content)[0])  # type: ignore
                         ^^^^^^^^^^^^^^^^^^^^^^^^^^^^^^^^^^^
  File "/home/airflow/.local/lib/python3.12/site-packages/jinja2/loaders.py", line 207, in get_source
    raise TemplateNotFound(template)
jinja2.exceptions.TemplateNotFound: ./queries/create_dim_date.sql
[2025-02-11T10:35:15.537+0000] {logging_mixin.py:190} INFO - [2025-02-11T10:35:15.536+0000] {templater.py:94} ERROR - Failed to resolve template field 'sql'
Traceback (most recent call last):
  File "/home/airflow/.local/lib/python3.12/site-packages/airflow/template/templater.py", line 92, in resolve_template_files
    setattr(self, field, env.loader.get_source(env, content)[0])  # type: ignore
                         ^^^^^^^^^^^^^^^^^^^^^^^^^^^^^^^^^^^
  File "/home/airflow/.local/lib/python3.12/site-packages/jinja2/loaders.py", line 207, in get_source
    raise TemplateNotFound(template)
jinja2.exceptions.TemplateNotFound: ./queries/create_dim_location.sql
[2025-02-11T10:35:15.541+0000] {logging_mixin.py:190} INFO - [2025-02-11T10:35:15.539+0000] {templater.py:94} ERROR - Failed to resolve template field 'sql'
Traceback (most recent call last):
  File "/home/airflow/.local/lib/python3.12/site-packages/airflow/template/templater.py", line 92, in resolve_template_files
    setattr(self, field, env.loader.get_source(env, content)[0])  # type: ignore
                         ^^^^^^^^^^^^^^^^^^^^^^^^^^^^^^^^^^^
  File "/home/airflow/.local/lib/python3.12/site-packages/jinja2/loaders.py", line 207, in get_source
    raise TemplateNotFound(template)
jinja2.exceptions.TemplateNotFound: queries/create_fact_table.sql
[2025-02-11T10:35:15.569+0000] {processor.py:925} INFO - DAG(s) 'Covid19' retrieved from /opt/airflow/dags/covid_19.py
[2025-02-11T10:35:15.731+0000] {logging_mixin.py:190} INFO - [2025-02-11T10:35:15.730+0000] {dag.py:3239} INFO - Sync 1 DAGs
[2025-02-11T10:35:15.915+0000] {logging_mixin.py:190} INFO - [2025-02-11T10:35:15.914+0000] {dag.py:4180} INFO - Setting next_dagrun for Covid19 to 2025-02-11 10:35:00+00:00, run_after=2025-02-11 10:40:00+00:00
[2025-02-11T10:35:16.033+0000] {processor.py:208} INFO - Processing /opt/airflow/dags/covid_19.py took 1.947 seconds
[2025-02-11T10:35:46.486+0000] {processor.py:186} INFO - Started process (PID=170) to work on /opt/airflow/dags/covid_19.py
[2025-02-11T10:35:46.488+0000] {processor.py:914} INFO - Processing file /opt/airflow/dags/covid_19.py for tasks to queue
[2025-02-11T10:35:46.489+0000] {logging_mixin.py:190} INFO - [2025-02-11T10:35:46.489+0000] {dagbag.py:588} INFO - Filling up the DagBag from /opt/airflow/dags/covid_19.py
[2025-02-11T10:35:46.875+0000] {logging_mixin.py:190} INFO - [2025-02-11T10:35:46.871+0000] {templater.py:94} ERROR - Failed to resolve template field 'sql'
Traceback (most recent call last):
  File "/home/airflow/.local/lib/python3.12/site-packages/airflow/template/templater.py", line 92, in resolve_template_files
    setattr(self, field, env.loader.get_source(env, content)[0])  # type: ignore
                         ^^^^^^^^^^^^^^^^^^^^^^^^^^^^^^^^^^^
  File "/home/airflow/.local/lib/python3.12/site-packages/jinja2/loaders.py", line 207, in get_source
    raise TemplateNotFound(template)
jinja2.exceptions.TemplateNotFound: ./queries/create_dim_date.sql
[2025-02-11T10:35:46.878+0000] {logging_mixin.py:190} INFO - [2025-02-11T10:35:46.877+0000] {templater.py:94} ERROR - Failed to resolve template field 'sql'
Traceback (most recent call last):
  File "/home/airflow/.local/lib/python3.12/site-packages/airflow/template/templater.py", line 92, in resolve_template_files
    setattr(self, field, env.loader.get_source(env, content)[0])  # type: ignore
                         ^^^^^^^^^^^^^^^^^^^^^^^^^^^^^^^^^^^
  File "/home/airflow/.local/lib/python3.12/site-packages/jinja2/loaders.py", line 207, in get_source
    raise TemplateNotFound(template)
jinja2.exceptions.TemplateNotFound: ./queries/create_dim_location.sql
[2025-02-11T10:35:46.880+0000] {logging_mixin.py:190} INFO - [2025-02-11T10:35:46.880+0000] {templater.py:94} ERROR - Failed to resolve template field 'sql'
Traceback (most recent call last):
  File "/home/airflow/.local/lib/python3.12/site-packages/airflow/template/templater.py", line 92, in resolve_template_files
    setattr(self, field, env.loader.get_source(env, content)[0])  # type: ignore
                         ^^^^^^^^^^^^^^^^^^^^^^^^^^^^^^^^^^^
  File "/home/airflow/.local/lib/python3.12/site-packages/jinja2/loaders.py", line 207, in get_source
    raise TemplateNotFound(template)
jinja2.exceptions.TemplateNotFound: queries/create_fact_table.sql
[2025-02-11T10:35:46.887+0000] {processor.py:925} INFO - DAG(s) 'Covid19' retrieved from /opt/airflow/dags/covid_19.py
[2025-02-11T10:35:46.930+0000] {logging_mixin.py:190} INFO - [2025-02-11T10:35:46.929+0000] {dag.py:3239} INFO - Sync 1 DAGs
[2025-02-11T10:35:46.976+0000] {logging_mixin.py:190} INFO - [2025-02-11T10:35:46.976+0000] {dag.py:4180} INFO - Setting next_dagrun for Covid19 to 2025-02-11 10:35:00+00:00, run_after=2025-02-11 10:40:00+00:00
[2025-02-11T10:35:47.016+0000] {processor.py:208} INFO - Processing /opt/airflow/dags/covid_19.py took 0.539 seconds
[2025-02-11T10:36:17.366+0000] {processor.py:186} INFO - Started process (PID=178) to work on /opt/airflow/dags/covid_19.py
[2025-02-11T10:36:17.369+0000] {processor.py:914} INFO - Processing file /opt/airflow/dags/covid_19.py for tasks to queue
[2025-02-11T10:36:17.371+0000] {logging_mixin.py:190} INFO - [2025-02-11T10:36:17.371+0000] {dagbag.py:588} INFO - Filling up the DagBag from /opt/airflow/dags/covid_19.py
[2025-02-11T10:36:17.698+0000] {logging_mixin.py:190} INFO - [2025-02-11T10:36:17.696+0000] {templater.py:94} ERROR - Failed to resolve template field 'sql'
Traceback (most recent call last):
  File "/home/airflow/.local/lib/python3.12/site-packages/airflow/template/templater.py", line 92, in resolve_template_files
    setattr(self, field, env.loader.get_source(env, content)[0])  # type: ignore
                         ^^^^^^^^^^^^^^^^^^^^^^^^^^^^^^^^^^^
  File "/home/airflow/.local/lib/python3.12/site-packages/jinja2/loaders.py", line 207, in get_source
    raise TemplateNotFound(template)
jinja2.exceptions.TemplateNotFound: ./queries/create_dim_date.sql
[2025-02-11T10:36:17.699+0000] {logging_mixin.py:190} INFO - [2025-02-11T10:36:17.699+0000] {templater.py:94} ERROR - Failed to resolve template field 'sql'
Traceback (most recent call last):
  File "/home/airflow/.local/lib/python3.12/site-packages/airflow/template/templater.py", line 92, in resolve_template_files
    setattr(self, field, env.loader.get_source(env, content)[0])  # type: ignore
                         ^^^^^^^^^^^^^^^^^^^^^^^^^^^^^^^^^^^
  File "/home/airflow/.local/lib/python3.12/site-packages/jinja2/loaders.py", line 207, in get_source
    raise TemplateNotFound(template)
jinja2.exceptions.TemplateNotFound: ./queries/create_dim_location.sql
[2025-02-11T10:36:17.700+0000] {logging_mixin.py:190} INFO - [2025-02-11T10:36:17.700+0000] {templater.py:94} ERROR - Failed to resolve template field 'sql'
Traceback (most recent call last):
  File "/home/airflow/.local/lib/python3.12/site-packages/airflow/template/templater.py", line 92, in resolve_template_files
    setattr(self, field, env.loader.get_source(env, content)[0])  # type: ignore
                         ^^^^^^^^^^^^^^^^^^^^^^^^^^^^^^^^^^^
  File "/home/airflow/.local/lib/python3.12/site-packages/jinja2/loaders.py", line 207, in get_source
    raise TemplateNotFound(template)
jinja2.exceptions.TemplateNotFound: queries/create_fact_table.sql
[2025-02-11T10:36:17.704+0000] {processor.py:925} INFO - DAG(s) 'Covid19' retrieved from /opt/airflow/dags/covid_19.py
[2025-02-11T10:36:17.729+0000] {logging_mixin.py:190} INFO - [2025-02-11T10:36:17.729+0000] {dag.py:3239} INFO - Sync 1 DAGs
[2025-02-11T10:36:17.750+0000] {logging_mixin.py:190} INFO - [2025-02-11T10:36:17.750+0000] {dag.py:4180} INFO - Setting next_dagrun for Covid19 to 2025-02-11 10:35:00+00:00, run_after=2025-02-11 10:40:00+00:00
[2025-02-11T10:36:17.776+0000] {processor.py:208} INFO - Processing /opt/airflow/dags/covid_19.py took 0.419 seconds
[2025-02-11T10:36:47.989+0000] {processor.py:186} INFO - Started process (PID=186) to work on /opt/airflow/dags/covid_19.py
[2025-02-11T10:36:47.991+0000] {processor.py:914} INFO - Processing file /opt/airflow/dags/covid_19.py for tasks to queue
[2025-02-11T10:36:47.993+0000] {logging_mixin.py:190} INFO - [2025-02-11T10:36:47.992+0000] {dagbag.py:588} INFO - Filling up the DagBag from /opt/airflow/dags/covid_19.py
[2025-02-11T10:36:48.261+0000] {logging_mixin.py:190} INFO - [2025-02-11T10:36:48.260+0000] {templater.py:94} ERROR - Failed to resolve template field 'sql'
Traceback (most recent call last):
  File "/home/airflow/.local/lib/python3.12/site-packages/airflow/template/templater.py", line 92, in resolve_template_files
    setattr(self, field, env.loader.get_source(env, content)[0])  # type: ignore
                         ^^^^^^^^^^^^^^^^^^^^^^^^^^^^^^^^^^^
  File "/home/airflow/.local/lib/python3.12/site-packages/jinja2/loaders.py", line 207, in get_source
    raise TemplateNotFound(template)
jinja2.exceptions.TemplateNotFound: ./queries/create_dim_date.sql
[2025-02-11T10:36:48.263+0000] {logging_mixin.py:190} INFO - [2025-02-11T10:36:48.262+0000] {templater.py:94} ERROR - Failed to resolve template field 'sql'
Traceback (most recent call last):
  File "/home/airflow/.local/lib/python3.12/site-packages/airflow/template/templater.py", line 92, in resolve_template_files
    setattr(self, field, env.loader.get_source(env, content)[0])  # type: ignore
                         ^^^^^^^^^^^^^^^^^^^^^^^^^^^^^^^^^^^
  File "/home/airflow/.local/lib/python3.12/site-packages/jinja2/loaders.py", line 207, in get_source
    raise TemplateNotFound(template)
jinja2.exceptions.TemplateNotFound: ./queries/create_dim_location.sql
[2025-02-11T10:36:48.264+0000] {logging_mixin.py:190} INFO - [2025-02-11T10:36:48.263+0000] {templater.py:94} ERROR - Failed to resolve template field 'sql'
Traceback (most recent call last):
  File "/home/airflow/.local/lib/python3.12/site-packages/airflow/template/templater.py", line 92, in resolve_template_files
    setattr(self, field, env.loader.get_source(env, content)[0])  # type: ignore
                         ^^^^^^^^^^^^^^^^^^^^^^^^^^^^^^^^^^^
  File "/home/airflow/.local/lib/python3.12/site-packages/jinja2/loaders.py", line 207, in get_source
    raise TemplateNotFound(template)
jinja2.exceptions.TemplateNotFound: queries/create_fact_table.sql
[2025-02-11T10:36:48.267+0000] {processor.py:925} INFO - DAG(s) 'Covid19' retrieved from /opt/airflow/dags/covid_19.py
[2025-02-11T10:36:48.289+0000] {logging_mixin.py:190} INFO - [2025-02-11T10:36:48.289+0000] {dag.py:3239} INFO - Sync 1 DAGs
[2025-02-11T10:36:48.308+0000] {logging_mixin.py:190} INFO - [2025-02-11T10:36:48.308+0000] {dag.py:4180} INFO - Setting next_dagrun for Covid19 to 2025-02-11 10:35:00+00:00, run_after=2025-02-11 10:40:00+00:00
[2025-02-11T10:36:48.333+0000] {processor.py:208} INFO - Processing /opt/airflow/dags/covid_19.py took 0.354 seconds
[2025-02-11T10:37:18.594+0000] {processor.py:186} INFO - Started process (PID=194) to work on /opt/airflow/dags/covid_19.py
[2025-02-11T10:37:18.595+0000] {processor.py:914} INFO - Processing file /opt/airflow/dags/covid_19.py for tasks to queue
[2025-02-11T10:37:18.597+0000] {logging_mixin.py:190} INFO - [2025-02-11T10:37:18.597+0000] {dagbag.py:588} INFO - Filling up the DagBag from /opt/airflow/dags/covid_19.py
[2025-02-11T10:37:18.899+0000] {logging_mixin.py:190} INFO - [2025-02-11T10:37:18.897+0000] {templater.py:94} ERROR - Failed to resolve template field 'sql'
Traceback (most recent call last):
  File "/home/airflow/.local/lib/python3.12/site-packages/airflow/template/templater.py", line 92, in resolve_template_files
    setattr(self, field, env.loader.get_source(env, content)[0])  # type: ignore
                         ^^^^^^^^^^^^^^^^^^^^^^^^^^^^^^^^^^^
  File "/home/airflow/.local/lib/python3.12/site-packages/jinja2/loaders.py", line 207, in get_source
    raise TemplateNotFound(template)
jinja2.exceptions.TemplateNotFound: ./queries/create_dim_date.sql
[2025-02-11T10:37:18.901+0000] {logging_mixin.py:190} INFO - [2025-02-11T10:37:18.900+0000] {templater.py:94} ERROR - Failed to resolve template field 'sql'
Traceback (most recent call last):
  File "/home/airflow/.local/lib/python3.12/site-packages/airflow/template/templater.py", line 92, in resolve_template_files
    setattr(self, field, env.loader.get_source(env, content)[0])  # type: ignore
                         ^^^^^^^^^^^^^^^^^^^^^^^^^^^^^^^^^^^
  File "/home/airflow/.local/lib/python3.12/site-packages/jinja2/loaders.py", line 207, in get_source
    raise TemplateNotFound(template)
jinja2.exceptions.TemplateNotFound: ./queries/create_dim_location.sql
[2025-02-11T10:37:18.902+0000] {logging_mixin.py:190} INFO - [2025-02-11T10:37:18.902+0000] {templater.py:94} ERROR - Failed to resolve template field 'sql'
Traceback (most recent call last):
  File "/home/airflow/.local/lib/python3.12/site-packages/airflow/template/templater.py", line 92, in resolve_template_files
    setattr(self, field, env.loader.get_source(env, content)[0])  # type: ignore
                         ^^^^^^^^^^^^^^^^^^^^^^^^^^^^^^^^^^^
  File "/home/airflow/.local/lib/python3.12/site-packages/jinja2/loaders.py", line 207, in get_source
    raise TemplateNotFound(template)
jinja2.exceptions.TemplateNotFound: queries/create_fact_table.sql
[2025-02-11T10:37:18.905+0000] {processor.py:925} INFO - DAG(s) 'Covid19' retrieved from /opt/airflow/dags/covid_19.py
[2025-02-11T10:37:18.931+0000] {logging_mixin.py:190} INFO - [2025-02-11T10:37:18.931+0000] {dag.py:3239} INFO - Sync 1 DAGs
[2025-02-11T10:37:18.952+0000] {logging_mixin.py:190} INFO - [2025-02-11T10:37:18.952+0000] {dag.py:4180} INFO - Setting next_dagrun for Covid19 to 2025-02-11 10:35:00+00:00, run_after=2025-02-11 10:40:00+00:00
[2025-02-11T10:37:18.977+0000] {processor.py:208} INFO - Processing /opt/airflow/dags/covid_19.py took 0.389 seconds
[2025-02-11T10:37:49.243+0000] {processor.py:186} INFO - Started process (PID=202) to work on /opt/airflow/dags/covid_19.py
[2025-02-11T10:37:49.246+0000] {processor.py:914} INFO - Processing file /opt/airflow/dags/covid_19.py for tasks to queue
[2025-02-11T10:37:49.248+0000] {logging_mixin.py:190} INFO - [2025-02-11T10:37:49.247+0000] {dagbag.py:588} INFO - Filling up the DagBag from /opt/airflow/dags/covid_19.py
[2025-02-11T10:37:49.830+0000] {logging_mixin.py:190} INFO - [2025-02-11T10:37:49.827+0000] {templater.py:94} ERROR - Failed to resolve template field 'sql'
Traceback (most recent call last):
  File "/home/airflow/.local/lib/python3.12/site-packages/airflow/template/templater.py", line 92, in resolve_template_files
    setattr(self, field, env.loader.get_source(env, content)[0])  # type: ignore
                         ^^^^^^^^^^^^^^^^^^^^^^^^^^^^^^^^^^^
  File "/home/airflow/.local/lib/python3.12/site-packages/jinja2/loaders.py", line 207, in get_source
    raise TemplateNotFound(template)
jinja2.exceptions.TemplateNotFound: ./queries/create_dim_date.sql
[2025-02-11T10:37:49.832+0000] {logging_mixin.py:190} INFO - [2025-02-11T10:37:49.831+0000] {templater.py:94} ERROR - Failed to resolve template field 'sql'
Traceback (most recent call last):
  File "/home/airflow/.local/lib/python3.12/site-packages/airflow/template/templater.py", line 92, in resolve_template_files
    setattr(self, field, env.loader.get_source(env, content)[0])  # type: ignore
                         ^^^^^^^^^^^^^^^^^^^^^^^^^^^^^^^^^^^
  File "/home/airflow/.local/lib/python3.12/site-packages/jinja2/loaders.py", line 207, in get_source
    raise TemplateNotFound(template)
jinja2.exceptions.TemplateNotFound: ./queries/create_dim_location.sql
[2025-02-11T10:37:49.834+0000] {logging_mixin.py:190} INFO - [2025-02-11T10:37:49.833+0000] {templater.py:94} ERROR - Failed to resolve template field 'sql'
Traceback (most recent call last):
  File "/home/airflow/.local/lib/python3.12/site-packages/airflow/template/templater.py", line 92, in resolve_template_files
    setattr(self, field, env.loader.get_source(env, content)[0])  # type: ignore
                         ^^^^^^^^^^^^^^^^^^^^^^^^^^^^^^^^^^^
  File "/home/airflow/.local/lib/python3.12/site-packages/jinja2/loaders.py", line 207, in get_source
    raise TemplateNotFound(template)
jinja2.exceptions.TemplateNotFound: queries/create_fact_table.sql
[2025-02-11T10:37:49.838+0000] {processor.py:925} INFO - DAG(s) 'Covid19' retrieved from /opt/airflow/dags/covid_19.py
[2025-02-11T10:37:49.868+0000] {logging_mixin.py:190} INFO - [2025-02-11T10:37:49.868+0000] {dag.py:3239} INFO - Sync 1 DAGs
[2025-02-11T10:37:49.896+0000] {logging_mixin.py:190} INFO - [2025-02-11T10:37:49.896+0000] {dag.py:4180} INFO - Setting next_dagrun for Covid19 to 2025-02-11 10:35:00+00:00, run_after=2025-02-11 10:40:00+00:00
[2025-02-11T10:37:49.922+0000] {processor.py:208} INFO - Processing /opt/airflow/dags/covid_19.py took 0.684 seconds
[2025-02-11T10:38:20.553+0000] {processor.py:186} INFO - Started process (PID=210) to work on /opt/airflow/dags/covid_19.py
[2025-02-11T10:38:20.554+0000] {processor.py:914} INFO - Processing file /opt/airflow/dags/covid_19.py for tasks to queue
[2025-02-11T10:38:20.556+0000] {logging_mixin.py:190} INFO - [2025-02-11T10:38:20.556+0000] {dagbag.py:588} INFO - Filling up the DagBag from /opt/airflow/dags/covid_19.py
[2025-02-11T10:38:21.018+0000] {logging_mixin.py:190} INFO - [2025-02-11T10:38:21.016+0000] {templater.py:94} ERROR - Failed to resolve template field 'sql'
Traceback (most recent call last):
  File "/home/airflow/.local/lib/python3.12/site-packages/airflow/template/templater.py", line 92, in resolve_template_files
    setattr(self, field, env.loader.get_source(env, content)[0])  # type: ignore
                         ^^^^^^^^^^^^^^^^^^^^^^^^^^^^^^^^^^^
  File "/home/airflow/.local/lib/python3.12/site-packages/jinja2/loaders.py", line 207, in get_source
    raise TemplateNotFound(template)
jinja2.exceptions.TemplateNotFound: ./queries/create_dim_date.sql
[2025-02-11T10:38:21.020+0000] {logging_mixin.py:190} INFO - [2025-02-11T10:38:21.019+0000] {templater.py:94} ERROR - Failed to resolve template field 'sql'
Traceback (most recent call last):
  File "/home/airflow/.local/lib/python3.12/site-packages/airflow/template/templater.py", line 92, in resolve_template_files
    setattr(self, field, env.loader.get_source(env, content)[0])  # type: ignore
                         ^^^^^^^^^^^^^^^^^^^^^^^^^^^^^^^^^^^
  File "/home/airflow/.local/lib/python3.12/site-packages/jinja2/loaders.py", line 207, in get_source
    raise TemplateNotFound(template)
jinja2.exceptions.TemplateNotFound: ./queries/create_dim_location.sql
[2025-02-11T10:38:21.021+0000] {logging_mixin.py:190} INFO - [2025-02-11T10:38:21.020+0000] {templater.py:94} ERROR - Failed to resolve template field 'sql'
Traceback (most recent call last):
  File "/home/airflow/.local/lib/python3.12/site-packages/airflow/template/templater.py", line 92, in resolve_template_files
    setattr(self, field, env.loader.get_source(env, content)[0])  # type: ignore
                         ^^^^^^^^^^^^^^^^^^^^^^^^^^^^^^^^^^^
  File "/home/airflow/.local/lib/python3.12/site-packages/jinja2/loaders.py", line 207, in get_source
    raise TemplateNotFound(template)
jinja2.exceptions.TemplateNotFound: queries/create_fact_table.sql
[2025-02-11T10:38:21.026+0000] {processor.py:925} INFO - DAG(s) 'Covid19' retrieved from /opt/airflow/dags/covid_19.py
[2025-02-11T10:38:21.054+0000] {logging_mixin.py:190} INFO - [2025-02-11T10:38:21.053+0000] {dag.py:3239} INFO - Sync 1 DAGs
[2025-02-11T10:38:21.080+0000] {logging_mixin.py:190} INFO - [2025-02-11T10:38:21.079+0000] {dag.py:4180} INFO - Setting next_dagrun for Covid19 to 2025-02-11 10:35:00+00:00, run_after=2025-02-11 10:40:00+00:00
[2025-02-11T10:38:21.107+0000] {processor.py:208} INFO - Processing /opt/airflow/dags/covid_19.py took 0.564 seconds
[2025-02-11T10:38:51.562+0000] {processor.py:186} INFO - Started process (PID=218) to work on /opt/airflow/dags/covid_19.py
[2025-02-11T10:38:51.564+0000] {processor.py:914} INFO - Processing file /opt/airflow/dags/covid_19.py for tasks to queue
[2025-02-11T10:38:51.567+0000] {logging_mixin.py:190} INFO - [2025-02-11T10:38:51.567+0000] {dagbag.py:588} INFO - Filling up the DagBag from /opt/airflow/dags/covid_19.py
[2025-02-11T10:38:51.902+0000] {logging_mixin.py:190} INFO - [2025-02-11T10:38:51.900+0000] {templater.py:94} ERROR - Failed to resolve template field 'sql'
Traceback (most recent call last):
  File "/home/airflow/.local/lib/python3.12/site-packages/airflow/template/templater.py", line 92, in resolve_template_files
    setattr(self, field, env.loader.get_source(env, content)[0])  # type: ignore
                         ^^^^^^^^^^^^^^^^^^^^^^^^^^^^^^^^^^^
  File "/home/airflow/.local/lib/python3.12/site-packages/jinja2/loaders.py", line 207, in get_source
    raise TemplateNotFound(template)
jinja2.exceptions.TemplateNotFound: ./queries/create_dim_date.sql
[2025-02-11T10:38:51.904+0000] {logging_mixin.py:190} INFO - [2025-02-11T10:38:51.903+0000] {templater.py:94} ERROR - Failed to resolve template field 'sql'
Traceback (most recent call last):
  File "/home/airflow/.local/lib/python3.12/site-packages/airflow/template/templater.py", line 92, in resolve_template_files
    setattr(self, field, env.loader.get_source(env, content)[0])  # type: ignore
                         ^^^^^^^^^^^^^^^^^^^^^^^^^^^^^^^^^^^
  File "/home/airflow/.local/lib/python3.12/site-packages/jinja2/loaders.py", line 207, in get_source
    raise TemplateNotFound(template)
jinja2.exceptions.TemplateNotFound: ./queries/create_dim_location.sql
[2025-02-11T10:38:51.906+0000] {logging_mixin.py:190} INFO - [2025-02-11T10:38:51.905+0000] {templater.py:94} ERROR - Failed to resolve template field 'sql'
Traceback (most recent call last):
  File "/home/airflow/.local/lib/python3.12/site-packages/airflow/template/templater.py", line 92, in resolve_template_files
    setattr(self, field, env.loader.get_source(env, content)[0])  # type: ignore
                         ^^^^^^^^^^^^^^^^^^^^^^^^^^^^^^^^^^^
  File "/home/airflow/.local/lib/python3.12/site-packages/jinja2/loaders.py", line 207, in get_source
    raise TemplateNotFound(template)
jinja2.exceptions.TemplateNotFound: queries/create_fact_table.sql
[2025-02-11T10:38:51.910+0000] {processor.py:925} INFO - DAG(s) 'Covid19' retrieved from /opt/airflow/dags/covid_19.py
[2025-02-11T10:38:51.935+0000] {logging_mixin.py:190} INFO - [2025-02-11T10:38:51.934+0000] {dag.py:3239} INFO - Sync 1 DAGs
[2025-02-11T10:38:51.964+0000] {logging_mixin.py:190} INFO - [2025-02-11T10:38:51.964+0000] {dag.py:4180} INFO - Setting next_dagrun for Covid19 to 2025-02-11 10:35:00+00:00, run_after=2025-02-11 10:40:00+00:00
[2025-02-11T10:38:51.993+0000] {processor.py:208} INFO - Processing /opt/airflow/dags/covid_19.py took 0.442 seconds
[2025-02-11T10:39:17.003+0000] {processor.py:186} INFO - Started process (PID=226) to work on /opt/airflow/dags/covid_19.py
[2025-02-11T10:39:17.004+0000] {processor.py:914} INFO - Processing file /opt/airflow/dags/covid_19.py for tasks to queue
[2025-02-11T10:39:17.006+0000] {logging_mixin.py:190} INFO - [2025-02-11T10:39:17.006+0000] {dagbag.py:588} INFO - Filling up the DagBag from /opt/airflow/dags/covid_19.py
[2025-02-11T10:39:17.413+0000] {logging_mixin.py:190} INFO - [2025-02-11T10:39:17.411+0000] {templater.py:94} ERROR - Failed to resolve template field 'sql'
Traceback (most recent call last):
  File "/home/airflow/.local/lib/python3.12/site-packages/airflow/template/templater.py", line 92, in resolve_template_files
    setattr(self, field, env.loader.get_source(env, content)[0])  # type: ignore
                         ^^^^^^^^^^^^^^^^^^^^^^^^^^^^^^^^^^^
  File "/home/airflow/.local/lib/python3.12/site-packages/jinja2/loaders.py", line 207, in get_source
    raise TemplateNotFound(template)
jinja2.exceptions.TemplateNotFound: ./queries/create_dim_date.sql
[2025-02-11T10:39:17.414+0000] {logging_mixin.py:190} INFO - [2025-02-11T10:39:17.413+0000] {templater.py:94} ERROR - Failed to resolve template field 'sql'
Traceback (most recent call last):
  File "/home/airflow/.local/lib/python3.12/site-packages/airflow/template/templater.py", line 92, in resolve_template_files
    setattr(self, field, env.loader.get_source(env, content)[0])  # type: ignore
                         ^^^^^^^^^^^^^^^^^^^^^^^^^^^^^^^^^^^
  File "/home/airflow/.local/lib/python3.12/site-packages/jinja2/loaders.py", line 207, in get_source
    raise TemplateNotFound(template)
jinja2.exceptions.TemplateNotFound: ./queries/create_dim_location.sql
[2025-02-11T10:39:17.415+0000] {logging_mixin.py:190} INFO - [2025-02-11T10:39:17.414+0000] {templater.py:94} ERROR - Failed to resolve template field 'sql'
Traceback (most recent call last):
  File "/home/airflow/.local/lib/python3.12/site-packages/airflow/template/templater.py", line 92, in resolve_template_files
    setattr(self, field, env.loader.get_source(env, content)[0])  # type: ignore
                         ^^^^^^^^^^^^^^^^^^^^^^^^^^^^^^^^^^^
  File "/home/airflow/.local/lib/python3.12/site-packages/jinja2/loaders.py", line 207, in get_source
    raise TemplateNotFound(template)
jinja2.exceptions.TemplateNotFound: queries/create_fact_table.sql
[2025-02-11T10:39:17.418+0000] {processor.py:925} INFO - DAG(s) 'Covid19' retrieved from /opt/airflow/dags/covid_19.py
[2025-02-11T10:39:17.444+0000] {logging_mixin.py:190} INFO - [2025-02-11T10:39:17.443+0000] {dag.py:3239} INFO - Sync 1 DAGs
[2025-02-11T10:39:17.467+0000] {logging_mixin.py:190} INFO - [2025-02-11T10:39:17.467+0000] {dag.py:4180} INFO - Setting next_dagrun for Covid19 to 2025-02-11 10:35:00+00:00, run_after=2025-02-11 10:40:00+00:00
[2025-02-11T10:39:17.495+0000] {processor.py:208} INFO - Processing /opt/airflow/dags/covid_19.py took 0.498 seconds
[2025-02-11T10:39:48.964+0000] {processor.py:186} INFO - Started process (PID=242) to work on /opt/airflow/dags/covid_19.py
[2025-02-11T10:39:49.028+0000] {processor.py:914} INFO - Processing file /opt/airflow/dags/covid_19.py for tasks to queue
[2025-02-11T10:39:49.096+0000] {logging_mixin.py:190} INFO - [2025-02-11T10:39:49.071+0000] {dagbag.py:588} INFO - Filling up the DagBag from /opt/airflow/dags/covid_19.py
[2025-02-11T10:40:00.983+0000] {logging_mixin.py:190} INFO - [2025-02-11T10:40:00.891+0000] {templater.py:94} ERROR - Failed to resolve template field 'sql'
Traceback (most recent call last):
  File "/home/airflow/.local/lib/python3.12/site-packages/airflow/template/templater.py", line 92, in resolve_template_files
    setattr(self, field, env.loader.get_source(env, content)[0])  # type: ignore
                         ^^^^^^^^^^^^^^^^^^^^^^^^^^^^^^^^^^^
  File "/home/airflow/.local/lib/python3.12/site-packages/jinja2/loaders.py", line 207, in get_source
    raise TemplateNotFound(template)
jinja2.exceptions.TemplateNotFound: ./queries/create_dim_date.sql
[2025-02-11T10:40:00.992+0000] {logging_mixin.py:190} INFO - [2025-02-11T10:40:00.991+0000] {templater.py:94} ERROR - Failed to resolve template field 'sql'
Traceback (most recent call last):
  File "/home/airflow/.local/lib/python3.12/site-packages/airflow/template/templater.py", line 92, in resolve_template_files
    setattr(self, field, env.loader.get_source(env, content)[0])  # type: ignore
                         ^^^^^^^^^^^^^^^^^^^^^^^^^^^^^^^^^^^
  File "/home/airflow/.local/lib/python3.12/site-packages/jinja2/loaders.py", line 207, in get_source
    raise TemplateNotFound(template)
jinja2.exceptions.TemplateNotFound: ./queries/create_dim_location.sql
[2025-02-11T10:40:01.000+0000] {logging_mixin.py:190} INFO - [2025-02-11T10:40:00.999+0000] {templater.py:94} ERROR - Failed to resolve template field 'sql'
Traceback (most recent call last):
  File "/home/airflow/.local/lib/python3.12/site-packages/airflow/template/templater.py", line 92, in resolve_template_files
    setattr(self, field, env.loader.get_source(env, content)[0])  # type: ignore
                         ^^^^^^^^^^^^^^^^^^^^^^^^^^^^^^^^^^^
  File "/home/airflow/.local/lib/python3.12/site-packages/jinja2/loaders.py", line 207, in get_source
    raise TemplateNotFound(template)
jinja2.exceptions.TemplateNotFound: queries/create_fact_table.sql
[2025-02-11T10:40:01.075+0000] {processor.py:925} INFO - DAG(s) 'Covid19' retrieved from /opt/airflow/dags/covid_19.py
[2025-02-11T10:40:01.360+0000] {logging_mixin.py:190} INFO - [2025-02-11T10:40:01.354+0000] {dag.py:3239} INFO - Sync 1 DAGs
[2025-02-11T10:40:01.598+0000] {logging_mixin.py:190} INFO - [2025-02-11T10:40:01.598+0000] {dag.py:4180} INFO - Setting next_dagrun for Covid19 to 2025-02-11 10:40:00+00:00, run_after=2025-02-11 10:45:00+00:00
[2025-02-11T10:40:01.739+0000] {processor.py:208} INFO - Processing /opt/airflow/dags/covid_19.py took 13.828 seconds
[2025-02-11T10:40:32.238+0000] {processor.py:186} INFO - Started process (PID=260) to work on /opt/airflow/dags/covid_19.py
[2025-02-11T10:40:32.240+0000] {processor.py:914} INFO - Processing file /opt/airflow/dags/covid_19.py for tasks to queue
[2025-02-11T10:40:32.248+0000] {logging_mixin.py:190} INFO - [2025-02-11T10:40:32.245+0000] {dagbag.py:588} INFO - Filling up the DagBag from /opt/airflow/dags/covid_19.py
[2025-02-11T10:40:33.061+0000] {logging_mixin.py:190} INFO - [2025-02-11T10:40:33.052+0000] {templater.py:94} ERROR - Failed to resolve template field 'sql'
Traceback (most recent call last):
  File "/home/airflow/.local/lib/python3.12/site-packages/airflow/template/templater.py", line 92, in resolve_template_files
    setattr(self, field, env.loader.get_source(env, content)[0])  # type: ignore
                         ^^^^^^^^^^^^^^^^^^^^^^^^^^^^^^^^^^^
  File "/home/airflow/.local/lib/python3.12/site-packages/jinja2/loaders.py", line 207, in get_source
    raise TemplateNotFound(template)
jinja2.exceptions.TemplateNotFound: ./queries/create_dim_date.sql
[2025-02-11T10:40:33.063+0000] {logging_mixin.py:190} INFO - [2025-02-11T10:40:33.062+0000] {templater.py:94} ERROR - Failed to resolve template field 'sql'
Traceback (most recent call last):
  File "/home/airflow/.local/lib/python3.12/site-packages/airflow/template/templater.py", line 92, in resolve_template_files
    setattr(self, field, env.loader.get_source(env, content)[0])  # type: ignore
                         ^^^^^^^^^^^^^^^^^^^^^^^^^^^^^^^^^^^
  File "/home/airflow/.local/lib/python3.12/site-packages/jinja2/loaders.py", line 207, in get_source
    raise TemplateNotFound(template)
jinja2.exceptions.TemplateNotFound: ./queries/create_dim_location.sql
[2025-02-11T10:40:33.065+0000] {logging_mixin.py:190} INFO - [2025-02-11T10:40:33.064+0000] {templater.py:94} ERROR - Failed to resolve template field 'sql'
Traceback (most recent call last):
  File "/home/airflow/.local/lib/python3.12/site-packages/airflow/template/templater.py", line 92, in resolve_template_files
    setattr(self, field, env.loader.get_source(env, content)[0])  # type: ignore
                         ^^^^^^^^^^^^^^^^^^^^^^^^^^^^^^^^^^^
  File "/home/airflow/.local/lib/python3.12/site-packages/jinja2/loaders.py", line 207, in get_source
    raise TemplateNotFound(template)
jinja2.exceptions.TemplateNotFound: queries/create_fact_table.sql
[2025-02-11T10:40:33.078+0000] {processor.py:925} INFO - DAG(s) 'Covid19' retrieved from /opt/airflow/dags/covid_19.py
[2025-02-11T10:40:33.143+0000] {logging_mixin.py:190} INFO - [2025-02-11T10:40:33.142+0000] {dag.py:3239} INFO - Sync 1 DAGs
[2025-02-11T10:40:33.211+0000] {logging_mixin.py:190} INFO - [2025-02-11T10:40:33.210+0000] {dag.py:4180} INFO - Setting next_dagrun for Covid19 to 2025-02-11 10:40:00+00:00, run_after=2025-02-11 10:45:00+00:00
[2025-02-11T10:40:33.253+0000] {processor.py:208} INFO - Processing /opt/airflow/dags/covid_19.py took 1.052 seconds
[2025-02-11T10:41:03.559+0000] {processor.py:186} INFO - Started process (PID=268) to work on /opt/airflow/dags/covid_19.py
[2025-02-11T10:41:03.561+0000] {processor.py:914} INFO - Processing file /opt/airflow/dags/covid_19.py for tasks to queue
[2025-02-11T10:41:03.563+0000] {logging_mixin.py:190} INFO - [2025-02-11T10:41:03.562+0000] {dagbag.py:588} INFO - Filling up the DagBag from /opt/airflow/dags/covid_19.py
[2025-02-11T10:41:04.045+0000] {logging_mixin.py:190} INFO - [2025-02-11T10:41:04.044+0000] {templater.py:94} ERROR - Failed to resolve template field 'sql'
Traceback (most recent call last):
  File "/home/airflow/.local/lib/python3.12/site-packages/airflow/template/templater.py", line 92, in resolve_template_files
    setattr(self, field, env.loader.get_source(env, content)[0])  # type: ignore
                         ^^^^^^^^^^^^^^^^^^^^^^^^^^^^^^^^^^^
  File "/home/airflow/.local/lib/python3.12/site-packages/jinja2/loaders.py", line 207, in get_source
    raise TemplateNotFound(template)
jinja2.exceptions.TemplateNotFound: ./queries/create_dim_date.sql
[2025-02-11T10:41:04.048+0000] {logging_mixin.py:190} INFO - [2025-02-11T10:41:04.047+0000] {templater.py:94} ERROR - Failed to resolve template field 'sql'
Traceback (most recent call last):
  File "/home/airflow/.local/lib/python3.12/site-packages/airflow/template/templater.py", line 92, in resolve_template_files
    setattr(self, field, env.loader.get_source(env, content)[0])  # type: ignore
                         ^^^^^^^^^^^^^^^^^^^^^^^^^^^^^^^^^^^
  File "/home/airflow/.local/lib/python3.12/site-packages/jinja2/loaders.py", line 207, in get_source
    raise TemplateNotFound(template)
jinja2.exceptions.TemplateNotFound: ./queries/create_dim_location.sql
[2025-02-11T10:41:04.049+0000] {logging_mixin.py:190} INFO - [2025-02-11T10:41:04.049+0000] {templater.py:94} ERROR - Failed to resolve template field 'sql'
Traceback (most recent call last):
  File "/home/airflow/.local/lib/python3.12/site-packages/airflow/template/templater.py", line 92, in resolve_template_files
    setattr(self, field, env.loader.get_source(env, content)[0])  # type: ignore
                         ^^^^^^^^^^^^^^^^^^^^^^^^^^^^^^^^^^^
  File "/home/airflow/.local/lib/python3.12/site-packages/jinja2/loaders.py", line 207, in get_source
    raise TemplateNotFound(template)
jinja2.exceptions.TemplateNotFound: queries/create_fact_table.sql
[2025-02-11T10:41:04.053+0000] {processor.py:925} INFO - DAG(s) 'Covid19' retrieved from /opt/airflow/dags/covid_19.py
[2025-02-11T10:41:04.081+0000] {logging_mixin.py:190} INFO - [2025-02-11T10:41:04.080+0000] {dag.py:3239} INFO - Sync 1 DAGs
[2025-02-11T10:41:04.110+0000] {logging_mixin.py:190} INFO - [2025-02-11T10:41:04.109+0000] {dag.py:4180} INFO - Setting next_dagrun for Covid19 to 2025-02-11 10:40:00+00:00, run_after=2025-02-11 10:45:00+00:00
[2025-02-11T10:41:04.142+0000] {processor.py:208} INFO - Processing /opt/airflow/dags/covid_19.py took 0.590 seconds
[2025-02-11T10:41:34.446+0000] {processor.py:186} INFO - Started process (PID=276) to work on /opt/airflow/dags/covid_19.py
[2025-02-11T10:41:34.447+0000] {processor.py:914} INFO - Processing file /opt/airflow/dags/covid_19.py for tasks to queue
[2025-02-11T10:41:34.450+0000] {logging_mixin.py:190} INFO - [2025-02-11T10:41:34.449+0000] {dagbag.py:588} INFO - Filling up the DagBag from /opt/airflow/dags/covid_19.py
[2025-02-11T10:41:34.805+0000] {logging_mixin.py:190} INFO - [2025-02-11T10:41:34.803+0000] {templater.py:94} ERROR - Failed to resolve template field 'sql'
Traceback (most recent call last):
  File "/home/airflow/.local/lib/python3.12/site-packages/airflow/template/templater.py", line 92, in resolve_template_files
    setattr(self, field, env.loader.get_source(env, content)[0])  # type: ignore
                         ^^^^^^^^^^^^^^^^^^^^^^^^^^^^^^^^^^^
  File "/home/airflow/.local/lib/python3.12/site-packages/jinja2/loaders.py", line 207, in get_source
    raise TemplateNotFound(template)
jinja2.exceptions.TemplateNotFound: ./queries/create_dim_date.sql
[2025-02-11T10:41:34.807+0000] {logging_mixin.py:190} INFO - [2025-02-11T10:41:34.806+0000] {templater.py:94} ERROR - Failed to resolve template field 'sql'
Traceback (most recent call last):
  File "/home/airflow/.local/lib/python3.12/site-packages/airflow/template/templater.py", line 92, in resolve_template_files
    setattr(self, field, env.loader.get_source(env, content)[0])  # type: ignore
                         ^^^^^^^^^^^^^^^^^^^^^^^^^^^^^^^^^^^
  File "/home/airflow/.local/lib/python3.12/site-packages/jinja2/loaders.py", line 207, in get_source
    raise TemplateNotFound(template)
jinja2.exceptions.TemplateNotFound: ./queries/create_dim_location.sql
[2025-02-11T10:41:34.808+0000] {logging_mixin.py:190} INFO - [2025-02-11T10:41:34.808+0000] {templater.py:94} ERROR - Failed to resolve template field 'sql'
Traceback (most recent call last):
  File "/home/airflow/.local/lib/python3.12/site-packages/airflow/template/templater.py", line 92, in resolve_template_files
    setattr(self, field, env.loader.get_source(env, content)[0])  # type: ignore
                         ^^^^^^^^^^^^^^^^^^^^^^^^^^^^^^^^^^^
  File "/home/airflow/.local/lib/python3.12/site-packages/jinja2/loaders.py", line 207, in get_source
    raise TemplateNotFound(template)
jinja2.exceptions.TemplateNotFound: queries/create_fact_table.sql
[2025-02-11T10:41:34.812+0000] {processor.py:925} INFO - DAG(s) 'Covid19' retrieved from /opt/airflow/dags/covid_19.py
[2025-02-11T10:41:34.840+0000] {logging_mixin.py:190} INFO - [2025-02-11T10:41:34.840+0000] {dag.py:3239} INFO - Sync 1 DAGs
[2025-02-11T10:41:34.862+0000] {logging_mixin.py:190} INFO - [2025-02-11T10:41:34.862+0000] {dag.py:4180} INFO - Setting next_dagrun for Covid19 to 2025-02-11 10:40:00+00:00, run_after=2025-02-11 10:45:00+00:00
[2025-02-11T10:41:34.885+0000] {processor.py:208} INFO - Processing /opt/airflow/dags/covid_19.py took 0.446 seconds
[2025-02-11T10:42:05.245+0000] {processor.py:186} INFO - Started process (PID=284) to work on /opt/airflow/dags/covid_19.py
[2025-02-11T10:42:05.247+0000] {processor.py:914} INFO - Processing file /opt/airflow/dags/covid_19.py for tasks to queue
[2025-02-11T10:42:05.249+0000] {logging_mixin.py:190} INFO - [2025-02-11T10:42:05.248+0000] {dagbag.py:588} INFO - Filling up the DagBag from /opt/airflow/dags/covid_19.py
[2025-02-11T10:42:05.539+0000] {logging_mixin.py:190} INFO - [2025-02-11T10:42:05.537+0000] {templater.py:94} ERROR - Failed to resolve template field 'sql'
Traceback (most recent call last):
  File "/home/airflow/.local/lib/python3.12/site-packages/airflow/template/templater.py", line 92, in resolve_template_files
    setattr(self, field, env.loader.get_source(env, content)[0])  # type: ignore
                         ^^^^^^^^^^^^^^^^^^^^^^^^^^^^^^^^^^^
  File "/home/airflow/.local/lib/python3.12/site-packages/jinja2/loaders.py", line 207, in get_source
    raise TemplateNotFound(template)
jinja2.exceptions.TemplateNotFound: ./queries/create_dim_date.sql
[2025-02-11T10:42:05.541+0000] {logging_mixin.py:190} INFO - [2025-02-11T10:42:05.541+0000] {templater.py:94} ERROR - Failed to resolve template field 'sql'
Traceback (most recent call last):
  File "/home/airflow/.local/lib/python3.12/site-packages/airflow/template/templater.py", line 92, in resolve_template_files
    setattr(self, field, env.loader.get_source(env, content)[0])  # type: ignore
                         ^^^^^^^^^^^^^^^^^^^^^^^^^^^^^^^^^^^
  File "/home/airflow/.local/lib/python3.12/site-packages/jinja2/loaders.py", line 207, in get_source
    raise TemplateNotFound(template)
jinja2.exceptions.TemplateNotFound: ./queries/create_dim_location.sql
[2025-02-11T10:42:05.542+0000] {logging_mixin.py:190} INFO - [2025-02-11T10:42:05.542+0000] {templater.py:94} ERROR - Failed to resolve template field 'sql'
Traceback (most recent call last):
  File "/home/airflow/.local/lib/python3.12/site-packages/airflow/template/templater.py", line 92, in resolve_template_files
    setattr(self, field, env.loader.get_source(env, content)[0])  # type: ignore
                         ^^^^^^^^^^^^^^^^^^^^^^^^^^^^^^^^^^^
  File "/home/airflow/.local/lib/python3.12/site-packages/jinja2/loaders.py", line 207, in get_source
    raise TemplateNotFound(template)
jinja2.exceptions.TemplateNotFound: queries/create_fact_table.sql
[2025-02-11T10:42:05.545+0000] {processor.py:925} INFO - DAG(s) 'Covid19' retrieved from /opt/airflow/dags/covid_19.py
[2025-02-11T10:42:05.570+0000] {logging_mixin.py:190} INFO - [2025-02-11T10:42:05.569+0000] {dag.py:3239} INFO - Sync 1 DAGs
[2025-02-11T10:42:05.592+0000] {logging_mixin.py:190} INFO - [2025-02-11T10:42:05.592+0000] {dag.py:4180} INFO - Setting next_dagrun for Covid19 to 2025-02-11 10:40:00+00:00, run_after=2025-02-11 10:45:00+00:00
[2025-02-11T10:42:05.615+0000] {processor.py:208} INFO - Processing /opt/airflow/dags/covid_19.py took 0.378 seconds
[2025-02-11T10:42:35.949+0000] {processor.py:186} INFO - Started process (PID=292) to work on /opt/airflow/dags/covid_19.py
[2025-02-11T10:42:35.951+0000] {processor.py:914} INFO - Processing file /opt/airflow/dags/covid_19.py for tasks to queue
[2025-02-11T10:42:35.952+0000] {logging_mixin.py:190} INFO - [2025-02-11T10:42:35.952+0000] {dagbag.py:588} INFO - Filling up the DagBag from /opt/airflow/dags/covid_19.py
[2025-02-11T10:42:36.336+0000] {logging_mixin.py:190} INFO - [2025-02-11T10:42:36.334+0000] {templater.py:94} ERROR - Failed to resolve template field 'sql'
Traceback (most recent call last):
  File "/home/airflow/.local/lib/python3.12/site-packages/airflow/template/templater.py", line 92, in resolve_template_files
    setattr(self, field, env.loader.get_source(env, content)[0])  # type: ignore
                         ^^^^^^^^^^^^^^^^^^^^^^^^^^^^^^^^^^^
  File "/home/airflow/.local/lib/python3.12/site-packages/jinja2/loaders.py", line 207, in get_source
    raise TemplateNotFound(template)
jinja2.exceptions.TemplateNotFound: ./queries/create_dim_date.sql
[2025-02-11T10:42:36.337+0000] {logging_mixin.py:190} INFO - [2025-02-11T10:42:36.337+0000] {templater.py:94} ERROR - Failed to resolve template field 'sql'
Traceback (most recent call last):
  File "/home/airflow/.local/lib/python3.12/site-packages/airflow/template/templater.py", line 92, in resolve_template_files
    setattr(self, field, env.loader.get_source(env, content)[0])  # type: ignore
                         ^^^^^^^^^^^^^^^^^^^^^^^^^^^^^^^^^^^
  File "/home/airflow/.local/lib/python3.12/site-packages/jinja2/loaders.py", line 207, in get_source
    raise TemplateNotFound(template)
jinja2.exceptions.TemplateNotFound: ./queries/create_dim_location.sql
[2025-02-11T10:42:36.339+0000] {logging_mixin.py:190} INFO - [2025-02-11T10:42:36.339+0000] {templater.py:94} ERROR - Failed to resolve template field 'sql'
Traceback (most recent call last):
  File "/home/airflow/.local/lib/python3.12/site-packages/airflow/template/templater.py", line 92, in resolve_template_files
    setattr(self, field, env.loader.get_source(env, content)[0])  # type: ignore
                         ^^^^^^^^^^^^^^^^^^^^^^^^^^^^^^^^^^^
  File "/home/airflow/.local/lib/python3.12/site-packages/jinja2/loaders.py", line 207, in get_source
    raise TemplateNotFound(template)
jinja2.exceptions.TemplateNotFound: queries/create_fact_table.sql
[2025-02-11T10:42:36.345+0000] {processor.py:925} INFO - DAG(s) 'Covid19' retrieved from /opt/airflow/dags/covid_19.py
[2025-02-11T10:42:36.392+0000] {logging_mixin.py:190} INFO - [2025-02-11T10:42:36.392+0000] {dag.py:3239} INFO - Sync 1 DAGs
[2025-02-11T10:42:36.459+0000] {logging_mixin.py:190} INFO - [2025-02-11T10:42:36.458+0000] {dag.py:4180} INFO - Setting next_dagrun for Covid19 to 2025-02-11 10:40:00+00:00, run_after=2025-02-11 10:45:00+00:00
[2025-02-11T10:42:36.501+0000] {processor.py:208} INFO - Processing /opt/airflow/dags/covid_19.py took 0.564 seconds
[2025-02-11T10:43:06.862+0000] {processor.py:186} INFO - Started process (PID=300) to work on /opt/airflow/dags/covid_19.py
[2025-02-11T10:43:06.863+0000] {processor.py:914} INFO - Processing file /opt/airflow/dags/covid_19.py for tasks to queue
[2025-02-11T10:43:06.865+0000] {logging_mixin.py:190} INFO - [2025-02-11T10:43:06.864+0000] {dagbag.py:588} INFO - Filling up the DagBag from /opt/airflow/dags/covid_19.py
[2025-02-11T10:43:07.350+0000] {logging_mixin.py:190} INFO - [2025-02-11T10:43:07.348+0000] {templater.py:94} ERROR - Failed to resolve template field 'sql'
Traceback (most recent call last):
  File "/home/airflow/.local/lib/python3.12/site-packages/airflow/template/templater.py", line 92, in resolve_template_files
    setattr(self, field, env.loader.get_source(env, content)[0])  # type: ignore
                         ^^^^^^^^^^^^^^^^^^^^^^^^^^^^^^^^^^^
  File "/home/airflow/.local/lib/python3.12/site-packages/jinja2/loaders.py", line 207, in get_source
    raise TemplateNotFound(template)
jinja2.exceptions.TemplateNotFound: ./queries/create_dim_date.sql
[2025-02-11T10:43:07.353+0000] {logging_mixin.py:190} INFO - [2025-02-11T10:43:07.352+0000] {templater.py:94} ERROR - Failed to resolve template field 'sql'
Traceback (most recent call last):
  File "/home/airflow/.local/lib/python3.12/site-packages/airflow/template/templater.py", line 92, in resolve_template_files
    setattr(self, field, env.loader.get_source(env, content)[0])  # type: ignore
                         ^^^^^^^^^^^^^^^^^^^^^^^^^^^^^^^^^^^
  File "/home/airflow/.local/lib/python3.12/site-packages/jinja2/loaders.py", line 207, in get_source
    raise TemplateNotFound(template)
jinja2.exceptions.TemplateNotFound: ./queries/create_dim_location.sql
[2025-02-11T10:43:07.355+0000] {logging_mixin.py:190} INFO - [2025-02-11T10:43:07.354+0000] {templater.py:94} ERROR - Failed to resolve template field 'sql'
Traceback (most recent call last):
  File "/home/airflow/.local/lib/python3.12/site-packages/airflow/template/templater.py", line 92, in resolve_template_files
    setattr(self, field, env.loader.get_source(env, content)[0])  # type: ignore
                         ^^^^^^^^^^^^^^^^^^^^^^^^^^^^^^^^^^^
  File "/home/airflow/.local/lib/python3.12/site-packages/jinja2/loaders.py", line 207, in get_source
    raise TemplateNotFound(template)
jinja2.exceptions.TemplateNotFound: queries/create_fact_table.sql
[2025-02-11T10:43:07.360+0000] {processor.py:925} INFO - DAG(s) 'Covid19' retrieved from /opt/airflow/dags/covid_19.py
[2025-02-11T10:43:07.389+0000] {logging_mixin.py:190} INFO - [2025-02-11T10:43:07.389+0000] {dag.py:3239} INFO - Sync 1 DAGs
[2025-02-11T10:43:07.418+0000] {logging_mixin.py:190} INFO - [2025-02-11T10:43:07.418+0000] {dag.py:4180} INFO - Setting next_dagrun for Covid19 to 2025-02-11 10:40:00+00:00, run_after=2025-02-11 10:45:00+00:00
[2025-02-11T10:43:07.442+0000] {processor.py:208} INFO - Processing /opt/airflow/dags/covid_19.py took 0.586 seconds
[2025-02-11T10:43:37.721+0000] {processor.py:186} INFO - Started process (PID=308) to work on /opt/airflow/dags/covid_19.py
[2025-02-11T10:43:37.722+0000] {processor.py:914} INFO - Processing file /opt/airflow/dags/covid_19.py for tasks to queue
[2025-02-11T10:43:37.724+0000] {logging_mixin.py:190} INFO - [2025-02-11T10:43:37.723+0000] {dagbag.py:588} INFO - Filling up the DagBag from /opt/airflow/dags/covid_19.py
[2025-02-11T10:43:38.077+0000] {logging_mixin.py:190} INFO - [2025-02-11T10:43:38.075+0000] {templater.py:94} ERROR - Failed to resolve template field 'sql'
Traceback (most recent call last):
  File "/home/airflow/.local/lib/python3.12/site-packages/airflow/template/templater.py", line 92, in resolve_template_files
    setattr(self, field, env.loader.get_source(env, content)[0])  # type: ignore
                         ^^^^^^^^^^^^^^^^^^^^^^^^^^^^^^^^^^^
  File "/home/airflow/.local/lib/python3.12/site-packages/jinja2/loaders.py", line 207, in get_source
    raise TemplateNotFound(template)
jinja2.exceptions.TemplateNotFound: ./queries/create_dim_date.sql
[2025-02-11T10:43:38.079+0000] {logging_mixin.py:190} INFO - [2025-02-11T10:43:38.078+0000] {templater.py:94} ERROR - Failed to resolve template field 'sql'
Traceback (most recent call last):
  File "/home/airflow/.local/lib/python3.12/site-packages/airflow/template/templater.py", line 92, in resolve_template_files
    setattr(self, field, env.loader.get_source(env, content)[0])  # type: ignore
                         ^^^^^^^^^^^^^^^^^^^^^^^^^^^^^^^^^^^
  File "/home/airflow/.local/lib/python3.12/site-packages/jinja2/loaders.py", line 207, in get_source
    raise TemplateNotFound(template)
jinja2.exceptions.TemplateNotFound: ./queries/create_dim_location.sql
[2025-02-11T10:43:38.080+0000] {logging_mixin.py:190} INFO - [2025-02-11T10:43:38.079+0000] {templater.py:94} ERROR - Failed to resolve template field 'sql'
Traceback (most recent call last):
  File "/home/airflow/.local/lib/python3.12/site-packages/airflow/template/templater.py", line 92, in resolve_template_files
    setattr(self, field, env.loader.get_source(env, content)[0])  # type: ignore
                         ^^^^^^^^^^^^^^^^^^^^^^^^^^^^^^^^^^^
  File "/home/airflow/.local/lib/python3.12/site-packages/jinja2/loaders.py", line 207, in get_source
    raise TemplateNotFound(template)
jinja2.exceptions.TemplateNotFound: queries/create_fact_table.sql
[2025-02-11T10:43:38.083+0000] {processor.py:925} INFO - DAG(s) 'Covid19' retrieved from /opt/airflow/dags/covid_19.py
[2025-02-11T10:43:38.109+0000] {logging_mixin.py:190} INFO - [2025-02-11T10:43:38.108+0000] {dag.py:3239} INFO - Sync 1 DAGs
[2025-02-11T10:43:38.133+0000] {logging_mixin.py:190} INFO - [2025-02-11T10:43:38.133+0000] {dag.py:4180} INFO - Setting next_dagrun for Covid19 to 2025-02-11 10:40:00+00:00, run_after=2025-02-11 10:45:00+00:00
[2025-02-11T10:43:38.157+0000] {processor.py:208} INFO - Processing /opt/airflow/dags/covid_19.py took 0.442 seconds
[2025-02-11T10:44:08.471+0000] {processor.py:186} INFO - Started process (PID=317) to work on /opt/airflow/dags/covid_19.py
[2025-02-11T10:44:08.473+0000] {processor.py:914} INFO - Processing file /opt/airflow/dags/covid_19.py for tasks to queue
[2025-02-11T10:44:08.474+0000] {logging_mixin.py:190} INFO - [2025-02-11T10:44:08.474+0000] {dagbag.py:588} INFO - Filling up the DagBag from /opt/airflow/dags/covid_19.py
[2025-02-11T10:44:08.793+0000] {logging_mixin.py:190} INFO - [2025-02-11T10:44:08.791+0000] {templater.py:94} ERROR - Failed to resolve template field 'sql'
Traceback (most recent call last):
  File "/home/airflow/.local/lib/python3.12/site-packages/airflow/template/templater.py", line 92, in resolve_template_files
    setattr(self, field, env.loader.get_source(env, content)[0])  # type: ignore
                         ^^^^^^^^^^^^^^^^^^^^^^^^^^^^^^^^^^^
  File "/home/airflow/.local/lib/python3.12/site-packages/jinja2/loaders.py", line 207, in get_source
    raise TemplateNotFound(template)
jinja2.exceptions.TemplateNotFound: ./queries/create_dim_date.sql
[2025-02-11T10:44:08.794+0000] {logging_mixin.py:190} INFO - [2025-02-11T10:44:08.794+0000] {templater.py:94} ERROR - Failed to resolve template field 'sql'
Traceback (most recent call last):
  File "/home/airflow/.local/lib/python3.12/site-packages/airflow/template/templater.py", line 92, in resolve_template_files
    setattr(self, field, env.loader.get_source(env, content)[0])  # type: ignore
                         ^^^^^^^^^^^^^^^^^^^^^^^^^^^^^^^^^^^
  File "/home/airflow/.local/lib/python3.12/site-packages/jinja2/loaders.py", line 207, in get_source
    raise TemplateNotFound(template)
jinja2.exceptions.TemplateNotFound: ./queries/create_dim_location.sql
[2025-02-11T10:44:08.796+0000] {logging_mixin.py:190} INFO - [2025-02-11T10:44:08.796+0000] {templater.py:94} ERROR - Failed to resolve template field 'sql'
Traceback (most recent call last):
  File "/home/airflow/.local/lib/python3.12/site-packages/airflow/template/templater.py", line 92, in resolve_template_files
    setattr(self, field, env.loader.get_source(env, content)[0])  # type: ignore
                         ^^^^^^^^^^^^^^^^^^^^^^^^^^^^^^^^^^^
  File "/home/airflow/.local/lib/python3.12/site-packages/jinja2/loaders.py", line 207, in get_source
    raise TemplateNotFound(template)
jinja2.exceptions.TemplateNotFound: queries/create_fact_table.sql
[2025-02-11T10:44:08.800+0000] {processor.py:925} INFO - DAG(s) 'Covid19' retrieved from /opt/airflow/dags/covid_19.py
[2025-02-11T10:44:08.829+0000] {logging_mixin.py:190} INFO - [2025-02-11T10:44:08.829+0000] {dag.py:3239} INFO - Sync 1 DAGs
[2025-02-11T10:44:08.851+0000] {logging_mixin.py:190} INFO - [2025-02-11T10:44:08.851+0000] {dag.py:4180} INFO - Setting next_dagrun for Covid19 to 2025-02-11 10:40:00+00:00, run_after=2025-02-11 10:45:00+00:00
[2025-02-11T10:44:08.876+0000] {processor.py:208} INFO - Processing /opt/airflow/dags/covid_19.py took 0.411 seconds
[2025-02-11T10:44:39.155+0000] {processor.py:186} INFO - Started process (PID=325) to work on /opt/airflow/dags/covid_19.py
[2025-02-11T10:44:39.156+0000] {processor.py:914} INFO - Processing file /opt/airflow/dags/covid_19.py for tasks to queue
[2025-02-11T10:44:39.158+0000] {logging_mixin.py:190} INFO - [2025-02-11T10:44:39.157+0000] {dagbag.py:588} INFO - Filling up the DagBag from /opt/airflow/dags/covid_19.py
[2025-02-11T10:44:39.495+0000] {logging_mixin.py:190} INFO - [2025-02-11T10:44:39.492+0000] {templater.py:94} ERROR - Failed to resolve template field 'sql'
Traceback (most recent call last):
  File "/home/airflow/.local/lib/python3.12/site-packages/airflow/template/templater.py", line 92, in resolve_template_files
    setattr(self, field, env.loader.get_source(env, content)[0])  # type: ignore
                         ^^^^^^^^^^^^^^^^^^^^^^^^^^^^^^^^^^^
  File "/home/airflow/.local/lib/python3.12/site-packages/jinja2/loaders.py", line 207, in get_source
    raise TemplateNotFound(template)
jinja2.exceptions.TemplateNotFound: ./queries/create_dim_date.sql
[2025-02-11T10:44:39.496+0000] {logging_mixin.py:190} INFO - [2025-02-11T10:44:39.496+0000] {templater.py:94} ERROR - Failed to resolve template field 'sql'
Traceback (most recent call last):
  File "/home/airflow/.local/lib/python3.12/site-packages/airflow/template/templater.py", line 92, in resolve_template_files
    setattr(self, field, env.loader.get_source(env, content)[0])  # type: ignore
                         ^^^^^^^^^^^^^^^^^^^^^^^^^^^^^^^^^^^
  File "/home/airflow/.local/lib/python3.12/site-packages/jinja2/loaders.py", line 207, in get_source
    raise TemplateNotFound(template)
jinja2.exceptions.TemplateNotFound: ./queries/create_dim_location.sql
[2025-02-11T10:44:39.498+0000] {logging_mixin.py:190} INFO - [2025-02-11T10:44:39.497+0000] {templater.py:94} ERROR - Failed to resolve template field 'sql'
Traceback (most recent call last):
  File "/home/airflow/.local/lib/python3.12/site-packages/airflow/template/templater.py", line 92, in resolve_template_files
    setattr(self, field, env.loader.get_source(env, content)[0])  # type: ignore
                         ^^^^^^^^^^^^^^^^^^^^^^^^^^^^^^^^^^^
  File "/home/airflow/.local/lib/python3.12/site-packages/jinja2/loaders.py", line 207, in get_source
    raise TemplateNotFound(template)
jinja2.exceptions.TemplateNotFound: queries/create_fact_table.sql
[2025-02-11T10:44:39.502+0000] {processor.py:925} INFO - DAG(s) 'Covid19' retrieved from /opt/airflow/dags/covid_19.py
[2025-02-11T10:44:39.526+0000] {logging_mixin.py:190} INFO - [2025-02-11T10:44:39.525+0000] {dag.py:3239} INFO - Sync 1 DAGs
[2025-02-11T10:44:39.548+0000] {logging_mixin.py:190} INFO - [2025-02-11T10:44:39.548+0000] {dag.py:4180} INFO - Setting next_dagrun for Covid19 to 2025-02-11 10:40:00+00:00, run_after=2025-02-11 10:45:00+00:00
[2025-02-11T10:44:39.569+0000] {processor.py:208} INFO - Processing /opt/airflow/dags/covid_19.py took 0.421 seconds
[2025-02-11T10:45:09.887+0000] {processor.py:186} INFO - Started process (PID=333) to work on /opt/airflow/dags/covid_19.py
[2025-02-11T10:45:09.889+0000] {processor.py:914} INFO - Processing file /opt/airflow/dags/covid_19.py for tasks to queue
[2025-02-11T10:45:09.896+0000] {logging_mixin.py:190} INFO - [2025-02-11T10:45:09.896+0000] {dagbag.py:588} INFO - Filling up the DagBag from /opt/airflow/dags/covid_19.py
[2025-02-11T10:45:10.453+0000] {logging_mixin.py:190} INFO - [2025-02-11T10:45:10.448+0000] {templater.py:94} ERROR - Failed to resolve template field 'sql'
Traceback (most recent call last):
  File "/home/airflow/.local/lib/python3.12/site-packages/airflow/template/templater.py", line 92, in resolve_template_files
    setattr(self, field, env.loader.get_source(env, content)[0])  # type: ignore
                         ^^^^^^^^^^^^^^^^^^^^^^^^^^^^^^^^^^^
  File "/home/airflow/.local/lib/python3.12/site-packages/jinja2/loaders.py", line 207, in get_source
    raise TemplateNotFound(template)
jinja2.exceptions.TemplateNotFound: ./queries/create_dim_date.sql
[2025-02-11T10:45:10.454+0000] {logging_mixin.py:190} INFO - [2025-02-11T10:45:10.454+0000] {templater.py:94} ERROR - Failed to resolve template field 'sql'
Traceback (most recent call last):
  File "/home/airflow/.local/lib/python3.12/site-packages/airflow/template/templater.py", line 92, in resolve_template_files
    setattr(self, field, env.loader.get_source(env, content)[0])  # type: ignore
                         ^^^^^^^^^^^^^^^^^^^^^^^^^^^^^^^^^^^
  File "/home/airflow/.local/lib/python3.12/site-packages/jinja2/loaders.py", line 207, in get_source
    raise TemplateNotFound(template)
jinja2.exceptions.TemplateNotFound: ./queries/create_dim_location.sql
[2025-02-11T10:45:10.455+0000] {logging_mixin.py:190} INFO - [2025-02-11T10:45:10.455+0000] {templater.py:94} ERROR - Failed to resolve template field 'sql'
Traceback (most recent call last):
  File "/home/airflow/.local/lib/python3.12/site-packages/airflow/template/templater.py", line 92, in resolve_template_files
    setattr(self, field, env.loader.get_source(env, content)[0])  # type: ignore
                         ^^^^^^^^^^^^^^^^^^^^^^^^^^^^^^^^^^^
  File "/home/airflow/.local/lib/python3.12/site-packages/jinja2/loaders.py", line 207, in get_source
    raise TemplateNotFound(template)
jinja2.exceptions.TemplateNotFound: queries/create_fact_table.sql
[2025-02-11T10:45:10.461+0000] {processor.py:925} INFO - DAG(s) 'Covid19' retrieved from /opt/airflow/dags/covid_19.py
[2025-02-11T10:45:10.518+0000] {logging_mixin.py:190} INFO - [2025-02-11T10:45:10.516+0000] {dag.py:3239} INFO - Sync 1 DAGs
[2025-02-11T10:45:10.571+0000] {logging_mixin.py:190} INFO - [2025-02-11T10:45:10.571+0000] {dag.py:4180} INFO - Setting next_dagrun for Covid19 to 2025-02-11 10:40:00+00:00, run_after=2025-02-11 10:45:00+00:00
[2025-02-11T10:45:10.628+0000] {processor.py:208} INFO - Processing /opt/airflow/dags/covid_19.py took 0.761 seconds
[2025-02-11T10:45:40.715+0000] {processor.py:186} INFO - Started process (PID=341) to work on /opt/airflow/dags/covid_19.py
[2025-02-11T10:45:40.718+0000] {processor.py:914} INFO - Processing file /opt/airflow/dags/covid_19.py for tasks to queue
[2025-02-11T10:45:40.723+0000] {logging_mixin.py:190} INFO - [2025-02-11T10:45:40.721+0000] {dagbag.py:588} INFO - Filling up the DagBag from /opt/airflow/dags/covid_19.py
[2025-02-11T10:45:41.087+0000] {logging_mixin.py:190} INFO - [2025-02-11T10:45:41.085+0000] {templater.py:94} ERROR - Failed to resolve template field 'sql'
Traceback (most recent call last):
  File "/home/airflow/.local/lib/python3.12/site-packages/airflow/template/templater.py", line 92, in resolve_template_files
    setattr(self, field, env.loader.get_source(env, content)[0])  # type: ignore
                         ^^^^^^^^^^^^^^^^^^^^^^^^^^^^^^^^^^^
  File "/home/airflow/.local/lib/python3.12/site-packages/jinja2/loaders.py", line 207, in get_source
    raise TemplateNotFound(template)
jinja2.exceptions.TemplateNotFound: ./queries/create_dim_date.sql
[2025-02-11T10:45:41.089+0000] {logging_mixin.py:190} INFO - [2025-02-11T10:45:41.088+0000] {templater.py:94} ERROR - Failed to resolve template field 'sql'
Traceback (most recent call last):
  File "/home/airflow/.local/lib/python3.12/site-packages/airflow/template/templater.py", line 92, in resolve_template_files
    setattr(self, field, env.loader.get_source(env, content)[0])  # type: ignore
                         ^^^^^^^^^^^^^^^^^^^^^^^^^^^^^^^^^^^
  File "/home/airflow/.local/lib/python3.12/site-packages/jinja2/loaders.py", line 207, in get_source
    raise TemplateNotFound(template)
jinja2.exceptions.TemplateNotFound: ./queries/create_dim_location.sql
[2025-02-11T10:45:41.090+0000] {logging_mixin.py:190} INFO - [2025-02-11T10:45:41.090+0000] {templater.py:94} ERROR - Failed to resolve template field 'sql'
Traceback (most recent call last):
  File "/home/airflow/.local/lib/python3.12/site-packages/airflow/template/templater.py", line 92, in resolve_template_files
    setattr(self, field, env.loader.get_source(env, content)[0])  # type: ignore
                         ^^^^^^^^^^^^^^^^^^^^^^^^^^^^^^^^^^^
  File "/home/airflow/.local/lib/python3.12/site-packages/jinja2/loaders.py", line 207, in get_source
    raise TemplateNotFound(template)
jinja2.exceptions.TemplateNotFound: queries/create_fact_table.sql
[2025-02-11T10:45:41.093+0000] {processor.py:925} INFO - DAG(s) 'Covid19' retrieved from /opt/airflow/dags/covid_19.py
[2025-02-11T10:45:41.119+0000] {logging_mixin.py:190} INFO - [2025-02-11T10:45:41.119+0000] {dag.py:3239} INFO - Sync 1 DAGs
[2025-02-11T10:45:41.140+0000] {logging_mixin.py:190} INFO - [2025-02-11T10:45:41.140+0000] {dag.py:4180} INFO - Setting next_dagrun for Covid19 to 2025-02-11 10:40:00+00:00, run_after=2025-02-11 10:45:00+00:00
[2025-02-11T10:45:41.165+0000] {processor.py:208} INFO - Processing /opt/airflow/dags/covid_19.py took 0.459 seconds
[2025-02-11T10:46:11.452+0000] {processor.py:186} INFO - Started process (PID=350) to work on /opt/airflow/dags/covid_19.py
[2025-02-11T10:46:11.453+0000] {processor.py:914} INFO - Processing file /opt/airflow/dags/covid_19.py for tasks to queue
[2025-02-11T10:46:11.454+0000] {logging_mixin.py:190} INFO - [2025-02-11T10:46:11.454+0000] {dagbag.py:588} INFO - Filling up the DagBag from /opt/airflow/dags/covid_19.py
[2025-02-11T10:46:11.732+0000] {logging_mixin.py:190} INFO - [2025-02-11T10:46:11.730+0000] {templater.py:94} ERROR - Failed to resolve template field 'sql'
Traceback (most recent call last):
  File "/home/airflow/.local/lib/python3.12/site-packages/airflow/template/templater.py", line 92, in resolve_template_files
    setattr(self, field, env.loader.get_source(env, content)[0])  # type: ignore
                         ^^^^^^^^^^^^^^^^^^^^^^^^^^^^^^^^^^^
  File "/home/airflow/.local/lib/python3.12/site-packages/jinja2/loaders.py", line 207, in get_source
    raise TemplateNotFound(template)
jinja2.exceptions.TemplateNotFound: ./queries/create_dim_date.sql
[2025-02-11T10:46:11.733+0000] {logging_mixin.py:190} INFO - [2025-02-11T10:46:11.733+0000] {templater.py:94} ERROR - Failed to resolve template field 'sql'
Traceback (most recent call last):
  File "/home/airflow/.local/lib/python3.12/site-packages/airflow/template/templater.py", line 92, in resolve_template_files
    setattr(self, field, env.loader.get_source(env, content)[0])  # type: ignore
                         ^^^^^^^^^^^^^^^^^^^^^^^^^^^^^^^^^^^
  File "/home/airflow/.local/lib/python3.12/site-packages/jinja2/loaders.py", line 207, in get_source
    raise TemplateNotFound(template)
jinja2.exceptions.TemplateNotFound: ./queries/create_dim_location.sql
[2025-02-11T10:46:11.734+0000] {logging_mixin.py:190} INFO - [2025-02-11T10:46:11.734+0000] {templater.py:94} ERROR - Failed to resolve template field 'sql'
Traceback (most recent call last):
  File "/home/airflow/.local/lib/python3.12/site-packages/airflow/template/templater.py", line 92, in resolve_template_files
    setattr(self, field, env.loader.get_source(env, content)[0])  # type: ignore
                         ^^^^^^^^^^^^^^^^^^^^^^^^^^^^^^^^^^^
  File "/home/airflow/.local/lib/python3.12/site-packages/jinja2/loaders.py", line 207, in get_source
    raise TemplateNotFound(template)
jinja2.exceptions.TemplateNotFound: queries/create_fact_table.sql
[2025-02-11T10:46:11.737+0000] {processor.py:925} INFO - DAG(s) 'Covid19' retrieved from /opt/airflow/dags/covid_19.py
[2025-02-11T10:46:11.761+0000] {logging_mixin.py:190} INFO - [2025-02-11T10:46:11.761+0000] {dag.py:3239} INFO - Sync 1 DAGs
[2025-02-11T10:46:11.781+0000] {logging_mixin.py:190} INFO - [2025-02-11T10:46:11.781+0000] {dag.py:4180} INFO - Setting next_dagrun for Covid19 to 2025-02-11 10:40:00+00:00, run_after=2025-02-11 10:45:00+00:00
[2025-02-11T10:46:11.805+0000] {processor.py:208} INFO - Processing /opt/airflow/dags/covid_19.py took 0.360 seconds
[2025-02-11T10:58:17.883+0000] {processor.py:186} INFO - Started process (PID=38) to work on /opt/airflow/dags/covid_19.py
[2025-02-11T10:58:17.896+0000] {processor.py:914} INFO - Processing file /opt/airflow/dags/covid_19.py for tasks to queue
[2025-02-11T10:58:18.044+0000] {logging_mixin.py:190} INFO - [2025-02-11T10:58:18.038+0000] {dagbag.py:588} INFO - Filling up the DagBag from /opt/airflow/dags/covid_19.py
[2025-02-11T10:58:37.366+0000] {logging_mixin.py:190} INFO - [2025-02-11T10:58:37.357+0000] {templater.py:94} ERROR - Failed to resolve template field 'sql'
Traceback (most recent call last):
  File "/home/airflow/.local/lib/python3.12/site-packages/airflow/template/templater.py", line 92, in resolve_template_files
    setattr(self, field, env.loader.get_source(env, content)[0])  # type: ignore
                         ^^^^^^^^^^^^^^^^^^^^^^^^^^^^^^^^^^^
  File "/home/airflow/.local/lib/python3.12/site-packages/jinja2/loaders.py", line 207, in get_source
    raise TemplateNotFound(template)
jinja2.exceptions.TemplateNotFound: ./queries/create_dim_date.sql
[2025-02-11T10:58:37.369+0000] {logging_mixin.py:190} INFO - [2025-02-11T10:58:37.368+0000] {templater.py:94} ERROR - Failed to resolve template field 'sql'
Traceback (most recent call last):
  File "/home/airflow/.local/lib/python3.12/site-packages/airflow/template/templater.py", line 92, in resolve_template_files
    setattr(self, field, env.loader.get_source(env, content)[0])  # type: ignore
                         ^^^^^^^^^^^^^^^^^^^^^^^^^^^^^^^^^^^
  File "/home/airflow/.local/lib/python3.12/site-packages/jinja2/loaders.py", line 207, in get_source
    raise TemplateNotFound(template)
jinja2.exceptions.TemplateNotFound: ./queries/create_dim_location.sql
[2025-02-11T10:58:37.371+0000] {logging_mixin.py:190} INFO - [2025-02-11T10:58:37.370+0000] {templater.py:94} ERROR - Failed to resolve template field 'sql'
Traceback (most recent call last):
  File "/home/airflow/.local/lib/python3.12/site-packages/airflow/template/templater.py", line 92, in resolve_template_files
    setattr(self, field, env.loader.get_source(env, content)[0])  # type: ignore
                         ^^^^^^^^^^^^^^^^^^^^^^^^^^^^^^^^^^^
  File "/home/airflow/.local/lib/python3.12/site-packages/jinja2/loaders.py", line 207, in get_source
    raise TemplateNotFound(template)
jinja2.exceptions.TemplateNotFound: queries/create_fact_table.sql
[2025-02-11T10:58:37.417+0000] {processor.py:925} INFO - DAG(s) 'Covid19' retrieved from /opt/airflow/dags/covid_19.py
[2025-02-11T10:58:37.623+0000] {logging_mixin.py:190} INFO - [2025-02-11T10:58:37.622+0000] {dag.py:3239} INFO - Sync 1 DAGs
[2025-02-11T10:58:37.851+0000] {logging_mixin.py:190} INFO - [2025-02-11T10:58:37.749+0000] {dag.py:4180} INFO - Setting next_dagrun for Covid19 to 2025-02-11 10:50:00+00:00, run_after=2025-02-11 10:55:00+00:00
[2025-02-11T10:58:37.962+0000] {processor.py:208} INFO - Processing /opt/airflow/dags/covid_19.py took 26.650 seconds
[2025-02-11T10:59:08.523+0000] {processor.py:186} INFO - Started process (PID=48) to work on /opt/airflow/dags/covid_19.py
[2025-02-11T10:59:08.525+0000] {processor.py:914} INFO - Processing file /opt/airflow/dags/covid_19.py for tasks to queue
[2025-02-11T10:59:08.537+0000] {logging_mixin.py:190} INFO - [2025-02-11T10:59:08.535+0000] {dagbag.py:588} INFO - Filling up the DagBag from /opt/airflow/dags/covid_19.py
[2025-02-11T10:59:09.593+0000] {logging_mixin.py:190} INFO - [2025-02-11T10:59:09.592+0000] {templater.py:94} ERROR - Failed to resolve template field 'sql'
Traceback (most recent call last):
  File "/home/airflow/.local/lib/python3.12/site-packages/airflow/template/templater.py", line 92, in resolve_template_files
    setattr(self, field, env.loader.get_source(env, content)[0])  # type: ignore
                         ^^^^^^^^^^^^^^^^^^^^^^^^^^^^^^^^^^^
  File "/home/airflow/.local/lib/python3.12/site-packages/jinja2/loaders.py", line 207, in get_source
    raise TemplateNotFound(template)
jinja2.exceptions.TemplateNotFound: ./queries/create_dim_date.sql
[2025-02-11T10:59:09.595+0000] {logging_mixin.py:190} INFO - [2025-02-11T10:59:09.594+0000] {templater.py:94} ERROR - Failed to resolve template field 'sql'
Traceback (most recent call last):
  File "/home/airflow/.local/lib/python3.12/site-packages/airflow/template/templater.py", line 92, in resolve_template_files
    setattr(self, field, env.loader.get_source(env, content)[0])  # type: ignore
                         ^^^^^^^^^^^^^^^^^^^^^^^^^^^^^^^^^^^
  File "/home/airflow/.local/lib/python3.12/site-packages/jinja2/loaders.py", line 207, in get_source
    raise TemplateNotFound(template)
jinja2.exceptions.TemplateNotFound: ./queries/create_dim_location.sql
[2025-02-11T10:59:09.596+0000] {logging_mixin.py:190} INFO - [2025-02-11T10:59:09.596+0000] {templater.py:94} ERROR - Failed to resolve template field 'sql'
Traceback (most recent call last):
  File "/home/airflow/.local/lib/python3.12/site-packages/airflow/template/templater.py", line 92, in resolve_template_files
    setattr(self, field, env.loader.get_source(env, content)[0])  # type: ignore
                         ^^^^^^^^^^^^^^^^^^^^^^^^^^^^^^^^^^^
  File "/home/airflow/.local/lib/python3.12/site-packages/jinja2/loaders.py", line 207, in get_source
    raise TemplateNotFound(template)
jinja2.exceptions.TemplateNotFound: queries/create_fact_table.sql
[2025-02-11T10:59:09.603+0000] {processor.py:925} INFO - DAG(s) 'Covid19' retrieved from /opt/airflow/dags/covid_19.py
[2025-02-11T10:59:09.628+0000] {logging_mixin.py:190} INFO - [2025-02-11T10:59:09.628+0000] {dag.py:3239} INFO - Sync 1 DAGs
[2025-02-11T10:59:09.646+0000] {logging_mixin.py:190} INFO - [2025-02-11T10:59:09.646+0000] {dag.py:4180} INFO - Setting next_dagrun for Covid19 to 2025-02-11 10:50:00+00:00, run_after=2025-02-11 10:55:00+00:00
[2025-02-11T10:59:09.671+0000] {processor.py:208} INFO - Processing /opt/airflow/dags/covid_19.py took 1.166 seconds
[2025-02-11T10:59:39.846+0000] {processor.py:186} INFO - Started process (PID=56) to work on /opt/airflow/dags/covid_19.py
[2025-02-11T10:59:39.848+0000] {processor.py:914} INFO - Processing file /opt/airflow/dags/covid_19.py for tasks to queue
[2025-02-11T10:59:39.851+0000] {logging_mixin.py:190} INFO - [2025-02-11T10:59:39.850+0000] {dagbag.py:588} INFO - Filling up the DagBag from /opt/airflow/dags/covid_19.py
[2025-02-11T10:59:46.738+0000] {logging_mixin.py:190} INFO - [2025-02-11T10:59:46.734+0000] {templater.py:94} ERROR - Failed to resolve template field 'sql'
Traceback (most recent call last):
  File "/home/airflow/.local/lib/python3.12/site-packages/airflow/template/templater.py", line 92, in resolve_template_files
    setattr(self, field, env.loader.get_source(env, content)[0])  # type: ignore
                         ^^^^^^^^^^^^^^^^^^^^^^^^^^^^^^^^^^^
  File "/home/airflow/.local/lib/python3.12/site-packages/jinja2/loaders.py", line 207, in get_source
    raise TemplateNotFound(template)
jinja2.exceptions.TemplateNotFound: ./queries/create_dim_date.sql
[2025-02-11T10:59:46.740+0000] {logging_mixin.py:190} INFO - [2025-02-11T10:59:46.740+0000] {templater.py:94} ERROR - Failed to resolve template field 'sql'
Traceback (most recent call last):
  File "/home/airflow/.local/lib/python3.12/site-packages/airflow/template/templater.py", line 92, in resolve_template_files
    setattr(self, field, env.loader.get_source(env, content)[0])  # type: ignore
                         ^^^^^^^^^^^^^^^^^^^^^^^^^^^^^^^^^^^
  File "/home/airflow/.local/lib/python3.12/site-packages/jinja2/loaders.py", line 207, in get_source
    raise TemplateNotFound(template)
jinja2.exceptions.TemplateNotFound: ./queries/create_dim_location.sql
[2025-02-11T10:59:46.741+0000] {logging_mixin.py:190} INFO - [2025-02-11T10:59:46.741+0000] {templater.py:94} ERROR - Failed to resolve template field 'sql'
Traceback (most recent call last):
  File "/home/airflow/.local/lib/python3.12/site-packages/airflow/template/templater.py", line 92, in resolve_template_files
    setattr(self, field, env.loader.get_source(env, content)[0])  # type: ignore
                         ^^^^^^^^^^^^^^^^^^^^^^^^^^^^^^^^^^^
  File "/home/airflow/.local/lib/python3.12/site-packages/jinja2/loaders.py", line 207, in get_source
    raise TemplateNotFound(template)
jinja2.exceptions.TemplateNotFound: queries/create_fact_table.sql
[2025-02-11T10:59:46.745+0000] {processor.py:925} INFO - DAG(s) 'Covid19' retrieved from /opt/airflow/dags/covid_19.py
[2025-02-11T10:59:46.789+0000] {logging_mixin.py:190} INFO - [2025-02-11T10:59:46.788+0000] {dag.py:3239} INFO - Sync 1 DAGs
[2025-02-11T10:59:46.819+0000] {logging_mixin.py:190} INFO - [2025-02-11T10:59:46.819+0000] {dag.py:4180} INFO - Setting next_dagrun for Covid19 to 2025-02-11 10:50:00+00:00, run_after=2025-02-11 10:55:00+00:00
[2025-02-11T10:59:46.850+0000] {processor.py:208} INFO - Processing /opt/airflow/dags/covid_19.py took 7.012 seconds
[2025-02-11T11:00:17.142+0000] {processor.py:186} INFO - Started process (PID=64) to work on /opt/airflow/dags/covid_19.py
[2025-02-11T11:00:17.144+0000] {processor.py:914} INFO - Processing file /opt/airflow/dags/covid_19.py for tasks to queue
[2025-02-11T11:00:17.147+0000] {logging_mixin.py:190} INFO - [2025-02-11T11:00:17.147+0000] {dagbag.py:588} INFO - Filling up the DagBag from /opt/airflow/dags/covid_19.py
[2025-02-11T11:00:17.993+0000] {logging_mixin.py:190} INFO - [2025-02-11T11:00:17.845+0000] {templater.py:94} ERROR - Failed to resolve template field 'sql'
Traceback (most recent call last):
  File "/home/airflow/.local/lib/python3.12/site-packages/airflow/template/templater.py", line 92, in resolve_template_files
    setattr(self, field, env.loader.get_source(env, content)[0])  # type: ignore
                         ^^^^^^^^^^^^^^^^^^^^^^^^^^^^^^^^^^^
  File "/home/airflow/.local/lib/python3.12/site-packages/jinja2/loaders.py", line 207, in get_source
    raise TemplateNotFound(template)
jinja2.exceptions.TemplateNotFound: ./queries/create_dim_date.sql
[2025-02-11T11:00:18.055+0000] {logging_mixin.py:190} INFO - [2025-02-11T11:00:18.055+0000] {templater.py:94} ERROR - Failed to resolve template field 'sql'
Traceback (most recent call last):
  File "/home/airflow/.local/lib/python3.12/site-packages/airflow/template/templater.py", line 92, in resolve_template_files
    setattr(self, field, env.loader.get_source(env, content)[0])  # type: ignore
                         ^^^^^^^^^^^^^^^^^^^^^^^^^^^^^^^^^^^
  File "/home/airflow/.local/lib/python3.12/site-packages/jinja2/loaders.py", line 207, in get_source
    raise TemplateNotFound(template)
jinja2.exceptions.TemplateNotFound: ./queries/create_dim_location.sql
[2025-02-11T11:00:18.446+0000] {logging_mixin.py:190} INFO - [2025-02-11T11:00:18.057+0000] {templater.py:94} ERROR - Failed to resolve template field 'sql'
Traceback (most recent call last):
  File "/home/airflow/.local/lib/python3.12/site-packages/airflow/template/templater.py", line 92, in resolve_template_files
    setattr(self, field, env.loader.get_source(env, content)[0])  # type: ignore
                         ^^^^^^^^^^^^^^^^^^^^^^^^^^^^^^^^^^^
  File "/home/airflow/.local/lib/python3.12/site-packages/jinja2/loaders.py", line 207, in get_source
    raise TemplateNotFound(template)
jinja2.exceptions.TemplateNotFound: queries/create_fact_table.sql
[2025-02-11T11:00:18.472+0000] {processor.py:925} INFO - DAG(s) 'Covid19' retrieved from /opt/airflow/dags/covid_19.py
[2025-02-11T11:00:18.571+0000] {logging_mixin.py:190} INFO - [2025-02-11T11:00:18.570+0000] {dag.py:3239} INFO - Sync 1 DAGs
[2025-02-11T11:00:20.325+0000] {logging_mixin.py:190} INFO - [2025-02-11T11:00:20.325+0000] {dag.py:4180} INFO - Setting next_dagrun for Covid19 to 2025-02-11 10:55:00+00:00, run_after=2025-02-11 11:00:00+00:00
[2025-02-11T11:00:20.576+0000] {processor.py:208} INFO - Processing /opt/airflow/dags/covid_19.py took 3.441 seconds
[2025-02-11T11:00:51.754+0000] {processor.py:186} INFO - Started process (PID=72) to work on /opt/airflow/dags/covid_19.py
[2025-02-11T11:00:51.908+0000] {processor.py:914} INFO - Processing file /opt/airflow/dags/covid_19.py for tasks to queue
[2025-02-11T11:00:51.978+0000] {logging_mixin.py:190} INFO - [2025-02-11T11:00:51.911+0000] {dagbag.py:588} INFO - Filling up the DagBag from /opt/airflow/dags/covid_19.py
[2025-02-11T11:00:55.398+0000] {logging_mixin.py:190} INFO - [2025-02-11T11:00:55.397+0000] {templater.py:94} ERROR - Failed to resolve template field 'sql'
Traceback (most recent call last):
  File "/home/airflow/.local/lib/python3.12/site-packages/airflow/template/templater.py", line 92, in resolve_template_files
    setattr(self, field, env.loader.get_source(env, content)[0])  # type: ignore
                         ^^^^^^^^^^^^^^^^^^^^^^^^^^^^^^^^^^^
  File "/home/airflow/.local/lib/python3.12/site-packages/jinja2/loaders.py", line 207, in get_source
    raise TemplateNotFound(template)
jinja2.exceptions.TemplateNotFound: ./queries/create_dim_date.sql
[2025-02-11T11:00:55.399+0000] {logging_mixin.py:190} INFO - [2025-02-11T11:00:55.399+0000] {templater.py:94} ERROR - Failed to resolve template field 'sql'
Traceback (most recent call last):
  File "/home/airflow/.local/lib/python3.12/site-packages/airflow/template/templater.py", line 92, in resolve_template_files
    setattr(self, field, env.loader.get_source(env, content)[0])  # type: ignore
                         ^^^^^^^^^^^^^^^^^^^^^^^^^^^^^^^^^^^
  File "/home/airflow/.local/lib/python3.12/site-packages/jinja2/loaders.py", line 207, in get_source
    raise TemplateNotFound(template)
jinja2.exceptions.TemplateNotFound: ./queries/create_dim_location.sql
[2025-02-11T11:00:55.401+0000] {logging_mixin.py:190} INFO - [2025-02-11T11:00:55.400+0000] {templater.py:94} ERROR - Failed to resolve template field 'sql'
Traceback (most recent call last):
  File "/home/airflow/.local/lib/python3.12/site-packages/airflow/template/templater.py", line 92, in resolve_template_files
    setattr(self, field, env.loader.get_source(env, content)[0])  # type: ignore
                         ^^^^^^^^^^^^^^^^^^^^^^^^^^^^^^^^^^^
  File "/home/airflow/.local/lib/python3.12/site-packages/jinja2/loaders.py", line 207, in get_source
    raise TemplateNotFound(template)
jinja2.exceptions.TemplateNotFound: queries/create_fact_table.sql
[2025-02-11T11:00:55.403+0000] {processor.py:925} INFO - DAG(s) 'Covid19' retrieved from /opt/airflow/dags/covid_19.py
[2025-02-11T11:00:55.425+0000] {logging_mixin.py:190} INFO - [2025-02-11T11:00:55.424+0000] {dag.py:3239} INFO - Sync 1 DAGs
[2025-02-11T11:00:55.443+0000] {logging_mixin.py:190} INFO - [2025-02-11T11:00:55.442+0000] {dag.py:4180} INFO - Setting next_dagrun for Covid19 to 2025-02-11 10:55:00+00:00, run_after=2025-02-11 11:00:00+00:00
[2025-02-11T11:00:55.463+0000] {processor.py:208} INFO - Processing /opt/airflow/dags/covid_19.py took 4.546 seconds
[2025-02-11T11:01:25.709+0000] {processor.py:186} INFO - Started process (PID=87) to work on /opt/airflow/dags/covid_19.py
[2025-02-11T11:01:25.710+0000] {processor.py:914} INFO - Processing file /opt/airflow/dags/covid_19.py for tasks to queue
[2025-02-11T11:01:25.713+0000] {logging_mixin.py:190} INFO - [2025-02-11T11:01:25.713+0000] {dagbag.py:588} INFO - Filling up the DagBag from /opt/airflow/dags/covid_19.py
[2025-02-11T11:01:26.134+0000] {logging_mixin.py:190} INFO - [2025-02-11T11:01:26.133+0000] {templater.py:94} ERROR - Failed to resolve template field 'sql'
Traceback (most recent call last):
  File "/home/airflow/.local/lib/python3.12/site-packages/airflow/template/templater.py", line 92, in resolve_template_files
    setattr(self, field, env.loader.get_source(env, content)[0])  # type: ignore
                         ^^^^^^^^^^^^^^^^^^^^^^^^^^^^^^^^^^^
  File "/home/airflow/.local/lib/python3.12/site-packages/jinja2/loaders.py", line 207, in get_source
    raise TemplateNotFound(template)
jinja2.exceptions.TemplateNotFound: ./queries/create_dim_date.sql
[2025-02-11T11:01:26.135+0000] {logging_mixin.py:190} INFO - [2025-02-11T11:01:26.135+0000] {templater.py:94} ERROR - Failed to resolve template field 'sql'
Traceback (most recent call last):
  File "/home/airflow/.local/lib/python3.12/site-packages/airflow/template/templater.py", line 92, in resolve_template_files
    setattr(self, field, env.loader.get_source(env, content)[0])  # type: ignore
                         ^^^^^^^^^^^^^^^^^^^^^^^^^^^^^^^^^^^
  File "/home/airflow/.local/lib/python3.12/site-packages/jinja2/loaders.py", line 207, in get_source
    raise TemplateNotFound(template)
jinja2.exceptions.TemplateNotFound: ./queries/create_dim_location.sql
[2025-02-11T11:01:26.136+0000] {logging_mixin.py:190} INFO - [2025-02-11T11:01:26.136+0000] {templater.py:94} ERROR - Failed to resolve template field 'sql'
Traceback (most recent call last):
  File "/home/airflow/.local/lib/python3.12/site-packages/airflow/template/templater.py", line 92, in resolve_template_files
    setattr(self, field, env.loader.get_source(env, content)[0])  # type: ignore
                         ^^^^^^^^^^^^^^^^^^^^^^^^^^^^^^^^^^^
  File "/home/airflow/.local/lib/python3.12/site-packages/jinja2/loaders.py", line 207, in get_source
    raise TemplateNotFound(template)
jinja2.exceptions.TemplateNotFound: queries/create_fact_table.sql
[2025-02-11T11:01:26.139+0000] {processor.py:925} INFO - DAG(s) 'Covid19' retrieved from /opt/airflow/dags/covid_19.py
[2025-02-11T11:01:26.163+0000] {logging_mixin.py:190} INFO - [2025-02-11T11:01:26.162+0000] {dag.py:3239} INFO - Sync 1 DAGs
[2025-02-11T11:01:26.184+0000] {logging_mixin.py:190} INFO - [2025-02-11T11:01:26.184+0000] {dag.py:4180} INFO - Setting next_dagrun for Covid19 to 2025-02-11 10:55:00+00:00, run_after=2025-02-11 11:00:00+00:00
[2025-02-11T11:01:26.209+0000] {processor.py:208} INFO - Processing /opt/airflow/dags/covid_19.py took 0.505 seconds
[2025-02-11T11:01:56.475+0000] {processor.py:186} INFO - Started process (PID=95) to work on /opt/airflow/dags/covid_19.py
[2025-02-11T11:01:56.476+0000] {processor.py:914} INFO - Processing file /opt/airflow/dags/covid_19.py for tasks to queue
[2025-02-11T11:01:56.479+0000] {logging_mixin.py:190} INFO - [2025-02-11T11:01:56.478+0000] {dagbag.py:588} INFO - Filling up the DagBag from /opt/airflow/dags/covid_19.py
[2025-02-11T11:01:56.959+0000] {logging_mixin.py:190} INFO - [2025-02-11T11:01:56.957+0000] {templater.py:94} ERROR - Failed to resolve template field 'sql'
Traceback (most recent call last):
  File "/home/airflow/.local/lib/python3.12/site-packages/airflow/template/templater.py", line 92, in resolve_template_files
    setattr(self, field, env.loader.get_source(env, content)[0])  # type: ignore
                         ^^^^^^^^^^^^^^^^^^^^^^^^^^^^^^^^^^^
  File "/home/airflow/.local/lib/python3.12/site-packages/jinja2/loaders.py", line 207, in get_source
    raise TemplateNotFound(template)
jinja2.exceptions.TemplateNotFound: ./queries/create_dim_date.sql
[2025-02-11T11:01:56.960+0000] {logging_mixin.py:190} INFO - [2025-02-11T11:01:56.960+0000] {templater.py:94} ERROR - Failed to resolve template field 'sql'
Traceback (most recent call last):
  File "/home/airflow/.local/lib/python3.12/site-packages/airflow/template/templater.py", line 92, in resolve_template_files
    setattr(self, field, env.loader.get_source(env, content)[0])  # type: ignore
                         ^^^^^^^^^^^^^^^^^^^^^^^^^^^^^^^^^^^
  File "/home/airflow/.local/lib/python3.12/site-packages/jinja2/loaders.py", line 207, in get_source
    raise TemplateNotFound(template)
jinja2.exceptions.TemplateNotFound: ./queries/create_dim_location.sql
[2025-02-11T11:01:56.961+0000] {logging_mixin.py:190} INFO - [2025-02-11T11:01:56.961+0000] {templater.py:94} ERROR - Failed to resolve template field 'sql'
Traceback (most recent call last):
  File "/home/airflow/.local/lib/python3.12/site-packages/airflow/template/templater.py", line 92, in resolve_template_files
    setattr(self, field, env.loader.get_source(env, content)[0])  # type: ignore
                         ^^^^^^^^^^^^^^^^^^^^^^^^^^^^^^^^^^^
  File "/home/airflow/.local/lib/python3.12/site-packages/jinja2/loaders.py", line 207, in get_source
    raise TemplateNotFound(template)
jinja2.exceptions.TemplateNotFound: queries/create_fact_table.sql
[2025-02-11T11:01:56.964+0000] {processor.py:925} INFO - DAG(s) 'Covid19' retrieved from /opt/airflow/dags/covid_19.py
[2025-02-11T11:01:56.984+0000] {logging_mixin.py:190} INFO - [2025-02-11T11:01:56.983+0000] {dag.py:3239} INFO - Sync 1 DAGs
[2025-02-11T11:01:57.002+0000] {logging_mixin.py:190} INFO - [2025-02-11T11:01:57.002+0000] {dag.py:4180} INFO - Setting next_dagrun for Covid19 to 2025-02-11 10:55:00+00:00, run_after=2025-02-11 11:00:00+00:00
[2025-02-11T11:01:57.022+0000] {processor.py:208} INFO - Processing /opt/airflow/dags/covid_19.py took 0.552 seconds
[2025-02-11T11:02:27.153+0000] {processor.py:186} INFO - Started process (PID=103) to work on /opt/airflow/dags/covid_19.py
[2025-02-11T11:02:27.155+0000] {processor.py:914} INFO - Processing file /opt/airflow/dags/covid_19.py for tasks to queue
[2025-02-11T11:02:27.157+0000] {logging_mixin.py:190} INFO - [2025-02-11T11:02:27.157+0000] {dagbag.py:588} INFO - Filling up the DagBag from /opt/airflow/dags/covid_19.py
[2025-02-11T11:02:27.536+0000] {logging_mixin.py:190} INFO - [2025-02-11T11:02:27.535+0000] {templater.py:94} ERROR - Failed to resolve template field 'sql'
Traceback (most recent call last):
  File "/home/airflow/.local/lib/python3.12/site-packages/airflow/template/templater.py", line 92, in resolve_template_files
    setattr(self, field, env.loader.get_source(env, content)[0])  # type: ignore
                         ^^^^^^^^^^^^^^^^^^^^^^^^^^^^^^^^^^^
  File "/home/airflow/.local/lib/python3.12/site-packages/jinja2/loaders.py", line 207, in get_source
    raise TemplateNotFound(template)
jinja2.exceptions.TemplateNotFound: ./queries/create_dim_date.sql
[2025-02-11T11:02:27.537+0000] {logging_mixin.py:190} INFO - [2025-02-11T11:02:27.537+0000] {templater.py:94} ERROR - Failed to resolve template field 'sql'
Traceback (most recent call last):
  File "/home/airflow/.local/lib/python3.12/site-packages/airflow/template/templater.py", line 92, in resolve_template_files
    setattr(self, field, env.loader.get_source(env, content)[0])  # type: ignore
                         ^^^^^^^^^^^^^^^^^^^^^^^^^^^^^^^^^^^
  File "/home/airflow/.local/lib/python3.12/site-packages/jinja2/loaders.py", line 207, in get_source
    raise TemplateNotFound(template)
jinja2.exceptions.TemplateNotFound: ./queries/create_dim_location.sql
[2025-02-11T11:02:27.538+0000] {logging_mixin.py:190} INFO - [2025-02-11T11:02:27.538+0000] {templater.py:94} ERROR - Failed to resolve template field 'sql'
Traceback (most recent call last):
  File "/home/airflow/.local/lib/python3.12/site-packages/airflow/template/templater.py", line 92, in resolve_template_files
    setattr(self, field, env.loader.get_source(env, content)[0])  # type: ignore
                         ^^^^^^^^^^^^^^^^^^^^^^^^^^^^^^^^^^^
  File "/home/airflow/.local/lib/python3.12/site-packages/jinja2/loaders.py", line 207, in get_source
    raise TemplateNotFound(template)
jinja2.exceptions.TemplateNotFound: queries/create_fact_table.sql
[2025-02-11T11:02:27.541+0000] {processor.py:925} INFO - DAG(s) 'Covid19' retrieved from /opt/airflow/dags/covid_19.py
[2025-02-11T11:02:27.561+0000] {logging_mixin.py:190} INFO - [2025-02-11T11:02:27.561+0000] {dag.py:3239} INFO - Sync 1 DAGs
[2025-02-11T11:02:27.579+0000] {logging_mixin.py:190} INFO - [2025-02-11T11:02:27.579+0000] {dag.py:4180} INFO - Setting next_dagrun for Covid19 to 2025-02-11 10:55:00+00:00, run_after=2025-02-11 11:00:00+00:00
[2025-02-11T11:02:27.600+0000] {processor.py:208} INFO - Processing /opt/airflow/dags/covid_19.py took 0.452 seconds
[2025-02-11T11:02:57.855+0000] {processor.py:186} INFO - Started process (PID=111) to work on /opt/airflow/dags/covid_19.py
[2025-02-11T11:02:57.857+0000] {processor.py:914} INFO - Processing file /opt/airflow/dags/covid_19.py for tasks to queue
[2025-02-11T11:02:57.859+0000] {logging_mixin.py:190} INFO - [2025-02-11T11:02:57.859+0000] {dagbag.py:588} INFO - Filling up the DagBag from /opt/airflow/dags/covid_19.py
[2025-02-11T11:02:58.344+0000] {logging_mixin.py:190} INFO - [2025-02-11T11:02:58.343+0000] {templater.py:94} ERROR - Failed to resolve template field 'sql'
Traceback (most recent call last):
  File "/home/airflow/.local/lib/python3.12/site-packages/airflow/template/templater.py", line 92, in resolve_template_files
    setattr(self, field, env.loader.get_source(env, content)[0])  # type: ignore
                         ^^^^^^^^^^^^^^^^^^^^^^^^^^^^^^^^^^^
  File "/home/airflow/.local/lib/python3.12/site-packages/jinja2/loaders.py", line 207, in get_source
    raise TemplateNotFound(template)
jinja2.exceptions.TemplateNotFound: ./queries/create_dim_date.sql
[2025-02-11T11:02:58.346+0000] {logging_mixin.py:190} INFO - [2025-02-11T11:02:58.346+0000] {templater.py:94} ERROR - Failed to resolve template field 'sql'
Traceback (most recent call last):
  File "/home/airflow/.local/lib/python3.12/site-packages/airflow/template/templater.py", line 92, in resolve_template_files
    setattr(self, field, env.loader.get_source(env, content)[0])  # type: ignore
                         ^^^^^^^^^^^^^^^^^^^^^^^^^^^^^^^^^^^
  File "/home/airflow/.local/lib/python3.12/site-packages/jinja2/loaders.py", line 207, in get_source
    raise TemplateNotFound(template)
jinja2.exceptions.TemplateNotFound: ./queries/create_dim_location.sql
[2025-02-11T11:02:58.347+0000] {logging_mixin.py:190} INFO - [2025-02-11T11:02:58.347+0000] {templater.py:94} ERROR - Failed to resolve template field 'sql'
Traceback (most recent call last):
  File "/home/airflow/.local/lib/python3.12/site-packages/airflow/template/templater.py", line 92, in resolve_template_files
    setattr(self, field, env.loader.get_source(env, content)[0])  # type: ignore
                         ^^^^^^^^^^^^^^^^^^^^^^^^^^^^^^^^^^^
  File "/home/airflow/.local/lib/python3.12/site-packages/jinja2/loaders.py", line 207, in get_source
    raise TemplateNotFound(template)
jinja2.exceptions.TemplateNotFound: queries/create_fact_table.sql
[2025-02-11T11:02:58.350+0000] {processor.py:925} INFO - DAG(s) 'Covid19' retrieved from /opt/airflow/dags/covid_19.py
[2025-02-11T11:02:58.372+0000] {logging_mixin.py:190} INFO - [2025-02-11T11:02:58.371+0000] {dag.py:3239} INFO - Sync 1 DAGs
[2025-02-11T11:02:58.389+0000] {logging_mixin.py:190} INFO - [2025-02-11T11:02:58.389+0000] {dag.py:4180} INFO - Setting next_dagrun for Covid19 to 2025-02-11 10:55:00+00:00, run_after=2025-02-11 11:00:00+00:00
[2025-02-11T11:02:58.410+0000] {processor.py:208} INFO - Processing /opt/airflow/dags/covid_19.py took 0.560 seconds
[2025-02-11T11:03:28.812+0000] {processor.py:186} INFO - Started process (PID=119) to work on /opt/airflow/dags/covid_19.py
[2025-02-11T11:03:28.813+0000] {processor.py:914} INFO - Processing file /opt/airflow/dags/covid_19.py for tasks to queue
[2025-02-11T11:03:28.816+0000] {logging_mixin.py:190} INFO - [2025-02-11T11:03:28.816+0000] {dagbag.py:588} INFO - Filling up the DagBag from /opt/airflow/dags/covid_19.py
[2025-02-11T11:03:29.093+0000] {logging_mixin.py:190} INFO - [2025-02-11T11:03:29.092+0000] {templater.py:94} ERROR - Failed to resolve template field 'sql'
Traceback (most recent call last):
  File "/home/airflow/.local/lib/python3.12/site-packages/airflow/template/templater.py", line 92, in resolve_template_files
    setattr(self, field, env.loader.get_source(env, content)[0])  # type: ignore
                         ^^^^^^^^^^^^^^^^^^^^^^^^^^^^^^^^^^^
  File "/home/airflow/.local/lib/python3.12/site-packages/jinja2/loaders.py", line 207, in get_source
    raise TemplateNotFound(template)
jinja2.exceptions.TemplateNotFound: ./queries/create_dim_date.sql
[2025-02-11T11:03:29.095+0000] {logging_mixin.py:190} INFO - [2025-02-11T11:03:29.095+0000] {templater.py:94} ERROR - Failed to resolve template field 'sql'
Traceback (most recent call last):
  File "/home/airflow/.local/lib/python3.12/site-packages/airflow/template/templater.py", line 92, in resolve_template_files
    setattr(self, field, env.loader.get_source(env, content)[0])  # type: ignore
                         ^^^^^^^^^^^^^^^^^^^^^^^^^^^^^^^^^^^
  File "/home/airflow/.local/lib/python3.12/site-packages/jinja2/loaders.py", line 207, in get_source
    raise TemplateNotFound(template)
jinja2.exceptions.TemplateNotFound: ./queries/create_dim_location.sql
[2025-02-11T11:03:29.096+0000] {logging_mixin.py:190} INFO - [2025-02-11T11:03:29.096+0000] {templater.py:94} ERROR - Failed to resolve template field 'sql'
Traceback (most recent call last):
  File "/home/airflow/.local/lib/python3.12/site-packages/airflow/template/templater.py", line 92, in resolve_template_files
    setattr(self, field, env.loader.get_source(env, content)[0])  # type: ignore
                         ^^^^^^^^^^^^^^^^^^^^^^^^^^^^^^^^^^^
  File "/home/airflow/.local/lib/python3.12/site-packages/jinja2/loaders.py", line 207, in get_source
    raise TemplateNotFound(template)
jinja2.exceptions.TemplateNotFound: queries/create_fact_table.sql
[2025-02-11T11:03:29.100+0000] {processor.py:925} INFO - DAG(s) 'Covid19' retrieved from /opt/airflow/dags/covid_19.py
[2025-02-11T11:03:29.126+0000] {logging_mixin.py:190} INFO - [2025-02-11T11:03:29.125+0000] {dag.py:3239} INFO - Sync 1 DAGs
[2025-02-11T11:03:29.147+0000] {logging_mixin.py:190} INFO - [2025-02-11T11:03:29.146+0000] {dag.py:4180} INFO - Setting next_dagrun for Covid19 to 2025-02-11 10:55:00+00:00, run_after=2025-02-11 11:00:00+00:00
[2025-02-11T11:03:29.166+0000] {processor.py:208} INFO - Processing /opt/airflow/dags/covid_19.py took 0.360 seconds
[2025-02-11T11:03:59.358+0000] {processor.py:186} INFO - Started process (PID=127) to work on /opt/airflow/dags/covid_19.py
[2025-02-11T11:03:59.360+0000] {processor.py:914} INFO - Processing file /opt/airflow/dags/covid_19.py for tasks to queue
[2025-02-11T11:03:59.362+0000] {logging_mixin.py:190} INFO - [2025-02-11T11:03:59.362+0000] {dagbag.py:588} INFO - Filling up the DagBag from /opt/airflow/dags/covid_19.py
[2025-02-11T11:03:59.702+0000] {logging_mixin.py:190} INFO - [2025-02-11T11:03:59.700+0000] {templater.py:94} ERROR - Failed to resolve template field 'sql'
Traceback (most recent call last):
  File "/home/airflow/.local/lib/python3.12/site-packages/airflow/template/templater.py", line 92, in resolve_template_files
    setattr(self, field, env.loader.get_source(env, content)[0])  # type: ignore
                         ^^^^^^^^^^^^^^^^^^^^^^^^^^^^^^^^^^^
  File "/home/airflow/.local/lib/python3.12/site-packages/jinja2/loaders.py", line 207, in get_source
    raise TemplateNotFound(template)
jinja2.exceptions.TemplateNotFound: ./queries/create_dim_date.sql
[2025-02-11T11:03:59.703+0000] {logging_mixin.py:190} INFO - [2025-02-11T11:03:59.703+0000] {templater.py:94} ERROR - Failed to resolve template field 'sql'
Traceback (most recent call last):
  File "/home/airflow/.local/lib/python3.12/site-packages/airflow/template/templater.py", line 92, in resolve_template_files
    setattr(self, field, env.loader.get_source(env, content)[0])  # type: ignore
                         ^^^^^^^^^^^^^^^^^^^^^^^^^^^^^^^^^^^
  File "/home/airflow/.local/lib/python3.12/site-packages/jinja2/loaders.py", line 207, in get_source
    raise TemplateNotFound(template)
jinja2.exceptions.TemplateNotFound: ./queries/create_dim_location.sql
[2025-02-11T11:03:59.704+0000] {logging_mixin.py:190} INFO - [2025-02-11T11:03:59.704+0000] {templater.py:94} ERROR - Failed to resolve template field 'sql'
Traceback (most recent call last):
  File "/home/airflow/.local/lib/python3.12/site-packages/airflow/template/templater.py", line 92, in resolve_template_files
    setattr(self, field, env.loader.get_source(env, content)[0])  # type: ignore
                         ^^^^^^^^^^^^^^^^^^^^^^^^^^^^^^^^^^^
  File "/home/airflow/.local/lib/python3.12/site-packages/jinja2/loaders.py", line 207, in get_source
    raise TemplateNotFound(template)
jinja2.exceptions.TemplateNotFound: queries/create_fact_table.sql
[2025-02-11T11:03:59.708+0000] {processor.py:925} INFO - DAG(s) 'Covid19' retrieved from /opt/airflow/dags/covid_19.py
[2025-02-11T11:03:59.732+0000] {logging_mixin.py:190} INFO - [2025-02-11T11:03:59.732+0000] {dag.py:3239} INFO - Sync 1 DAGs
[2025-02-11T11:03:59.753+0000] {logging_mixin.py:190} INFO - [2025-02-11T11:03:59.753+0000] {dag.py:4180} INFO - Setting next_dagrun for Covid19 to 2025-02-11 10:55:00+00:00, run_after=2025-02-11 11:00:00+00:00
[2025-02-11T11:03:59.778+0000] {processor.py:208} INFO - Processing /opt/airflow/dags/covid_19.py took 0.426 seconds
